File: completed/Koerner_2005_Polymer/RawDataFromAuthors/cnttobreak/neatpua.csv
Strain (%),Stress (MPa),Time (sec)
0.0478,0.5,
0.693,0.6,1
1.343,0.6889,2
1.988,0.7778,2
2.64,0.8778,3
3.29,0.9667,4
3.93,1.0556,5
4.58,1.1333,6
5.24,1.2111,7
5.87,1.2889,7
6.52,1.3667,8
7.17,1.4444,9
7.82,1.5111,10
8.46,1.5778,11
9.11,1.6444,11
9.76,1.7111,12
10.41,1.7778,13
11.06,1.8222,14
11.7,1.8778,15
12.35,1.9333,15
13,1.9778,16
13.64,2.022,17
14.29,2.078,18
14.94,2.122,19
15.59,2.167,20
16.23,2.2,20
16.88,2.244,21
17.53,2.278,22
18.18,2.311,23
18.82,2.344,24
19.47,2.367,24
20.1,2.411,25
20.8,2.433,26
21.4,2.467,27
22.1,2.5,28
22.7,2.522,28
23.4,2.544,29
24,2.567,30
24.6,2.589,31
25.3,2.611,32
25.9,2.633,33
26.6,2.656,33
27.2,2.678,34
27.9,2.7,35
28.5,2.722,36
29.2,2.744,37
29.8,2.756,37
30.5,2.778,38
31.1,2.789,39
31.8,2.811,40
32.4,2.833,41
33.1,2.844,41
33.7,2.856,42
34.4,2.878,43
35,2.889,44
35.7,2.9,45
36.3,2.911,46
36.9,2.933,46
37.6,2.944,47
38.2,2.956,48
38.9,2.967,49
39.5,2.978,50
40.2,2.989,50
40.8,3,51
41.5,3.011,52
42.1,3.022,53
42.8,3.033,54
43.4,3.044,54
44.1,3.056,55
44.7,3.067,56
45.4,3.078,57
46,3.089,58
46.7,3.1,59
47.3,3.111,59
48,3.122,60
48.6,3.133,61
49.3,3.133,62
49.9,3.144,63
50.5,3.156,63
51.2,3.167,64
51.8,3.167,65
52.5,3.189,66
53.1,3.2,67
53.8,3.2,67
54.4,3.211,68
55.1,3.222,69
55.7,3.233,70
56.4,3.233,71
57,3.244,72
57.7,3.256,72
58.3,3.267,73
59,3.278,74
59.6,3.289,75
60.3,3.289,76
60.9,3.3,76
61.6,3.311,77
62.2,3.322,78
62.8,3.333,79
63.5,3.344,80
64.1,3.356,80
64.8,3.367,81
65.4,3.378,82
66.1,3.389,83
66.7,3.4,84
67.4,3.4,85
68,3.411,85
68.7,3.422,86
69.3,3.422,87
70,3.444,88
70.6,3.456,89
71.3,3.467,89
71.9,3.478,90
72.6,3.489,91
73.2,3.5,92
73.9,3.511,93
74.5,3.511,93
75.1,3.522,94
75.8,3.533,95
76.4,3.556,96
77.1,3.556,97
77.7,3.567,98
78.4,3.578,98
79,3.589,99
79.7,3.589,100
80.3,3.6,101
81,3.611,102
81.6,3.622,102
82.3,3.633,103
82.9,3.644,104
83.6,3.656,105
84.2,3.667,106
84.9,3.667,106
85.5,3.678,107
86.2,3.689,108
86.8,3.7,109
87.4,3.711,110
88.1,3.711,111
88.7,3.722,111
89.4,3.733,112
90,3.744,113
90.7,3.744,114
91.3,3.756,115
92,3.767,115
92.6,3.778,116
93.3,3.789,117
93.9,3.8,118
94.6,3.811,119
95.2,3.822,119
95.9,3.833,120
96.5,3.833,121
97.2,3.844,122
97.8,3.856,123
98.5,3.867,124
99.1,3.878,124
99.7,3.889,125
100.4,3.9,126
101,3.9,127
101.7,3.911,128
102.3,3.922,128
103,3.933,129
103.6,3.944,130
104.3,3.944,131
104.9,3.956,132
105.6,3.967,132
106.2,3.978,133
106.9,3.989,134
107.5,4,135
108.2,4.011,136
108.8,4.022,137
109.5,4.022,137
110.1,4.033,138
110.8,4.044,139
111.4,4.056,140
112,4.067,141
112.7,4.078,141
113.3,4.089,142
114,4.1,143
114.6,4.111,144
115.3,4.111,145
115.9,4.122,145
116.6,4.144,146
117.2,4.156,147
117.9,4.167,148
118.5,4.178,149
119.2,4.189,150
119.8,4.2,150
120.5,4.211,151
121.1,4.222,152
121.8,4.233,153
122.4,4.256,154
123.1,4.267,154
123.7,4.278,155
124.4,4.289,156
125,4.3,157
125.6,4.311,158
126.3,4.333,158
126.9,4.344,159
127.6,4.356,160
128.2,4.367,161
128.9,4.389,162
129.5,4.4,163
130.2,4.411,163
130.8,4.422,164
131.5,4.444,165
132.1,4.456,166
132.8,4.467,167
133.4,4.489,167
134.1,4.5,168
134.7,4.522,169
135.4,4.533,170
136,4.556,171
136.6,4.567,171
137.3,4.589,172
137.9,4.6,173
138.6,4.622,174
139.2,4.644,175
139.9,4.656,176
140.5,4.667,176
141.2,4.689,177
141.8,4.711,178
142.5,4.722,179
143.1,4.733,180
143.8,4.756,180
144.4,4.767,181
145.1,4.789,182
145.7,4.811,183
146.4,4.822,184
147,4.844,184
147.7,4.856,185
148.3,4.889,186
149,4.9,187
149.6,4.922,188
150.2,4.933,189
150.9,4.956,189
151.5,4.978,190
152.2,5,191
152.9,5.022,192
153.6,5.033,193
154.2,5.067,193
154.9,5.078,194
155.5,5.1,195
156.1,5.122,196
156.8,5.144,197
157.4,5.167,198
158.1,5.189,198
158.7,5.211,199
159.4,5.233,200
160,5.256,201
160.7,5.278,202
161.3,5.3,202
162,5.333,203
162.6,5.356,204
163.3,5.367,205
163.9,5.4,206
164.6,5.411,206
165.2,5.444,207
165.9,5.467,208
166.5,5.489,209
167.2,5.511,210
167.8,5.533,211
168.5,5.556,211
169.1,5.578,212
169.7,5.611,213
170.4,5.633,214
171,5.656,215
171.7,5.678,215
172.3,5.711,216
173,5.722,217
173.6,5.756,218
174.3,5.778,219
174.9,5.8,219
175.6,5.822,220
176.2,5.844,221
176.9,5.867,222
177.5,5.889,223
178.2,5.922,224
178.8,5.944,224
179.5,5.967,225
180.1,5.989,226
180.7,6.011,227
181.4,6.033,228
182,6.056,228
182.7,6.078,229
183.3,6.1,230
184,6.122,231
184.6,6.156,232
185.3,6.178,232
185.9,6.2,233
186.6,6.222,234
187.2,6.244,235
187.9,6.267,236
188.5,6.289,237
189.2,6.322,237
189.8,6.344,238
190.5,6.378,239
191.1,6.411,240
191.8,6.422,241
192.4,6.456,241
193,6.478,242
193.7,6.5,243
194.3,6.522,244
195,6.544,245
195.6,6.567,245
196.3,6.589,246
196.9,6.611,247
197.6,6.633,248
198.2,6.656,249
198.9,6.689,250
199.5,6.711,250
200,6.733,251
201,6.756,252
201,6.778,253
202,6.8,254
203,6.822,254
203,6.856,255
204,6.878,256
205,6.9,257
205,6.922,258
206,6.944,258
207,6.978,259
207,7.011,260
208,7.033,261
209,7.056,262
209,7.078,263
210,7.111,263
211,7.133,264
211,7.156,265
212,7.178,266
212,7.211,267
213,7.233,267
214,7.256,268
214,7.278,269
215,7.311,270
216,7.322,271
216,7.356,271
217,7.378,272
218,7.4,273
218,7.422,274
219,7.456,275
220,7.478,276
220,7.489,276
221,7.522,277
222,7.544,278
222,7.578,279
223,7.6,280
224,7.622,281
224,7.644,281
225,7.667,282
226,7.689,283
226,7.722,284
227,7.744,285
227,7.767,285
228,7.8,286
229,7.822,287
229,7.844,288
230,7.867,289
231,7.9,289
231,7.922,290
232,7.944,291
233,7.967,292
233,8,293
234,8.022,294
235,8.044,294
235,8.078,295
236,8.1,296
237,8.122,297
237,8.144,298
238,8.178,298
238,8.2,299
239,8.211,300
240,8.244,301
240,8.267,302
241,8.289,302
242,8.311,303
242,8.333,304
243,8.356,305
244,8.378,306
244,8.4,307
245,8.433,307
246,8.456,308
246,8.489,309
247,8.511,310
248,8.533,311
248,8.567,311
249,8.578,312
249,8.611,313
250,8.644,314
251,8.667,315
251,8.689,315
252,8.722,316
253,8.733,317
253,8.756,318
254,8.789,319
255,8.811,320
255,8.833,320
256,8.844,321
257,8.878,322
257,8.9,323
258,8.922,324
259,8.933,324
259,8.956,325
260,8.978,326
260,8.989,327
261,9.011,328
262,9.033,328
262,9.044,329
263,9.056,330
264,9.067,331
264,9.089,332
265,9.1,333
266,9.122,333
266,9.144,334
267,9.167,335
268,9.2,336
268,9.222,337
269,9.244,337
270,9.267,338
270,9.3,339
271,9.333,340
271,9.356,341
272,9.378,341
273,9.411,342
273,9.433,343
274,9.456,344
275,9.478,345
275,9.511,346
276,9.533,346
277,9.556,347
277,9.578,348
278,9.6,349
279,9.622,350
279,9.644,350
280,9.667,351
281,9.689,352
281,9.711,353
282,9.733,354
282,9.744,354
283,9.767,355
284,9.8,356
284,9.811,357
285,9.844,358
286,9.867,359
286,9.889,359
287,9.911,360
288,9.944,361
288,9.967,362
289,9.978,363
290,10.011,363
290,10.033,364
291,10.056,365
292,10.078,366
292,10.089,367
293,10.111,368
294,10.144,368
294,10.167,369
295,10.189,370
296,10.211,371
296,10.233,372
297,10.256,373
298,10.278,373
298,10.311,374
299,10.333,375
299,10.367,376
300,10.4,377
301,10.433,377
301,10.456,378
302,10.489,379
303,10.511,380
303,10.533,381
304,10.567,381
305,10.589,382
305,10.611,383
306,10.633,384
307,10.667,385
307,10.689,386
308,10.711,386
309,10.733,387
309,10.744,388
310,10.767,389
310,10.789,390
311,10.8,390
312,10.822,391
312,10.844,392
313,10.867,393
314,10.878,394
314,10.9,394
315,10.922,395
316,10.944,396
316,10.967,397
317,10.989,398
318,11,399
318,11.022,399
319,11.044,400
320,11.067,401
320,11.078,402
321,11.111,403
321,11.144,403
322,11.167,404
323,11.2,405
323,11.222,406
324,11.244,407
325,11.267,407
325,11.289,408
326,11.311,409
327,11.333,410
327,11.367,411
328,11.389,412
329,11.422,412
329,11.444,413
330,11.478,414
331,11.511,415
331,11.544,416
332,11.578,416
333,11.611,417
333,11.644,418
334,11.678,419
334,11.711,420
335,11.733,420
336,11.756,421
336,11.778,422
337,11.8,423
338,11.833,424
338,11.856,425
339,11.878,425
340,11.9,426
340,11.922,427
341,11.944,428
342,11.978,429
342,12.011,429
343,12.044,430
344,12.067,431
344,12.1,432
345,12.122,433
345,12.156,433
346,12.189,434
347,12.233,435
347,12.256,436
348,12.289,437
349,12.322,438
349,12.344,438
350,12.378,439
351,12.4,440
351,12.433,441
352,12.456,442
353,12.489,442
353,12.511,443
354,12.533,444
355,12.556,445
355,12.567,446
356,12.589,447
357,12.611,448
357,12.622,448
358,12.633,449
359,12.644,450
359,12.667,451
360,12.678,452
361,12.689,452
361,12.711,453
362,12.733,454
362,12.756,455
363,12.756,456
364,12.778,456
364,12.8,457
365,12.822,458
366,12.844,459
366,12.867,460
367,12.889,461
368,12.922,461
368,12.944,462
369,12.967,463
370,12.989,464
370,13.022,465
371,13.056,465
372,13.078,466
372,13.111,467
373,13.144,468
373,13.178,469
374,13.2,469
375,13.222,470
375,13.256,471
376,13.267,472
377,13.289,473
377,13.311,474
378,13.333,474
379,13.356,475
379,13.389,476
380,13.411,477
381,13.433,478
381,13.467,478
382,13.489,479
383,13.511,480
383,13.533,481
384,13.567,482
384,13.589,482
385,13.611,483
386,13.644,484
386,13.656,485
387,13.678,486
388,13.711,487
388,13.733,487
389,13.756,488
390,13.789,489
390,13.833,490
391,13.867,491
392,13.889,491
392,13.911,492
393,13.933,493
394,13.956,494
394,13.978,495
395,14,495
395,14.022,496
396,14.056,497
397,14.078,498
397,14.111,499
398,14.133,500
399,14.156,500
399,14.167,501
400,14.2,502
401,14.211,503
401,14.233,504
402,14.244,504
403,14.256,505
403,14.278,506
404,14.289,507
405,14.311,508
405,14.344,508
406,14.367,509
406,14.411,510
407,14.433,511
408,14.478,512
408,14.511,513
409,14.544,513
410,14.578,514
410,14.611,515
411,14.644,516
412,14.667,517
412,14.7,517
413,14.722,518
414,14.744,519
414,14.767,520
415,14.789,521
416,14.822,521
416,14.833,522
417,14.867,523
417,14.878,524
418,14.911,525
419,14.922,526
419,14.944,526
420,14.967,527
421,15,528
422,15.044,529
422,15.089,530
423,15.111,531
424,15.156,531
424,15.189,532
425,15.233,533
425,15.267,534
426,15.311,535
427,15.356,536
427,15.4,536
428,15.433,537
429,15.456,538
429,15.489,539
430,15.511,540
431,15.544,540
431,15.567,541
432,15.589,542
433,15.611,543
433,15.644,544
434,15.667,544
435,15.711,545
435,15.744,546
436,15.778,547
436,15.811,548
437,15.844,549
438,15.878,549
438,15.9,550
439,15.933,551
440,15.956,552
440,15.967,553
441,15.989,553
442,16,554
442,16.011,555
443,16.033,556
444,16.044,557
444,16.067,557
445,16.1,558
446,16.133,559
446,16.167,560
447,16.2,561
447,16.244,562
448,16.278,562
449,16.3,563
449,16.333,564
450,16.367,565
451,16.4,566
451,16.422,566
452,16.444,567
453,16.467,568
453,16.489,569
454,16.5,570
455,16.522,570
455,16.544,571
456,16.556,572
457,16.578,573
457,16.589,574
458,16.611,575
458,16.633,575
459,16.644,576
460,16.667,577
460,16.689,578
461,16.711,579
462,16.733,579
462,16.767,580
463,16.8,581
464,16.822,582
464,16.856,583
465,16.878,583
466,16.911,584
466,16.956,585
467,16.978,586
468,17.022,587
468,17.044,588
469,17.078,588
469,17.111,589
470,17.133,590
471,17.178,591
471,17.211,592
472,17.244,592
473,17.278,593
473,17.322,594
474,17.367,595
475,17.411,596
475,17.444,596
476,17.478,597
477,17.511,598
477,17.544,599
478,17.578,600
479,17.611,601
479,17.633,602
480,17.656,602
481,17.678,603
481,17.7,604
482,17.711,605
483,17.711,606
483,17.722,607
484,17.733,607
485,17.744,608
485,17.756,609
486,17.767,610
487,17.789,611
487,17.8,611
488,17.822,612
489,17.844,613
489,17.867,614
490,17.9,615
490,17.922,615
491,17.956,616
492,17.989,617
492,18.011,618
493,18.044,619
494,18.067,620
494,18.1,620
495,18.122,621
496,18.144,622
496,18.167,623
497,18.189,624
498,18.222,624
498,18.233,625
499,18.244,626
500,18.267,627
500,18.289,628
501,18.311,628
501,18.344,629
502,18.367,630
503,18.411,631
503,18.433,632
504,18.467,633
505,18.489,633
505,18.511,634
506,18.522,635
507,18.544,636
507,18.567,637
508,18.589,637
509,18.6,638
509,18.622,639
510,18.667,640
511,18.7,641
511,18.733,641
512,18.778,642
512,18.822,643
513,18.878,644
514,18.933,645
514,18.989,646
515,19.056,646
516,19.111,647
516,19.189,648
517,19.244,649
518,19.3,650
518,19.356,650
519,19.411,651
520,19.467,652
520,19.522,653
521,19.567,654
522,19.611,654
522,19.656,655
523,19.7,656
523,19.733,657
524,19.767,658
525,19.811,659
525,19.844,659
526,19.878,660
527,19.911,661
527,19.933,662
528,19.956,663
529,19.967,663
529,20,664
530,20.01,665
531,20.03,666
531,20.06,667
532,20.07,668
533,20.09,669
533,20.1,669
534,20.12,670
535,20.13,671
535,20.16,672
536,20.17,673
537,20.18,673
537,20.19,674
538,20.19,675
539,20.19,676
539,20.21,677
540,20.22,678
541,20.23,678
541,20.24,679
542,20.26,680
542,20.28,681
543,20.29,682
544,20.3,682
544,20.31,683
545,20.33,684
546,20.34,685
546,20.37,686
547,20.39,686
548,20.41,687
548,20.42,688
549,20.44,689
550,20.47,690
550,20.48,691
551,20.5,691
552,20.51,692
552,20.53,693
553,20.57,694
553,20.6,695
554,20.64,695
555,20.68,696
555,20.72,697
556,20.76,698
557,20.79,699
557,20.82,699
558,20.86,700
559,20.9,701
559,20.94,702
560,20.98,703
561,21.01,704
561,21.06,704
562,21.11,705
563,21.16,706
563,21.21,707
564,21.26,708
564,21.31,708
565,21.37,709
566,21.41,710
566,21.46,711
567,21.5,712
568,21.54,712
568,21.58,713
569,21.62,714
570,21.66,715
570,21.7,716
571,21.73,717
572,21.77,717
572,21.8,718
573,21.83,719
574,21.87,720
574,21.89,721
575,21.91,721
576,21.93,722
576,21.97,723
577,21.99,724
577,22.02,725
578,22.04,725
579,22.08,726
579,22.1,727
580,22.13,728
581,22.17,729
581,22.2,730
582,22.23,730
583,22.27,731
583,22.3,732
584,22.33,733
585,22.36,734
585,22.38,734
586,22.4,735
587,22.43,736
587,22.48,737
588,22.56,738
589,22.61,739
589,22.69,740
590,22.76,740
591,22.82,741
591,22.89,742
592,22.96,743
593,23.01,744
593,23.08,744
594,23.12,745
595,23.19,746
595,23.23,747
596,23.29,748
596,23.33,749
597,23.39,749
598,23.43,750
598,23.48,751
599,23.52,752
600,23.58,753
600,23.61,753
601,23.67,754
602,23.7,755
602,23.74,756
603,23.79,757
604,23.82,757
604,23.88,758
605,23.92,759
606,23.98,760
606,24.01,761
607,24.07,762
608,24.11,762
608,24.13,763
609,24.17,764
609,24.2,765
610,24.23,766
611,24.26,766
611,24.28,767
612,24.3,768
613,24.33,769
613,24.34,770
614,24.36,770
615,24.38,771
615,24.39,772
616,24.4,773
617,24.41,774
617,24.42,775
618,24.42,775
619,24.42,776
619,24.43,777
620,24.44,778
620,24.44,779
621,24.47,779
622,24.48,780
622,24.51,781
623,24.54,782
624,24.57,783
624,24.6,783
625,24.63,784
626,24.67,785
626,24.69,786
627,24.72,787
628,24.76,788
628,24.78,788
629,24.81,789
630,24.84,790
630,24.9,791
631,24.93,792
631,24.97,792
632,25.02,794
633,25.06,794
634,25.09,795
634,25.12,796
635,25.14,797
636,25.17,798
636,25.18,799
637,25.2,799
638,25.22,800
638,25.23,801
639,25.26,802
640,25.28,803
640,25.29,803
641,25.31,804
641,25.32,805
642,25.33,806
643,25.34,807
643,25.37,807
644,25.38,808
645,25.4,809
645,25.43,810
646,25.44,811
647,25.48,812
647,25.51,812
648,25.53,813
649,25.58,814
649,25.62,815
650,25.67,816
651,25.71,816
651,25.74,817
652,25.77,818
652,25.79,819
653,25.8,820
654,25.81,820
654,25.81,821
655,25.83,822
656,25.86,823
656,25.87,824
657,25.9,825
658,25.92,825
658,25.96,826
659,26,827
660,26.04,828
660,26.08,829
661,26.13,829
662,26.17,830
662,26.2,831
663,26.23,832
664,26.27,833
664,26.31,833
665,26.34,834
665,26.39,835
666,26.42,836
667,26.46,837
667,26.49,838
668,26.52,838
669,26.56,839
669,26.61,840
670,26.64,841
671,26.69,842
671,26.72,842
672,26.74,843
673,26.77,844
673,26.79,845
674,26.83,846
675,26.88,846
675,26.93,847
676,26.99,848
676,27.04,849
677,27.11,850
678,27.17,851
678,27.23,851
679,27.29,852
680,27.33,853
680,27.39,854
681,27.44,855
682,27.5,855
683,27.59,857
683,27.64,857
684,27.7,858
684,27.76,859
685,27.81,860
686,27.84,861
686,27.89,861
687,27.93,862
688,27.96,863
688,27.98,864
689,28,865
690,28.02,865
690,28.04,866
691,28.08,867
692,28.1,868
692,28.13,869
693,28.16,870
694,28.19,870
694,28.21,871
695,28.24,872
695,28.28,873
696,28.3,874
697,28.31,874
697,28.32,875
698,28.34,876
699,28.36,877
699,28.37,878
700,28.36,878
701,28.37,879
701,28.39,880
702,28.43,881
703,28.47,882
703,28.51,883
704,28.54,883
705,28.58,884
705,28.63,885
706,28.69,886
707,28.73,887
707,28.78,887
708,28.82,888
708,28.88,889
709,28.92,890
710,28.97,891
710,29.02,891
711,29.07,892
712,29.11,893
712,29.14,894
713,29.19,895
714,29.23,896
714,29.26,896
715,29.29,897
716,29.33,898
716,29.36,899
717,29.39,900
718,29.41,900
718,29.44,901
719,29.48,902
719,29.52,903
720,29.54,904
721,29.58,904
721,29.61,905
722,29.61,906
723,29.63,907
723,29.66,908
724,29.69,909
725,29.72,909
725,29.74,910
726,29.79,911
727,29.81,912
727,29.83,913
728,29.87,913
729,29.89,914
729,29.91,915
730,29.94,916
730,29.97,917
731,29.99,917
732,30.02,919
733,30.04,920
733,30.07,920
734,30.08,921
735,30.09,922
735,30.1,923
736,30.11,924
737,30.1,924
737,30.07,925
738,30.04,926
739,30.03,927
739,30.03,928
740,30.04,928
740,30.06,929
741,30.06,930
742,30.06,931
742,30.04,932
743,30.03,933
744,30.02,933
744,29.99,934
745,29.97,935
746,29.97,936
746,29.97,937
747,30,937
748,30.03,938
748,30.06,939
749,30.07,940
750,30.1,941
750,30.12,941
751,30.14,942
751,30.17,943
752,30.19,944
753,30.2,945
753,30.23,946
754,30.26,946
755,30.28,947
755,30.31,948
756,30.32,949
757,30.33,950
757,30.33,950
758,30.34,951
759,30.37,952
759,30.38,953
760,30.39,954
761,30.4,954
761,30.42,955
762,30.42,956
763,30.44,957
763,30.47,958
764,30.51,959
764,30.53,959
765,30.58,960
766,30.61,961
766,30.64,962
767,30.68,963
768,30.71,963
768,30.74,964
769,30.77,965
770,30.78,966
770,30.8,967
771,30.83,967
772,30.86,968
772,30.89,969
773,30.91,970
774,30.93,971
774,30.97,972
775,31,972
775,31.03,973
776,31.08,974
777,31.13,975
777,31.19,976
778,31.26,976
779,31.32,977
779,31.38,978
780,31.42,979
781,31.46,980
781,31.49,980
782,31.5,981
783,31.53,982
783,31.56,983
784,31.58,984
785,31.6,985
785,31.61,985
786,31.63,986
786,31.66,987
787,31.68,988
788,31.7,989
788,31.72,989
789,31.74,990
790,31.76,991
790,31.78,992
791,31.83,993
792,31.9,993
792,31.99,994
793,32.08,995
794,32.14,996
794,32.23,997
795,32.3,998
796,32.37,998
796,32.42,999
797,32.47,1000
797,32.5,1001
798,32.52,1002
799,32.52,1003
800,32.52,1004
800,32.51,1004
801,32.5,1005
802,32.49,1006
802,32.49,1007
803,32.5,1008
804,32.54,1008
804,32.57,1009
805,32.62,1010
806,32.67,1011
806,32.72,1012
807,32.77,1013
807,32.81,1013
808,32.87,1014
809,32.92,1015
809,32.96,1016
810,32.98,1017
811,32.99,1017
811,33,1018
812,33.02,1019
813,33.08,1020
813,33.12,1021
814,33.19,1021
815,33.26,1022
815,33.32,1023
816,33.39,1024
817,33.46,1025
817,33.53,1026
818,33.6,1026
818,33.66,1027
819,33.72,1028
820,33.78,1029
820,33.83,1030
821,33.89,1030
822,33.93,1031
822,33.98,1032
823,34.01,1033
824,34.06,1034
824,34.09,1034
825,34.12,1035
826,34.14,1036
826,34.17,1037
827,34.18,1038
828,34.19,1039
828,34.2,1039
829,34.21,1040
829,34.23,1041
830,34.24,1042
831,34.27,1043
831,34.28,1043
832,34.28,1044
833,34.28,1045
833,34.29,1046
834,34.3,1047
835,34.32,1047
835,34.33,1048
836,34.36,1049
837,34.38,1050
837,34.39,1051
838,34.4,1052
839,34.41,1052
839,34.41,1053
840,34.42,1054
841,34.42,1055
841,34.42,1056
842,34.43,1056
842,34.44,1057
843,34.46,1058
844,34.48,1059
844,34.49,1060
845,34.52,1060
846,34.57,1061
846,34.6,1062
847,34.64,1063
848,34.68,1064
848,34.72,1065
849,34.78,1065
850,34.82,1066
850,34.86,1067
851,34.9,1068
852,34.96,1069
852,34.99,1069
853,35.07,1071
854,35.12,1072
855,35.17,1072
855,35.22,1073
856,35.27,1074
857,35.31,1075
857,35.36,1076
858,35.4,1076
858,35.44,1077
859,35.48,1078
860,35.52,1079
860,35.54,1080
861,35.56,1081
862,35.56,1081
862,35.57,1082
863,35.57,1083
864,35.56,1084
864,35.54,1085
865,35.52,1085
866,35.51,1086
866,35.48,1087
867,35.46,1088
868,35.42,1089
868,35.4,1089
869,35.4,1090
869,35.4,1091
870,35.4,1092
871,35.4,1093
871,35.4,1094
872,35.39,1094
873,35.39,1095
873,35.38,1096
874,35.37,1097
875,35.36,1098
875,35.34,1098
876,35.33,1099
877,35.32,1100
877,35.31,1101
878,35.31,1102
879,35.3,1102
879,35.29,1103
880,35.28,1104
880,35.24,1105
881,35.23,1106
882,35.2,1107
882,35.18,1107
883,35.14,1108
884,35.13,1109
884,35.12,1110
885,35.12,1111
886,35.13,1111
886,35.14,1112
887,35.14,1113
888,35.14,1114
888,35.14,1115
889,35.13,1115
890,35.1,1116
890,35.03,1117
891,34.93,1118
891,34.81,1119
892,34.64,1120
893,34.44,1120
893,34.18,1121
894,33.82,1122
895,33.37,1123
895,32.78,1124
896,31.97,1124
897,30.82,1125
897,29.02,1126
898,20.51,1127
899,0.05556,1128
899,0.05556,1128
900,0.05556,1129
901,0.05556,1130
901,0.05556,1131
902,0.05556,1132
902,0.05556,1132
Strain (%),Stress (MPa),Time (sec)
0.0502,0.5376,
1.301,1.4695,2
2.56,2.258,3
3.81,2.867,5
5.07,3.369,7
6.32,3.799,8
7.58,4.158,10
8.83,4.427,11
10.09,4.677,13
11.34,4.857,15
12.59,5,16
13.85,5.143,18
15.11,5.233,20
16.36,5.341,21
17.62,5.412,23
18.87,5.484,24
20.1,5.538,26
21.4,5.609,28
22.6,5.663,29
23.9,5.717,31
25.1,5.753,33
26.4,5.789,34
27.7,5.806,36
28.9,5.842,37
30.2,5.878,39
31.4,5.896,41
32.7,5.914,42
33.9,5.932,44
35.2,5.932,46
36.4,5.95,47
37.7,5.968,49
38.9,5.968,50
40.2,5.986,52
41.5,6.022,54
42.7,6.039,55
44,6.075,57
45.2,6.093,59
46.5,6.129,60
47.7,6.147,62
49,6.165,63
50.2,6.183,65
51.5,6.201,67
52.7,6.201,68
54,6.201,70
55.3,6.219,72
56.5,6.237,73
57.8,6.254,75
59,6.272,76
60.3,6.29,78
61.5,6.308,80
62.8,6.326,81
64,6.344,83
65.3,6.38,85
66.6,6.398,86
67.8,6.416,88
69.1,6.434,89
70.3,6.47,91
71.6,6.487,93
72.8,6.505,94
74.1,6.541,96
75.3,6.559,98
76.6,6.577,99
77.8,6.613,101
79.1,6.631,102
80.4,6.649,104
81.6,6.685,106
82.9,6.685,107
84.1,6.72,109
85.4,6.738,111
86.6,6.756,112
87.9,6.774,114
89.1,6.774,115
90.4,6.792,117
91.6,6.81,119
92.9,6.828,120
94.2,6.846,122
95.4,6.882,124
96.7,6.9,125
97.9,6.918,127
99.2,6.935,128
100.4,6.971,130
101.7,6.989,132
102.9,7.007,133
104.2,7.025,135
105.5,7.043,137
106.7,7.079,138
108,7.097,140
109.2,7.115,141
110.5,7.133,143
111.7,7.151,145
113,7.168,146
114.2,7.186,148
115.5,7.222,150
116.7,7.24,151
118,7.258,153
119.3,7.294,154
120.5,7.312,156
121.8,7.348,158
123,7.384,159
124.3,7.401,161
125.5,7.419,163
126.8,7.455,164
128,7.473,166
129.3,7.491,167
130.6,7.527,169
131.9,7.563,171
133.1,7.599,172
134.4,7.634,174
135.6,7.652,176
136.9,7.688,177
138.1,7.724,179
139.4,7.724,180
140.6,7.76,182
141.9,7.778,184
143.2,7.796,185
144.4,7.814,187
145.7,7.832,189
146.9,7.885,190
148.2,7.921,192
149.4,7.957,193
150.7,7.975,195
151.9,8.011,197
153.2,8.029,198
154.5,8.047,200
155.7,8.047,202
157,8.065,203
158.2,8.082,205
159.5,8.1,206
160.7,8.154,208
162,8.19,210
163.2,8.244,211
164.5,8.28,213
165.7,8.333,215
167,8.405,216
168.3,8.441,218
169.5,8.495,219
170.8,8.548,221
172,8.584,223
173.3,8.62,224
174.5,8.656,226
175.8,8.692,228
177,8.728,229
178.3,8.763,231
179.5,8.799,232
180.8,8.835,234
182.1,8.871,236
183.3,8.907,237
184.6,8.943,239
185.8,8.978,241
187.1,9.014,242
188.3,9.05,244
189.6,9.086,245
190.8,9.122,247
192.1,9.158,249
193.4,9.194,250
194.6,9.229,252
195.9,9.247,254
197.1,9.283,255
198.4,9.319,257
199.6,9.355,258
201,9.391,260
202,9.427,262
203,9.444,263
205,9.498,265
206,9.534,267
207,9.552,268
208,9.588,270
210,9.642,271
211,9.659,273
212,9.695,275
213,9.749,276
215,9.785,278
216,9.821,280
217,9.857,281
218,9.875,283
220,9.928,284
221,9.964,286
222,10,288
224,10.018,289
225,10.054,291
226,10.072,293
227,10.108,294
229,10.125,296
230,10.161,298
231,10.161,299
232,10.197,301
234,10.215,302
235,10.251,304
236,10.305,306
237,10.34,307
239,10.394,309
240,10.43,311
241,10.484,312
242,10.52,314
244,10.556,315
245,10.609,317
246,10.645,319
247,10.681,320
249,10.717,322
250,10.735,324
251,10.771,325
252,10.789,327
254,10.806,328
255,10.842,330
256,10.86,332
257,10.896,333
259,10.95,335
260,10.986,337
261,11.039,338
262,11.093,340
264,11.111,341
265,11.147,343
266,11.201,345
267,11.237,346
269,11.272,348
270,11.308,350
271,11.344,351
273,11.398,353
274,11.434,354
275,11.47,356
276,11.505,358
278,11.541,359
279,11.559,361
280,11.577,363
281,11.595,364
283,11.613,366
284,11.631,367
285,11.649,369
286,11.667,371
288,11.685,372
289,11.703,374
290,11.738,376
291,11.774,377
293,11.828,379
294,11.864,380
295,11.882,382
296,11.918,384
298,11.971,385
299,12.007,387
300,12.079,389
301,12.115,390
303,12.151,392
304,12.204,393
305,12.24,395
306,12.276,397
308,12.294,398
309,12.33,400
310,12.366,402
311,12.384,403
313,12.419,405
314,12.437,406
315,12.473,408
317,12.509,410
318,12.527,412
319,12.545,413
320,12.563,415
322,12.599,416
323,12.616,418
324,12.652,420
325,12.67,421
327,12.706,423
328,12.724,425
329,12.76,426
330,12.778,428
332,12.778,429
333,12.778,431
334,12.778,433
335,12.76,434
337,12.742,436
338,12.706,438
339,12.688,439
340,12.688,441
342,12.67,442
343,12.706,444
344,12.76,446
345,12.796,447
347,12.832,449
348,12.867,451
349,12.885,452
350,12.921,454
352,12.957,455
353,13.029,457
354,13.1,459
355,13.172,460
357,13.244,462
358,13.297,464
359,13.351,465
360,13.405,467
362,13.441,468
363,13.477,470
364,13.495,472
366,13.548,473
367,13.566,475
368,13.602,477
369,13.656,478
371,13.692,480
372,13.746,481
373,13.817,483
374,13.871,485
376,13.925,486
377,13.961,488
378,13.996,490
379,14.05,491
381,14.104,493
382,14.14,494
383,14.176,496
384,14.211,498
386,14.247,499
387,14.265,501
388,14.283,503
389,14.337,504
391,14.391,506
392,14.427,507
393,14.462,509
394,14.516,511
396,14.552,512
397,14.606,514
398,14.642,516
399,14.659,517
401,14.695,519
402,14.713,520
403,14.731,522
404,14.767,524
406,14.785,525
407,14.821,527
408,14.839,529
409,14.839,530
411,14.857,532
412,14.857,533
413,14.857,535
414,14.821,537
416,14.821,538
417,14.803,540
418,14.785,542
419,14.785,543
421,14.839,545
422,14.91,546
423,14.982,548
425,15.09,550
426,15.143,552
427,15.215,553
428,15.251,555
430,15.287,556
431,15.305,558
432,15.341,560
433,15.341,561
435,15.341,563
436,15.448,565
437,15.556,566
438,15.663,568
440,15.735,569
441,15.806,571
442,15.878,573
444,15.878,574
445,15.896,576
446,15.896,578
447,15.932,579
449,15.968,581
450,15.986,582
451,16.022,584
452,16.057,586
454,16.075,587
455,16.093,589
456,16.129,591
457,16.129,592
459,16.147,594
460,16.165,595
461,16.183,597
462,16.183,599
464,16.201,600
465,16.237,602
466,16.29,604
467,16.344,605
469,16.416,607
470,16.505,608
471,16.595,610
472,16.703,612
474,16.774,613
475,16.846,615
476,16.9,617
477,16.953,618
479,16.989,620
480,17.043,621
481,17.097,623
482,17.133,625
484,17.133,626
485,17.168,628
486,17.186,630
487,17.204,631
489,17.24,633
490,17.258,634
491,17.276,636
492,17.24,638
494,17.222,639
495,17.168,641
496,17.168,643
497,17.115,644
499,17.079,646
500,17.061,647
501,17.025,649
502,17.061,651
504,17.043,652
505,17.061,654
506,17.079,656
508,17.133,657
509,17.24,659
510,17.348,660
511,17.419,662
513,17.473,664
514,17.581,666
515,17.652,667
517,17.742,669
518,17.814,670
519,17.885,672
520,17.921,674
522,17.921,675
523,17.885,677
524,17.849,679
525,17.796,680
527,17.76,682
528,17.724,683
529,17.742,685
530,17.742,687
532,17.832,688
533,17.867,690
534,17.993,692
535,18.047,693
537,18.136,695
538,18.262,696
539,18.387,698
540,18.459,700
542,18.548,701
543,18.62,703
544,18.692,705
545,18.728,706
547,18.799,708
548,18.853,709
549,18.889,711
550,18.978,713
552,19.068,714
553,19.14,716
554,19.211,718
555,19.265,719
557,19.301,721
558,19.373,722
559,19.444,724
560,19.48,726
562,19.552,727
563,19.588,729
564,19.624,731
565,19.659,732
567,19.713,734
568,19.767,735
569,19.785,737
570,19.803,739
572,19.839,740
573,19.857,742
574,19.892,744
575,19.928,745
577,19.982,747
578,20,748
579,20.04,750
581,20.07,752
582,20.11,754
583,20.16,755
585,20.18,757
586,20.25,759
587,20.29,760
588,20.29,762
590,20.32,763
591,20.34,765
592,20.36,767
593,20.45,768
595,20.48,770
596,20.5,772
597,20.59,773
598,20.63,775
600,20.68,776
601,20.72,778
602,20.75,780
603,20.81,781
605,20.88,783
606,20.93,785
607,21,786
608,21.06,788
610,21.11,789
611,21.15,791
612,21.2,793
613,21.27,794
615,21.31,796
616,21.31,798
617,21.36,799
618,21.42,801
620,21.42,802
621,21.4,804
622,21.45,806
623,21.52,807
625,21.54,809
626,21.59,811
627,21.7,812
628,21.63,814
630,21.65,815
631,21.68,817
632,21.81,819
633,21.83,820
635,21.85,822
636,21.83,824
637,21.94,825
638,21.95,827
640,21.97,828
641,22.08,830
642,22.06,832
643,22.08,833
645,22.13,835
646,22.1,837
647,22.19,838
648,22.19,840
650,22.2,841
651,22.31,843
652,22.28,845
654,22.38,846
655,22.33,848
656,22.4,850
657,22.4,851
659,22.35,853
660,22.42,854
661,22.37,856
662,22.47,858
664,22.44,859
665,22.53,861
666,22.62,863
668,22.58,865
669,22.58,866
670,22.56,868
671,22.67,869
673,22.67,871
674,22.81,873
675,22.8,874
676,22.81,876
678,22.83,878
679,22.87,879
680,22.89,881
681,23.01,882
683,23.05,884
684,23.08,886
685,23.24,887
686,23.28,889
688,23.33,891
689,23.39,892
690,23.46,894
691,23.41,895
693,23.39,897
694,23.46,899
695,23.46,900
697,23.48,902
698,23.6,904
699,23.64,905
700,23.69,907
702,23.89,908
703,23.94,910
704,24,912
705,24.05,913
707,24.14,915
708,24.23,917
709,24.32,918
710,24.37,920
712,24.52,921
713,24.57,923
714,24.62,925
715,24.66,926
717,24.7,928
718,24.78,930
719,24.77,931
720,24.75,933
722,24.71,934
723,24.77,936
724,24.73,938
725,24.68,939
727,24.68,941
728,24.59,943
729,24.57,944
730,24.7,946
732,24.73,947
733,24.8,949
734,24.93,951
735,24.96,952
737,25.05,954
738,25.05,956
740,25.14,958
741,25.04,959
742,25.02,961
743,24.93,963
745,25.04,964
746,25.2,966
747,25.29,967
748,25.54,969
750,25.5,971
751,25.48,972
752,25.47,974
753,25.5,976
755,25.59,977
756,25.56,979
757,25.68,980
758,25.63,982
760,25.54,984
761,25.57,985
762,25.48,987
763,25.54,989
765,25.48,990
766,25.5,992
767,25.39,993
768,25.32,995
770,25.18,997
771,25.16,998
772,25.16,1000
773,25.18,1002
775,25.27,1003
776,25.25,1005
777,25.38,1006
778,25.34,1008
780,25.48,1010
781,25.52,1011
782,25.57,1013
783,25.65,1015
785,25.61,1016
786,25.72,1018
787,25.66,1019
788,25.75,1021
790,25.79,1023
791,25.79,1024
792,25.82,1026
794,25.73,1028
795,25.82,1029
796,25.88,1031
797,25.9,1032
799,25.95,1034
800,25.9,1036
801,25.91,1037
802,25.9,1039
804,25.84,1041
805,25.9,1042
806,25.81,1044
807,25.81,1045
809,25.84,1047
810,25.86,1049
811,26.04,1050
812,26.25,1052
814,26.36,1054
815,26.61,1055
816,26.54,1057
817,26.54,1058
819,26.59,1060
820,26.65,1062
821,26.7,1063
822,26.85,1065
824,26.74,1067
825,26.74,1068
826,26.47,1070
827,26.29,1071
829,25.84,1073
830,0.16129,1075
831,0.16129,1076
832,0.16129,1078
834,0.16129,1080
835,0.16129,1081
836,0.16129,1083
837,0.16129,1084
839,0.16129,1086
840,0.16129,1088
841,0.16129,1089
842,0.16129,1091
844,0.16129,1093
845,0.16129,1094
846,0.16129,1096
847,0.14337,1097
849,0.16129,1099
850,0.16129,1101
851,0.16129,1102
852,0.16129,1104
854,0.16129,1106
855,0.16129,1107
856,0.16129,1109
858,0.16129,1110
859,0.16129,1112
860,0.16129,1114
861,0.14337,1115
863,0.16129,1117
864,0.17921,1119
865,0.16129,1120
866,0.16129,1122
868,0.16129,1123
869,0.16129,1125
870,0.16129,1127
871,0.16129,1128
873,0.16129,1130
874,0.16129,1132
875,0.16129,1133
876,0.16129,1135
878,0.16129,1136
879,0.16129,1138
880,0.16129,1140
881,0.16129,1141
883,0.16129,1143
884,0.16129,1145
885,0.16129,1146
886,0.16129,1148
888,0.16129,1149
889,0.16129,1151
890,0.16129,1153
891,0.16129,1154
893,0.16129,1156
894,0.17921,1158
895,0.16129,1159
896,0.17921,1161
898,0.17921,1162
899,0.16129,1164
900,0.17921,1166
901,0.17921,1167
903,0.16129,1169
904,0.17921,1171
905,0.17921,1172
906,0.17921,1174
908,0.16129,1175
909,0.16129,1177
910,0.17921,1179
911,0.17921,1180
913,0.17921,1182
914,0.16129,1184
915,0.17921,1185
916,0.17921,1187
918,0.16129,1188
919,0.16129,1190
920,0.16129,1192
922,0.16129,1193
923,0.17921,1195
924,0.17921,1197
925,0.17921,1198
927,0.17921,1200
928,0.17921,1201
929,0.17921,1203
930,0.17921,1205
932,0.16129,1206
933,0.16129,1208
934,0.16129,1210
935,0.16129,1211
937,0.16129,1213
938,0.17921,1214
939,0.16129,1216
940,0.16129,1218
942,0.16129,1219
943,0.16129,1221
944,0.16129,1223
945,0.16129,1224
947,0.16129,1226
948,0.16129,1227
949,0.16129,1229
950,0.16129,1231
952,0.16129,1232
953,0.16129,1234
954,0.16129,1236
955,0.16129,1237
957,0.16129,1239
958,0.16129,1240
959,0.16129,1242
960,0.16129,1244
962,0.16129,1245
963,0.17921,1247
964,0.17921,1249
965,0.17921,1250
967,0.16129,1252
968,0.16129,1253
969,0.16129,1255
970,0.16129,1257
972,0.17921,1258
973,0.16129,1260
974,0.16129,1262
975,0.16129,1263
977,0.17921,1265
978,0.16129,1266
979,0.16129,1268
980,0.17921,1270
982,0.16129,1271
983,0.17921,1273
984,0.16129,1275
986,0.17921,1276
987,0.16129,1278
988,0.17921,1279
989,0.17921,1281
991,0.17921,1283
992,0.17921,1284
993,0.16129,1286
994,0.16129,1288
996,0.17921,1289
997,0.16129,1291
998,0.16129,1292
1000,0.17921,1295
1001,0.17921,1296
1002,0.17921,1298
1004,0.17921,1300
1005,0.16129,1301
1006,0.17921,1303
1007,0.17921,1304
1009,0.17921,1306
1010,0.17921,1308
1011,0.16129,1309
1012,0.16129,1311
1014,0.16129,1313
1015,0.16129,1314
1016,0.16129,1316
1017,0.16129,1317
1019,0.16129,1319
1020,0.17921,1321
1021,0.16129,1322
1022,0.16129,1324
1024,0.17921,1326
1025,0.16129,1327
1026,0.16129,1329
1027,0.16129,1330
1029,0.16129,1332
1030,0.16129,1334
1031,0.16129,1335
1032,0.16129,1337
1034,0.16129,1339
1035,0.17921,1340
1036,0.17921,1342
1037,0.16129,1343
1039,0.17921,1345
1040,0.17921,1347
1041,0.16129,1348
1042,0.17921,1350
1044,0.17921,1352
1045,0.17921,1353
1046,0.17921,1355
1047,0.17921,1356
1049,0.16129,1358
1050,0.17921,1360
1051,0.17921,1361
1052,0.17921,1363
1054,0.17921,1365
1055,0.17921,1366
1056,0.17921,1368
1057,0.17921,1369
1059,0.17921,1371
1060,0.17921,1373
1061,0.17921,1374
1063,0.17921,1376
1064,0.17921,1378
1065,0.17921,1379
1066,0.17921,1381
1068,0.19713,1382
1069,0.17921,1384
1070,0.17921,1386
1071,0.17921,1387
1073,0.17921,1389
1074,0.17921,1391
1075,0.16129,1392
1076,0.16129,1394
1078,0.16129,1395
1079,0.16129,1397
1080,0.16129,1399
1081,0.17921,1400
1083,0.17921,1402
1084,0.16129,1404
1085,0.17921,1405
1086,0.17921,1407
1088,0.16129,1408
1089,0.16129,1410
1090,0.16129,1412
1091,0.16129,1413
1093,0.17921,1415
1094,0.17921,1417
1095,0.17921,1418
1096,0.17921,1420
1098,0.17921,1421
1099,0.19713,1423
1100,0.17921,1425
1101,0.19713,1426
1103,0.17921,1428
1104,0.19713,1430
1105,0.17921,1431
1106,0.19713,1433
1108,0.17921,1434
1109,0.17921,1436
1110,0.16129,1438
1111,0.16129,1439
1113,0.17921,1441
1114,0.17921,1443
1115,0.17921,1444
1116,0.16129,1446
1118,0.17921,1447
1119,0.17921,1449
1120,0.16129,1451
1121,0.17921,1452
1123,0.17921,1454
1124,0.17921,1456
1125,0.16129,1457
1127,0.17921,1459
1128,0.16129,1460
1129,0.17921,1462
1130,0.17921,1464
1132,0.17921,1465
1133,0.17921,1467
1134,0.17921,1469
1135,0.17921,1470
1137,0.17921,1472
1138,0.16129,1473
1139,0.17921,1475
1140,0.17921,1477
1142,0.17921,1478
1143,0.17921,1480
1144,0.17921,1482
1145,0.17921,1483
1147,0.17921,1485
1148,0.19713,1486
1149,0.17921,1488
1150,0.17921,1490
1152,0.17921,1491
1153,0.17921,1493
1154,0.17921,1495
1155,0.17921,1496
1157,0.17921,1498
1158,0.17921,1499
1159,0.19713,1501
1160,0.19713,1503
1162,0.17921,1504
1163,0.17921,1506
1164,0.17921,1508
1165,0.17921,1509
1167,0.17921,1511
1168,0.17921,1512
1169,0.17921,1514
1170,0.17921,1516
1172,0.17921,1517
1173,0.17921,1519
1174,0.17921,1521
1175,0.17921,1522
1177,0.17921,1524
1178,0.17921,1525
1179,0.17921,1527
1180,0.17921,1529
1182,0.17921,1530
1183,0.17921,1532
1184,0.17921,1534
1185,0.17921,1535
1187,0.17921,1537
1188,0.17921,1538
1189,0.19713,1540
1191,0.17921,1542
1192,0.17921,1543
1193,0.17921,1545
1194,0.19713,1547
1196,0.17921,1548
1197,0.17921,1550
1198,0.17921,1551
1199,0.17921,1553
1201,0.17921,1555
1202,0.17921,1556
1203,0.17921,1558
1204,0.17921,1560
1206,0.17921,1561
1207,0.17921,1563
1208,0.19713,1564
1209,0.17921,1566
1211,0.17921,1568
1212,0.17921,1569
1213,0.17921,1571
1214,0.19713,1573
1216,0.17921,1574
1217,0.19713,1576
1218,0.16129,1577
1219,0.17921,1579
1221,0.16129,1581
1222,0.16129,1582
1223,0.16129,1584
1224,0.17921,1586
1226,0.17921,1587
1227,0.17921,1589
1228,0.17921,1590
1229,0.17921,1592
1231,0.16129,1594
1232,0.17921,1595
1233,0.17921,1597
1234,0.17921,1599
1236,0.17921,1600
1237,0.17921,1602
1238,0.17921,1603
1239,0.17921,1605
1241,0.17921,1607
1242,0.17921,1608
1243,0.17921,1610
1244,0.17921,1612
1246,0.17921,1613
1247,0.17921,1615
1248,0.17921,1616
1249,0.17921,1618
1251,0.17921,1620
1252,0.17921,1621
1253,0.17921,1623
1255,0.17921,1625
1256,0.19713,1626
1257,0.17921,1628
1258,0.17921,1629
1260,0.17921,1631
1261,0.17921,1633
1262,0.17921,1634
1263,0.17921,1636
1265,0.17921,1638
1266,0.17921,1639
1267,0.17921,1641
1268,0.17921,1642
1270,0.17921,1644
1271,0.17921,1646
1272,0.19713,1647
1273,0.17921,1649
1275,0.17921,1651
1276,0.17921,1652
1277,0.17921,1654
1278,0.17921,1655
1280,0.17921,1657
1281,0.17921,1659
1282,0.17921,1660
1283,0.17921,1662
1285,0.17921,1664
1286,0.17921,1665
1287,0.17921,1667
1288,0.17921,1668
1290,0.17921,1670
1291,0.17921,1672
1292,0.17921,1673
1293,0.19713,1675
1295,0.17921,1677
1296,0.17921,1678
1297,0.17921,1680
1298,0.17921,1681
1300,0.17921,1683
1301,0.16129,1685
1302,0.16129,1686
1303,0.16129,1688
1305,0.16129,1690
1306,0.16129,1691
1307,0.17921,1693
1308,0.16129,1694
1310,0.16129,1696
1311,0.16129,1698
1312,0.17921,1699
1313,0.16129,1701
1315,0.17921,1703
1316,0.17921,1704
1317,0.17921,1706
1318,0.17921,1707
1320,0.16129,1709
1321,0.16129,1711
1322,0.17921,1712
1324,0.17921,1714
1325,0.17921,1716
1326,0.17921,1717
1327,0.16129,1719
1329,0.16129,1720
1330,0.16129,1722
1331,0.17921,1724
1332,0.16129,1725
1334,0.17921,1727
1335,0.16129,1729
1336,0.17921,1730
1337,0.17921,1732
1339,0.17921,1733
1340,0.16129,1735
1341,0.16129,1737
1342,0.16129,1738
1344,0.16129,1740
1345,0.17921,1742
1346,0.16129,1743
1347,0.16129,1745
1349,0.16129,1746
1350,0.16129,1748
1351,0.16129,1750
1352,0.16129,1751
1354,0.16129,1753
1355,0.16129,1755
1356,0.17921,1756
1357,0.16129,1758
1359,0.16129,1759
1360,0.16129,1761
1361,0.16129,1763
1362,0.16129,1764
1364,0.16129,1766
1365,0.17921,1768
1366,0.16129,1769
1367,0.16129,1771
1369,0.16129,1772
1370,0.16129,1774
1371,0.16129,1776
1372,0.16129,1777
1374,0.17921,1779
1375,0.16129,1781
1376,0.17921,1782
1377,0.17921,1784
1379,0.16129,1785
1380,0.16129,1787
1381,0.16129,1789
1382,0.17921,1790
1384,0.16129,1792
1385,0.16129,1794
1386,0.16129,1795
1388,0.16129,1797
1389,0.16129,1798
1390,0.17921,1800
1391,0.17921,1802
1393,0.17921,1803
1394,0.16129,1805
1395,0.16129,1807
1396,0.16129,1808
1398,0.16129,1810
1399,0.16129,1811
1400,0.16129,1813
1401,0.16129,1815
1403,0.16129,1816
1404,0.17921,1818
1405,0.17921,1820
1406,0.17921,1821
1408,0.16129,1823
1409,0.16129,1824
1410,0.17921,1826
1411,0.17921,1828
1413,0.17921,1829
1414,0.17921,1831
1415,0.17921,1833
1416,0.16129,1834
1418,0.16129,1836
1419,0.17921,1837
1420,0.17921,1839
1421,0.17921,1841
1423,0.17921,1842
1424,0.17921,1844
1425,0.17921,1846
1426,0.16129,1847
1428,0.17921,1849
1429,0.17921,1850
1430,0.16129,1852
1431,0.16129,1854
1433,0.17921,1855
1434,0.17921,1857
1435,0.17921,1859
1436,0.17921,1860
1438,0.16129,1862
1439,0.17921,1863
1440,0.16129,1865
1441,0.17921,1867
1443,0.16129,1868
1444,0.16129,1870
1445,0.16129,1872
1446,0.17921,1873
1448,0.16129,1875
1449,0.17921,1876
1450,0.17921,1878
1452,0.16129,1880
1453,0.17921,1881
1454,0.16129,1883
1455,0.17921,1885
1457,0.17921,1886
1458,0.17921,1888
1459,0.17921,1889
1460,0.17921,1891
1462,0.17921,1893
1463,0.17921,1894
1464,0.17921,1896
1465,0.17921,1898
1467,0.17921,1899
1468,0.17921,1901
1469,0.17921,1902
1470,0.17921,1904
1472,0.17921,1906
1473,0.17921,1907
1474,0.17921,1909
1475,0.16129,1911
1477,0.17921,1912
1478,0.16129,1914
1479,0.17921,1915
1480,0.17921,1917
1482,0.16129,1919
1483,0.17921,1920
1484,0.16129,1922
1485,0.17921,1924
1487,0.16129,1925
1488,0.17921,1927
1489,0.17921,1928
1490,0.17921,1930
1492,0.16129,1932
1493,0.16129,1933
1494,0.16129,1935
1495,0.16129,1937
1497,0.16129,1938
1498,0.16129,1940
1499,0.17921,1942
1501,0.16129,1944
1502,0.16129,1946
1504,0.16129,1947
1505,0.16129,1949
1506,0.16129,1950
1507,0.16129,1952
1509,0.16129,1954
1510,0.16129,1955
1511,0.16129,1957
1512,0.16129,1959
1514,0.16129,1960
1515,0.16129,1962
1516,0.16129,1963
1517,0.16129,1965
1519,0.16129,1967
1520,0.16129,1968
1521,0.16129,1970
1522,0.16129,1972
1524,0.16129,1973
1525,0.16129,1975
1526,0.16129,1976
1527,0.16129,1978
1529,0.16129,1980
1530,0.16129,1981
1531,0.16129,1983
1532,0.16129,1985
1534,0.16129,1986
1535,0.16129,1988
1536,0.16129,1989
1538,0.16129,1991
1539,0.16129,1993
1540,0.16129,1994
1541,0.16129,1996
1543,0.16129,1998
1544,0.16129,1999
1545,0.16129,2001
1546,0.16129,2002
1548,0.16129,2004
1549,0.16129,2006
1550,0.16129,2007
1551,0.16129,2009
1553,0.16129,2011
1554,0.16129,2012
1555,0.16129,2014
1556,0.16129,2015
1558,0.16129,2017
1559,0.16129,2019
1560,0.16129,2020
1561,0.17921,2022
1563,0.17921,2024
1564,0.16129,2025
1565,0.16129,2027
1566,0.16129,2028
1568,0.16129,2030
1569,0.16129,2032
1570,0.16129,2033
1571,0.16129,2035
1573,0.16129,2037
1574,0.16129,2038
1575,0.16129,2040
1576,0.16129,2041
1578,0.16129,2043
1579,0.16129,2045
1580,0.16129,2046
1581,0.16129,2048
1583,0.16129,2050
1584,0.16129,2051
1585,0.16129,2053
1586,0.16129,2054
1588,0.16129,2056
1589,0.16129,2058
1590,0.17921,2059
1591,0.16129,2061
1593,0.16129,2063
1594,0.16129,2064
1595,0.16129,2066
1596,0.17921,2067
1598,0.16129,2069
1599,0.16129,2071
1600,0.17921,2072
1602,0.17921,2074
1603,0.17921,2076
1604,0.17921,2077
1605,0.17921,2079
1607,0.19713,2080
1608,0.17921,2082
1609,0.17921,2084
1610,0.19713,2085
1612,0.19713,2087
1613,0.19713,2089
1614,0.19713,2090
1615,0.19713,2092
1617,0.19713,2093
1618,0.19713,2095
1619,0.19713,2097
1620,0.19713,2098
1622,0.19713,2100
1623,0.19713,2102
1624,0.19713,2103
1625,0.19713,2105
1627,0.19713,2106
1628,0.2151,2108
1629,0.2151,2110
1630,0.2151,2111
1632,0.2151,2113
1633,0.19713,2115
1634,0.19713,2116
1635,0.19713,2118
1637,0.2151,2119
1638,0.2151,2121
1639,0.2151,2123
1640,0.19713,2124
1642,0.19713,2126
1643,0.16129,2128
1644,0.17921,2129
1645,0.17921,2131
1647,0.17921,2132
1648,0.19713,2134
1649,0.19713,2136
1650,0.17921,2137
1652,0.17921,2139
1653,0.17921,2141
1654,0.17921,2142
1655,0.17921,2144
1657,0.16129,2145
1658,0.16129,2147
1659,0.17921,2149
1660,0.16129,2150
1662,0.16129,2152
1663,0.16129,2154
1664,0.16129,2155
1666,0.16129,2157
1667,0.16129,2158
1668,0.16129,2160
1669,0.16129,2162
1671,0.16129,2163
1672,0.16129,2165
1673,0.16129,2167
1674,0.16129,2168
1676,0.16129,2170
1677,0.16129,2171
1678,0.16129,2173
1679,0.16129,2175
1681,0.16129,2176
1682,0.16129,2178
1683,0.16129,2180
1684,0.16129,2181
1686,0.17921,2183
1687,0.17921,2184
1688,0.17921,2186
1689,0.17921,2188
1691,0.17921,2189
1692,0.17921,2191
1693,0.17921,2193
1694,0.19713,2194
1696,0.19713,2196
1697,0.19713,2197
1698,0.19713,2199
1699,0.17921,2201
1701,0.19713,2202
1702,0.19713,2204
1703,0.19713,2206
1704,0.19713,2207
1706,0.19713,2209
1707,0.19713,2210
1708,0.2151,2212
1709,0.19713,2214
1711,0.19713,2215
1712,0.19713,2217
1713,0.19713,2219
1714,0.19713,2220
1716,0.19713,2222
1717,0.19713,2223
1718,0.19713,2225
1719,0.19713,2227
1721,0.2151,2228
1722,0.19713,2230
1723,0.19713,2232
1724,0.19713,2233
1726,0.19713,2235
1727,0.19713,2236
1728,0.19713,2238
1729,0.19713,2240
1731,0.19713,2241
1732,0.19713,2243
1733,0.19713,2245
1735,0.19713,2246
1736,0.19713,2248
1737,0.19713,2249
1738,0.19713,2251
1740,0.19713,2253
1741,0.19713,2254
1742,0.2151,2256
1743,0.2151,2258
1745,0.2151,2259
1746,0.2151,2261
1747,0.2151,2262
1748,0.2151,2264
1750,0.19713,2266
1751,0.19713,2267
1752,0.19713,2269
1753,0.19713,2271
1755,0.19713,2272
1756,0.19713,2274
1757,0.2151,2275
1758,0.2151,2277
1760,0.2151,2279
1761,0.19713,2280
1762,0.19713,2282
1763,0.19713,2284
1765,0.19713,2285
1766,0.2151,2287
1767,0.2151,2288
1768,0.2151,2290
1770,0.2151,2292
1771,0.2151,2293
1772,0.2151,2295
1773,0.2151,2297
1775,0.2151,2298
1776,0.2151,2300
1777,0.2151,2301
1778,0.2151,2303
1780,0.233,2305
1781,0.2151,2306
1782,0.233,2308
1783,0.2151,2310
1785,0.2151,2311
1786,0.233,2313
1787,0.2151,2314
1788,0.233,2316
1790,0.2151,2318
1791,0.2151,2319
1792,0.19713,2321
1794,0.2151,2323
1795,0.19713,2324
1796,0.2151,2326
1797,0.2151,2327
1799,0.2151,2329
1800,0.2151,2331
1801,0.2151,2332
1802,0.2151,2334
1804,0.2151,2336
1805,0.2151,2337
1806,0.19713,2339
1807,0.2151,2340
1809,0.2151,2342
1810,0.2151,2344
1811,0.2151,2345
1812,0.2151,2347
1814,0.2151,2349
1815,0.233,2350
1816,0.2151,2352
1817,0.2151,2353
1819,0.10753,2355
1820,0.16129,2357
1821,0.17921,2358