File: wishlist/Koerner_2005_Polymer/RawDataFromAuthors/cnttobreak/cnt15pu.csv
Strain (%),Stress (MPa),Time (sec)
0.0458,0.558,
1.294,1.6997,1
2.52,2.524,2
3.76,3.202,3
4.99,3.786,4
6.23,4.284,5
7.46,4.653,6
8.7,4.936,8
9.93,5.159,9
11.17,5.34,10
12.41,5.494,11
13.64,5.631,12
14.88,5.752,13
16.11,5.855,14
17.35,5.94,15
18.58,6.018,16
19.82,6.095,17
21.1,6.155,18
22.3,6.207,19
23.5,6.258,20
24.8,6.31,22
26,6.344,23
27.2,6.387,24
28.5,6.43,25
29.7,6.464,26
30.9,6.498,27
32.2,6.541,28
33.4,6.567,29
34.6,6.601,30
35.9,6.636,31
37.1,6.67,32
38.3,6.713,33
39.6,6.739,35
40.8,6.765,36
42.1,6.79,37
43.3,6.807,38
44.5,6.833,39
45.7,6.85,40
47,6.868,41
48.2,6.885,42
49.5,6.902,43
50.7,6.928,44
51.9,6.936,45
53.2,6.962,46
54.4,6.988,47
55.6,7.013,49
56.9,7.039,50
58.1,7.065,51
59.3,7.082,52
60.6,7.108,53
61.8,7.134,54
63,7.151,55
64.3,7.177,56
65.5,7.202,57
66.8,7.228,58
68,7.245,59
69.2,7.271,60
70.4,7.297,61
71.7,7.323,63
72.9,7.34,64
74.2,7.365,65
75.4,7.391,66
76.6,7.408,67
77.9,7.434,68
79.1,7.46,69
80.3,7.486,70
81.6,7.503,71
82.8,7.537,72
84.1,7.554,73
85.3,7.571,74
86.5,7.58,76
87.8,7.606,77
89,7.623,78
90.2,7.632,79
91.5,7.657,80
92.7,7.674,81
93.9,7.7,82
95.2,7.735,83
96.4,7.752,84
97.7,7.769,85
98.9,7.795,86
100.1,7.82,87
101.4,7.838,88
102.6,7.846,90
103.8,7.881,91
105.1,7.898,92
106.3,7.923,93
107.5,7.949,94
108.8,7.966,95
110,7.992,96
111.2,8.018,97
112.5,8.035,98
113.7,8.044,99
114.9,8.069,100
116.2,8.095,101
117.4,8.112,102
118.6,8.138,104
119.9,8.164,105
121.1,8.19,106
122.3,8.207,107
123.6,8.224,108
124.8,8.241,109
126.1,8.258,110
127.3,8.275,111
128.5,8.293,112
129.8,8.301,113
131,8.318,114
132.2,8.344,115
133.5,8.37,116
134.7,8.387,118
135.9,8.413,119
137.2,8.438,120
138.4,8.464,121
139.6,8.481,122
140.9,8.507,123
142.1,8.524,124
143.3,8.542,125
144.6,8.559,126
145.8,8.576,127
147.1,8.576,128
148.3,8.584,129
149.5,8.602,130
150.8,8.61,132
152,8.627,133
153.2,8.636,134
154.5,8.645,135
155.7,8.653,136
156.9,8.67,137
158.2,8.696,138
159.4,8.713,139
160.6,8.73,140
161.9,8.756,141
163.1,8.773,142
164.3,8.782,143
165.6,8.799,145
166.8,8.825,146
168.1,8.859,147
169.3,8.885,148
170.5,8.919,149
171.8,8.945,150
173,8.971,151
174.2,9.005,152
175.5,9.022,153
176.7,9.048,154
177.9,9.057,155
179.2,9.074,156
180.4,9.091,157
181.6,9.125,159
182.9,9.151,160
184.1,9.168,161
185.3,9.177,162
186.6,9.194,163
187.8,9.211,164
189,9.228,165
190.3,9.245,166
191.5,9.263,167
192.7,9.288,168
194,9.314,169
195.2,9.34,170
196.5,9.366,171
197.7,9.391,173
198.9,9.409,174
200,9.426,175
201,9.451,176
203,9.477,177
204,9.494,178
205,9.512,179
206,9.529,180
208,9.554,181
209,9.572,182
210,9.597,183
211,9.615,184
212,9.64,185
214,9.666,187
215,9.692,188
216,9.718,189
217,9.743,190
219,9.778,191
220,9.795,192
221,9.821,193
222,9.846,194
224,9.872,195
225,9.898,196
226,9.915,197
227,9.932,198
229,9.941,199
230,9.967,201
231,9.984,202
232,10.009,203
232,10.035,204
235,10.052,205
236,10.07,206
237,10.078,207
238,10.095,208
240,10.121,209
241,10.138,210
242,10.164,211
243,10.181,212
245,10.198,214
246,10.215,215
247,10.233,216
248,10.241,217
250,10.267,218
251,10.293,219
252,10.318,220
253,10.344,221
254,10.37,222
256,10.387,223
257,10.413,224
258,10.421,225
259,10.447,226
261,10.473,228
262,10.499,229
263,10.516,230
264,10.533,231
266,10.55,232
267,10.567,233
268,10.576,234
269,10.585,235
271,10.593,236
272,10.602,237
273,10.619,238
274,10.636,239
275,10.662,240
277,10.679,242
278,10.705,243
279,10.722,244
280,10.748,245
282,10.773,246
283,10.808,247
284,10.834,248
285,10.859,249
287,10.885,250
288,10.919,251
289,10.945,252
290,10.979,253
292,10.997,254
293,11.014,256
294,11.031,257
295,11.057,258
296,11.082,259
298,11.108,260
299,11.125,261
300,11.143,262
301,11.151,263
303,11.168,264
304,11.186,265
305,11.211,266
306,11.228,267
308,11.254,268
309,11.28,270
310,11.306,271
311,11.331,272
313,11.349,273
314,11.366,274
315,11.383,275
316,11.409,276
317,11.426,277
319,11.452,278
320,11.477,279
321,11.495,280
322,11.495,281
324,11.512,283
325,11.52,284
326,11.546,285
327,11.572,286
329,11.598,287
330,11.623,288
331,11.658,289
332,11.675,290
334,11.701,291
335,11.718,292
336,11.743,293
337,11.769,294
338,11.795,295
340,11.821,297
341,11.847,298
342,11.881,299
343,11.898,300
345,11.924,301
346,11.95,302
347,11.975,303
348,12.001,304
350,12.027,305
351,12.044,306
352,12.07,307
353,12.087,308
355,12.113,309
356,12.138,311
357,12.164,312
358,12.19,313
359,12.198,314
361,12.207,315
362,12.224,316
363,12.233,317
364,12.25,318
366,12.267,319
367,12.293,320
368,12.31,321
369,12.327,322
371,12.344,323
372,12.362,325
373,12.379,326
374,12.396,327
376,12.404,328
377,12.43,329
378,12.447,330
379,12.473,331
380,12.499,332
382,12.525,333
383,12.542,334
384,12.55,335
385,12.559,336
387,12.559,338
388,12.568,339
389,12.585,340
390,12.611,341
392,12.645,342
393,12.671,343
394,12.705,344
395,12.714,345
397,12.714,346
398,12.705,347
399,12.714,348
400,12.731,349
402,12.756,350
403,12.791,352
404,12.817,353
405,12.859,354
406,12.894,355
408,12.92,356
409,12.954,357
410,12.98,358
411,13.005,359
413,13.04,360
414,13.083,361
415,13.117,362
416,13.16,363
418,13.203,365
419,13.246,366
420,13.272,367
421,13.297,368
423,13.332,369
424,13.349,370
425,13.392,371
426,13.417,372
427,13.443,373
429,13.469,374
430,13.503,375
431,13.52,376
432,13.546,377
434,13.572,379
435,13.589,380
436,13.606,381
437,13.623,382
439,13.641,383
440,13.649,384
441,13.658,385
442,13.675,386
444,13.709,387
445,13.735,388
446,13.769,389
447,13.795,390
448,13.812,391
450,13.838,393
451,13.864,394
452,13.898,395
453,13.933,396
455,13.958,397
456,13.984,398
457,14.01,399
458,14.027,400
460,14.053,401
461,14.078,402
462,14.104,403
463,14.139,404
465,14.156,405
466,14.181,407
467,14.199,408
468,14.216,409
469,14.242,410
471,14.267,411
472,14.284,412
473,14.31,413
474,14.336,414
476,14.353,415
477,14.387,416
478,14.396,417
479,14.413,418
481,14.439,419
482,14.456,421
483,14.482,422
484,14.508,423
486,14.525,424
487,14.551,425
488,14.568,426
489,14.602,427
490,14.628,428
492,14.645,429
493,14.662,430
494,14.679,431
495,14.688,432
497,14.697,434
498,14.705,435
499,14.714,436
500,14.722,437
502,14.739,438
503,14.757,439
504,14.774,440
505,14.8,441
506,14.817,442
508,14.825,443
509,14.834,444
510,14.834,445
511,14.842,446
513,14.842,448
514,14.86,449
515,14.868,450
516,14.868,451
518,14.885,452
519,14.894,453
520,14.894,454
521,14.894,455
523,14.894,456
524,14.894,457
525,14.894,458
526,14.911,459
527,14.928,460
529,14.937,462
530,14.954,463
531,14.98,464
532,15.006,465
534,15.057,466
535,15.091,467
536,15.134,468
538,15.177,469
539,15.22,470
540,15.263,471
541,15.297,473
543,15.323,474
544,15.349,475
545,15.375,476
546,15.418,477
548,15.461,478
549,15.495,479
550,15.529,480
551,15.564,481
552,15.598,482
554,15.632,483
555,15.675,484
556,15.71,486
557,15.744,487
559,15.77,488
560,15.795,489
561,15.813,490
562,15.847,491
564,15.881,492
565,15.898,493
566,15.907,494
567,15.907,495
569,15.916,496
570,15.916,497
571,15.907,498
572,15.898,500
573,15.89,501
575,15.898,502
576,15.916,503
577,15.941,504
578,15.967,505
580,15.984,506
581,16.01,507
582,16.044,508
583,16.087,509
585,16.122,510
586,16.164,511
587,16.182,512
588,16.199,514
590,16.233,515
591,16.276,516
592,16.31,517
593,16.345,518
594,16.388,519
596,16.431,520
597,16.465,521
598,16.499,522
599,16.525,523
601,16.559,524
602,16.577,525
603,16.611,526
604,16.628,528
606,16.645,529
607,16.662,530
608,16.68,531
609,16.697,532
611,16.722,533
612,16.748,534
613,16.783,535
614,16.808,536
615,16.834,537
617,16.851,538
618,16.86,539
619,16.877,540
620,16.903,542
622,16.911,543
623,16.937,544
624,16.98,545
625,17.014,546
627,17.04,547
628,17.074,548
629,17.1,549
630,17.117,550
632,17.152,551
633,17.177,552
634,17.203,553
635,17.238,555
636,17.255,556
638,17.28,557
639,17.306,558
640,17.349,559
641,17.383,560
643,17.418,561
644,17.452,562
645,17.478,563
647,17.521,564
648,17.555,566
649,17.581,567
650,17.598,568
652,17.615,569
653,17.641,570
654,17.65,571
655,17.684,572
657,17.701,573
658,17.727,574
659,17.753,575
660,17.778,576
661,17.804,577
663,17.847,578
664,17.864,580
665,17.881,581
666,17.881,582
668,17.89,583
669,17.899,584
670,17.916,585
671,17.941,586
673,17.959,587
674,17.976,588
675,18.002,589
676,18.027,590
678,18.053,591
679,18.087,593
680,18.105,594
681,18.113,595
682,18.122,596
684,18.13,597
685,18.147,598
686,18.182,599
687,18.233,600
689,18.285,601
690,18.328,602
691,18.362,603
692,18.396,604
694,18.405,605
695,18.414,607
696,18.422,608
697,18.439,609
699,18.465,610
700,18.474,611
701,18.491,612
702,18.491,613
703,18.482,614
705,18.482,615
706,18.482,616
707,18.491,617
708,18.508,618
710,18.525,619
711,18.542,621
712,18.56,622
713,18.585,623
715,18.62,624
716,18.645,625
717,18.688,626
718,18.731,627
719,18.766,628
721,18.808,629
722,18.834,630
723,18.869,631
724,18.886,632
726,18.911,633
727,18.946,635
728,18.98,636
729,19.006,637
731,19.04,638
732,19.075,639
733,19.118,640
734,19.178,641
736,19.229,642
737,19.281,643
738,19.332,644
739,19.384,645
740,19.427,646
742,19.469,647
743,19.512,649
744,19.555,650
745,19.59,651
747,19.633,652
748,19.676,653
749,19.71,654
750,19.736,655
752,19.761,656
753,19.779,657
754,19.804,658
755,19.83,659
757,19.847,660
758,19.856,662
759,19.847,663
760,19.821,664
761,19.804,665
763,19.804,666
764,19.813,667
765,19.821,668
766,19.839,669
768,19.856,670
769,19.864,671
770,19.864,672
771,19.882,673
773,19.899,674
774,19.924,676
775,19.942,677
776,19.976,678
778,19.993,679
779,20.04,680
780,20.06,681
782,20.1,682
783,20.11,683
784,20.14,684
785,20.16,685
786,20.17,687
788,20.2,688
789,20.22,689
790,20.24,690
791,20.28,691
793,20.29,692
794,20.32,693
795,20.35,694
796,20.39,695
798,20.43,696
799,20.48,697
800,20.53,698
801,20.57,699
803,20.61,701
804,20.66,702
805,20.71,703
806,20.77,704
807,20.81,705
809,20.86,706
810,20.89,707
811,20.94,708
812,20.97,709
814,21,710
815,21.02,711
816,21.05,712
817,21.07,714
819,21.09,715
820,21.12,716
821,21.13,717
822,21.15,718
824,21.16,719
825,21.18,720
826,21.19,721
827,21.21,722
828,21.22,723
830,21.24,724
831,21.26,725
832,21.28,726
833,21.3,728
835,21.32,729
836,21.34,730
837,21.34,731
838,21.36,732
840,21.38,733
841,21.39,734
842,21.39,735
843,21.39,736
845,21.38,737
846,21.38,738
847,21.41,739
848,21.44,740
849,21.46,742
851,21.5,743
852,21.55,744
853,21.58,745
854,21.63,746
856,21.67,747
857,21.69,748
858,21.72,749
859,21.74,750
861,21.75,751
862,21.78,752
863,21.79,753
864,21.8,754
866,21.82,756
867,21.84,757
868,21.86,758
869,21.89,759
870,21.92,760
872,21.98,761
873,22.05,762
874,22.12,763
875,22.17,764
877,22.23,765
878,22.26,766
879,22.3,767
880,22.34,768
882,22.38,770
883,22.41,771
884,22.44,772
885,22.47,773
886,22.5,774
888,22.53,775
889,22.54,776
891,22.55,777
892,22.55,778
893,22.54,780
894,22.54,781
895,22.53,782
897,22.56,783
898,22.59,784
899,22.61,785
900,22.64,786
902,22.67,787
903,22.7,788
904,22.71,789
905,22.73,790
907,22.75,791
908,22.75,792
909,22.74,794
910,22.75,795
912,22.75,796
913,22.76,797
914,22.75,798
915,22.76,799
916,22.76,800
918,22.79,801
919,22.82,802
920,22.86,803
921,22.89,804
923,22.93,805
924,22.95,806
925,23,808
926,23.04,809
928,23.07,810
929,23.13,811
930,23.16,812
931,23.2,813
933,23.23,814
934,23.25,815
935,23.26,816
936,23.26,817
937,23.27,818
939,23.29,819
940,23.32,821
941,23.34,822
942,23.37,823
944,23.39,824
945,23.41,825
946,23.42,826
947,23.43,827
949,23.44,828
950,23.45,829
951,23.47,830
952,23.5,831
952,23.51,832
955,23.54,833
956,23.56,835
957,23.55,836
958,23.54,837
960,23.54,838
961,23.55,839
962,23.56,840
963,23.59,841
965,23.62,842
966,23.65,843
967,23.69,844
968,23.72,845
970,23.76,846
971,23.8,847
972,23.84,849
973,23.88,850
974,23.93,851
976,23.98,852
977,24.01,853
978,24.05,854
979,24.09,855
981,24.12,856
982,24.15,857
983,24.18,858
984,24.23,859
986,24.25,860
987,24.29,861
988,24.32,863
989,24.35,864
991,24.39,865
992,24.41,866
993,24.44,867
994,24.47,868
995,24.5,869
997,24.52,870
998,24.53,871
999,24.56,872
1001,24.58,874
1002,24.59,875
1003,24.62,876
1005,24.65,877
1006,24.68,878
1007,24.71,879
1008,24.73,880
1010,24.72,881
1011,24.73,882
1012,24.76,883
1013,24.8,885
1014,24.84,886
1016,24.88,887
1017,24.9,888
1018,24.91,889
1019,24.94,890
1021,24.97,891
1022,25.02,893
1024,25.05,894
1025,25.09,895
1026,25.13,896
1027,25.17,897
1029,25.2,898
1030,25.25,899
1031,25.27,900
1032,25.32,901
1034,25.34,902
1035,25.36,903
1036,25.38,904
1037,25.39,905
1038,25.41,907
1040,25.41,908
1041,25.44,909
1042,25.46,910
1043,25.49,911
1045,25.52,912
1046,25.55,913
1047,25.56,914
1048,25.59,915
1050,25.6,916
1051,25.61,917
1052,25.61,918
1053,25.61,919
1055,25.62,921
1056,25.67,922
1057,25.69,923
1058,25.73,924
1059,25.75,925
1061,25.81,926
1062,25.86,927
1063,25.89,928
1064,25.94,929
1066,25.98,930
1067,26,931
1068,26.04,932
1069,26.07,933
1071,26.11,935
1072,26.14,936
1073,26.17,937
1074,26.2,938
1076,26.23,939
1077,26.25,940
1078,26.27,941
1079,26.28,942
1080,26.29,943
1082,26.29,944
1083,26.29,945
1084,26.28,946
1085,26.29,948
1087,26.27,949
1088,26.29,950
1089,26.31,951
1090,26.33,952
1092,26.35,953
1093,26.37,954
1094,26.4,955
1095,26.41,956
1096,26.45,957
1098,26.48,958
1099,26.51,959
1100,26.54,960
1101,26.56,962
1103,26.58,963
1104,26.59,964
1105,26.61,965
1106,26.65,966
1108,26.68,967
1109,26.7,968
1110,26.72,969
1111,26.71,970
1113,26.71,971
1114,26.72,972
1115,26.71,973
1116,26.71,974
1117,26.71,976
1119,26.72,977
1120,26.76,978
1121,26.78,979
1122,26.82,980
1124,26.85,981
1125,26.88,982
1126,26.91,983
1127,26.96,984
1129,26.97,985
1130,26.98,986
1131,26.96,987
1132,26.93,988
1134,26.91,990
1135,26.92,991
1136,26.95,992
1137,27,993
1138,27.05,994
1140,27.11,995
1141,27.17,996
1142,27.2,997
1143,27.24,998
1145,27.26,999
1146,27.26,1000
1147,27.25,1001
1148,27.24,1002
1150,27.26,1004
1151,27.28,1005
1152,27.31,1006
1153,27.36,1007
1155,27.4,1008
1156,27.46,1009
1157,27.5,1010
1159,27.57,1012
1160,27.61,1013
1161,27.65,1014
1162,27.68,1015
1164,27.72,1016
1165,27.75,1017
1166,27.8,1018
1167,27.81,1019
1169,27.86,1020
1170,27.88,1021
1171,27.92,1022
1172,27.94,1023
1174,27.97,1025
1175,27.99,1026
1176,28.01,1027
1177,28.04,1028
1179,28.06,1029
1180,28.08,1030
1181,28.11,1031
1182,28.12,1032
1183,28.14,1033
1185,28.17,1034
1186,28.18,1035
1187,28.2,1036
1188,28.2,1037
1190,27.89,1039
1191,-0.3949,1040
1192,-0.3863,1041
1193,-0.3863,1042
1195,-0.3863,1043
1196,-0.3863,1044
1197,-0.3863,1045
1198,-0.3863,1046
1200,-0.3863,1047
1201,-0.3777,1048
1202,-0.3863,1049
1203,-0.3777,1050
1204,-0.3777,1051
1206,-0.3863,1053
1207,-0.3777,1054
1208,-0.3777,1055
1209,-0.3777,1056
1211,-0.3777,1057
1212,-0.3777,1058
1213,-0.3863,1059
1214,-0.3863,1060
1216,-0.3863,1061
1217,-0.3863,1062
1218,-0.3777,1063
1219,-0.3863,1064
1221,-0.3863,1065
1222,-0.3777,1067
1223,-0.3777,1068
1224,-0.3777,1069
1225,-0.3863,1070
1227,-0.3777,1071
1228,-0.3777,1072
1229,-0.3777,1073
1230,-0.3777,1074
1232,-0.3863,1075
1233,-0.3777,1076
1234,-0.3777,1077
1235,-0.3777,1078
1237,-0.3777,1079
1238,-0.3863,1081
1239,-0.3777,1082
1240,-0.3777,1083
1242,-0.3863,1084
1243,-0.3777,1085
1244,-0.3777,1086
1245,-0.3777,1087
1246,-0.3777,1088
1248,-0.3777,1089
1249,-0.3777,1090
1250,-0.3691,1091
1251,-0.3691,1092
1253,-0.3691,1094
1254,-0.3777,1095
1255,-0.3777,1096
1256,-0.3777,1097
1258,-0.3777,1098
1259,-0.3777,1099
1260,-0.3777,1100
1261,-0.3777,1101
1263,-0.3691,1102
1264,-0.3777,1103
1265,-0.3691,1104
1266,-0.3691,1105
1267,-0.3691,1106
1269,-0.3691,1108
1270,-0.3691,1109
1271,-0.3691,1110
1272,-0.3605,1111
1274,-0.3605,1112
1275,-0.3605,1113
1276,-0.352,1114
1277,-0.3605,1115
1279,-0.3605,1116
1280,-0.3605,1117
1281,-0.3605,1118
1282,-0.352,1119
1283,-0.3605,1120
1285,-0.352,1122
1286,-0.352,1123
1287,-0.3691,1124
1288,-0.3605,1125
1290,-0.3605,1126
1291,-0.3605,1127
1292,-0.3605,1128
1293,-0.352,1129
1295,-0.3605,1130
1296,-0.352,1131
1297,-0.3605,1132
1298,-0.352,1133
1300,-0.3605,1134
1301,-0.352,1136
1302,-0.352,1137
1303,-0.352,1138
1304,-0.352,1139
1306,-0.3691,1140
1307,-0.3691,1141
1308,-0.3605,1142
1309,-0.3691,1143
1311,-0.3691,1144
1312,-0.3605,1145
1313,-0.3605,1146
1314,-0.3691,1147
1316,-0.3691,1148
1317,-0.3691,1150
1318,-0.3777,1151
1319,-0.4035,1152
1321,-0.3949,1153
1322,-0.4206,1154
1323,-0.4035,1155
1324,-0.4035,1156
1325,-0.3949,1157
1327,-0.3949,1158
1328,-0.3949,1159
1329,-0.3949,1160
1330,-0.3949,1161
1332,-0.3949,1163
1333,-0.3949,1164
1334,-0.4035,1165
1335,-0.3949,1166
1337,-0.3949,1167
1338,-0.3863,1168
1339,-0.3949,1169
1340,-0.3949,1170
1342,-0.3949,1171
1343,-0.3949,1172
1344,-0.3863,1173
1345,-0.3949,1174
1346,-0.3949,1175
1348,-0.3949,1177
1349,-0.3949,1178
1350,-0.3949,1179
1351,-0.3863,1180
1353,-0.3863,1181
1354,-0.3949,1182
1355,-0.3949,1183
1356,-0.4035,1184
1358,-0.4035,1185
1359,-0.3949,1186
1360,-0.3949,1187
1361,-0.3949,1188
1363,-0.3949,1189
1364,-0.4035,1191
1365,-0.4035,1192
1366,-0.3949,1193
1367,-0.4035,1194
1369,-0.3949,1195
1370,-0.3949,1196
1371,-0.3949,1197
1372,-0.3949,1198
1374,-0.3949,1199
1375,-0.3863,1200
1376,-0.3949,1201
1377,-0.3863,1202
1379,-0.3949,1203
1380,-0.3949,1205
1381,-0.3949,1206
1382,-0.3949,1207
1384,-0.3949,1208
1385,-0.3949,1209
1386,-0.3863,1210
1387,-0.3949,1211
1388,-0.3949,1212
1390,-0.3949,1213
1391,-0.3949,1214
1392,-0.3949,1215
1393,-0.3949,1216
1395,-0.3949,1217
1396,-0.3949,1219
1397,-0.3863,1220
1398,-0.3863,1221
1400,-0.3949,1222
1401,-0.3949,1223
1402,-0.3863,1224
1403,-0.3949,1225
1405,-0.3863,1226
1406,-0.3949,1227
1407,-0.3863,1228
1408,-0.3949,1229
1409,-0.3949,1230
1411,-0.3863,1232
1412,-0.3863,1233
1413,-0.3863,1234
1414,-0.3863,1235
1416,-0.3863,1236
1417,-0.3863,1237
1418,-0.3863,1238
1419,-0.3863,1239
1421,-0.3863,1240
1422,-0.3863,1241
1423,-0.3949,1242
1424,-0.3863,1243
1426,-0.3863,1244
1427,-0.3863,1246
1428,-0.3863,1247
1429,-0.3863,1248
1430,-0.3949,1249
1432,-0.3949,1250
1433,-0.3863,1251
1434,-0.3863,1252
1435,-0.3863,1253
1437,-0.3863,1254
1438,-0.3863,1255
1439,-0.3863,1256
1440,-0.3863,1257
1442,-0.3863,1258
1443,-0.3863,1260
1444,-0.3863,1261
1445,-0.3863,1262
1447,-0.3863,1263
1448,-0.3777,1264
1449,-0.3863,1265
1450,-0.3863,1266
1451,-0.3863,1267
1453,-0.3863,1268
1454,-0.3863,1269
1455,-0.3863,1270
1456,-0.3863,1271
1458,-0.3863,1272
1459,-0.3863,1274
1460,-0.3863,1275
1461,-0.3863,1276
1463,-0.3777,1277
1464,-0.3777,1278
1465,-0.3863,1279
1466,-0.3863,1280
1468,-0.3863,1281
1469,-0.3863,1282
1470,-0.3863,1283
1471,-0.3863,1284
1472,-0.3863,1285
1474,-0.3863,1286
1475,-0.3863,1288
1476,-0.3777,1289
1477,-0.3863,1290
1479,-0.3863,1291
1480,-0.3863,1292
1481,-0.3863,1293
1482,-0.3863,1294
1484,-0.3863,1295
1485,-0.3863,1296
1486,-0.3863,1297
1487,-0.3863,1298
1488,-0.3863,1299
1490,-0.3863,1301
1491,-0.3863,1302
1492,-0.3863,1303
1493,-0.3863,1304
1495,-0.3863,1305
1496,-0.3863,1306
1497,-0.3863,1307
1498,-0.3863,1308
1500,-0.3863,1310
1502,-0.3863,1311
1503,-0.3863,1312
1504,-0.3863,1313
1505,-0.3863,1314
1506,-0.3863,1315
1508,-0.3863,1316
1509,-0.3863,1317
1510,-0.3777,1318
1511,-0.3777,1319
1513,-0.3777,1321
1514,-0.3777,1322
1515,-0.3863,1323
1516,-0.3777,1324
1518,-0.3863,1325
1519,-0.3777,1326
1520,-0.3777,1327
1521,-0.3863,1328
1523,-0.3777,1329
1524,-0.3949,1330
1525,-0.3863,1331
1526,-0.3949,1332
1527,-0.3863,1333
1529,-0.3863,1335
1530,-0.3863,1336
1531,-0.3863,1337
1532,-0.3863,1338
1534,-0.3863,1339
1535,-0.3863,1340
1536,-0.3863,1341
1537,-0.3863,1342
1539,-0.3863,1343
1540,-0.3863,1344
1541,-0.3863,1345
1542,-0.3863,1346
1544,-0.3777,1347
1545,-0.3777,1349
1546,-0.3777,1350
1547,-0.3777,1351
1548,-0.3863,1352
1550,-0.3863,1353
1551,-0.3863,1354
1552,-0.3777,1355
1553,-0.3777,1356
1555,-0.3777,1357
1556,-0.3777,1358
1557,-0.3863,1359
1558,-0.3863,1360
1560,-0.3863,1362
1561,-0.3777,1363
1562,-0.3777,1364
1563,-0.3777,1365
1565,-0.3777,1366
1566,-0.3777,1367
1567,-0.3863,1368
1568,-0.3777,1369
1569,-0.3777,1370
1571,-0.3863,1371
1572,-0.3777,1372
1573,-0.3777,1373
1574,-0.3691,1374
1576,-0.3691,1376
1577,-0.3691,1377
1578,-0.3691,1378
1579,-0.3605,1379
1581,-0.3605,1380
1582,-0.3605,1381
1583,-0.3605,1382
1584,-0.352,1383
1586,-0.3777,1384
1587,-0.3863,1385
1588,-0.3777,1386
1589,-0.3777,1387
1590,-0.3777,1388
1592,-0.3777,1390
1593,-0.3777,1391
1594,-0.3777,1392
1595,-0.3777,1393
1597,-0.3777,1394
1598,-0.3777,1395
1599,-0.3777,1396
1600,-0.3691,1397
1602,-0.3691,1398
1603,-0.3691,1399
1604,-0.3605,1400
1605,-0.3691,1401
1607,-0.3691,1402
1608,-0.3691,1404
1609,-0.3691,1405
1610,-0.3605,1406
1611,-0.3605,1407
1613,-0.3691,1408
1614,-0.3691,1409
1615,-0.3605,1410
1616,-0.3605,1411
1618,-0.3605,1412
1619,-0.352,1413
1620,-0.3605,1414
1621,-0.352,1415
1623,-0.352,1416
1624,-0.352,1418
1625,-0.3434,1419
1626,-0.3691,1420
1628,-0.3863,1421
1629,-0.3777,1422
1630,-0.3691,1423
1631,-0.3691,1424
1632,-0.3691,1425
1634,-0.3691,1426
1635,-0.3691,1427
1636,-0.3691,1428
1637,-0.3691,1429
1639,-0.3691,1431
1640,-0.3691,1432
1641,-0.3605,1433
1642,-0.3605,1434
1644,-0.3605,1435
1645,-0.3605,1436
1646,-0.352,1437
1647,-0.3691,1438
1649,-0.3691,1439
1650,-0.3605,1440
1651,-0.3605,1441
1652,-0.3605,1442
1653,-0.3605,1443
1655,-0.3691,1445
1656,-0.3605,1446
1657,-0.3605,1447
1658,-0.3605,1448
1660,-0.3605,1449
1661,-0.3605,1450
1662,-0.3605,1451
1663,-0.352,1452
1665,-0.352,1453
1666,-0.3434,1454
1667,-0.352,1455
1668,-0.3434,1456
1670,-0.3434,1457
1671,-0.3605,1459
1672,-0.3605,1460
1673,-0.3605,1461
1674,-0.3605,1462
1676,-0.3605,1463
1677,-0.352,1464
1678,-0.352,1465
1679,-0.3605,1466
1681,-0.352,1467
1682,-0.352,1468
1683,-0.352,1469
1684,-0.352,1470
1686,-0.352,1471
1687,-0.3605,1473
1688,-0.3605,1474
1689,-0.3691,1475
1691,-0.3949,1476
1692,-0.3863,1477
1693,-0.3777,1478
1694,-0.3777,1479
1695,-0.3777,1480
1697,-0.3777,1481
1698,-0.3777,1482
1699,-0.3777,1483
1700,-0.3691,1484
1702,-0.3777,1485
1703,-0.3691,1487
1704,-0.3691,1488
1705,-0.3691,1489
1707,-0.3777,1490
1708,-0.3691,1491
1709,-0.3691,1492
1710,-0.3691,1493
1712,-0.3691,1494
1713,-0.3691,1495
1714,-0.3691,1496
1715,-0.3691,1497
1716,-0.3691,1498
1718,-0.3691,1500
1719,-0.3605,1501
1720,-0.3691,1502
1721,-0.3691,1503
1723,-0.3691,1504
1724,-0.3691,1505
1725,-0.3691,1506
1726,-0.3605,1507
1728,-0.3691,1508
1729,-0.3691,1509
1730,-0.3691,1510
1731,-0.3605,1511
1732,-0.3605,1512
1734,-0.3605,1514
1735,-0.3691,1515
1736,-0.3605,1516
1737,-0.3691,1517
1739,-0.3691,1518
1740,-0.3691,1519
1741,-0.3605,1520
1742,-0.3691,1521
1744,-0.3691,1522
1745,-0.3605,1523
1746,-0.3605,1524
1747,-0.352,1525
1749,-0.3605,1526
1750,-0.3605,1528
1751,-0.352,1529
1752,-0.352,1530
1752,-0.352,1531
1755,-0.3434,1532
1756,-0.3434,1533
1757,-0.3434,1534
1758,-0.3777,1535
1760,-0.3691,1536
1761,-0.3691,1537
1762,-0.3691,1538
1763,-0.3691,1539
1765,-0.3691,1540
1766,-0.3691,1542
1767,-0.3605,1543
1768,-0.3605,1544
1770,-0.3691,1545
1771,-0.3691,1546
1772,-0.3605,1547
1773,-0.3605,1548
1774,-0.3605,1549
1776,-0.352,1550
1777,-0.352,1551
1778,-0.352,1552
1779,-0.3691,1553
1781,-0.3777,1554
1782,-0.3691,1556
1783,-0.3691,1557
1784,-0.3691,1558
1786,-0.3605,1559
1787,-0.3605,1560
1788,-0.3605,1561
1789,-0.3691,1562
1791,-0.3691,1563
1792,-0.3691,1564
1793,-0.3605,1565
1794,-0.3605,1566
1795,-0.3605,1567
1797,-0.3691,1569
1798,-0.3605,1570
1799,-0.3605,1571
1800,-0.3605,1572
1802,-0.3605,1573
1803,-0.3691,1574
1804,-0.3605,1575
1805,-0.3605,1576
1807,-0.3605,1577
1808,-0.3605,1578
1809,-0.3605,1579
1810,-0.352,1580
1812,-0.352,1581
1813,-0.3605,1583
1814,-0.352,1584
1815,-0.3605,1585
1816,-0.352,1586
1818,-0.352,1587
1819,-0.3605,1588
1820,-0.3605,1589
1821,-0.3605,1590
1823,-0.352,1591
1824,-0.352,1592
1825,-0.352,1593
1826,-0.352,1594
1828,-0.3605,1595
1829,-0.3605,1597
1830,-0.3605,1598
1831,-0.3691,1598