File: wishlist/Koerner_2005_Polymer/RawDataFromAuthors/cnttobreak/cnt10pu.csv
Strain (%),Stress (MPa),Time (sec)
0.0407,0.5316,
1.422,1.5517,2
2.82,2.284,4
4.2,2.802,6
5.6,3.19,8
6.98,3.477,9
8.37,3.75,11
9.76,3.951,13
11.14,4.138,15
12.54,4.296,17
13.93,4.44,19
15.31,4.569,21
16.7,4.684,23
18.1,4.799,24
19.49,4.899,26
20.9,5,28
22.3,5.086,30
23.7,5.187,32
25,5.273,34
26.4,5.374,36
27.8,5.46,38
29.2,5.546,39
30.6,5.618,41
32,5.704,43
33.4,5.761,45
34.8,5.819,47
36.2,5.876,49
37.5,5.934,51
38.9,5.963,53
40.3,6.02,54
41.7,6.049,56
43.1,6.078,58
44.5,6.106,60
45.9,6.135,62
47.3,6.164,64
48.6,6.193,66
50,6.207,68
51.4,6.236,69
52.8,6.264,71
54.2,6.279,73
55.6,6.293,75
57,6.307,77
58.4,6.351,79
59.8,6.379,81
61.1,6.408,83
62.5,6.422,84
63.9,6.451,86
65.3,6.466,88
66.7,6.494,90
68.1,6.523,92
69.5,6.552,94
70.9,6.58,96
72.3,6.595,98
73.7,6.609,99
75,6.624,101
76.4,6.638,103
77.8,6.667,105
79.2,6.695,107
80.6,6.724,109
82,6.739,111
83.4,6.753,113
84.8,6.782,114
86.2,6.81,116
87.5,6.839,118
88.9,6.868,120
90.3,6.882,122
91.7,6.911,124
93.1,6.925,126
94.5,6.954,128
95.9,6.968,129
97.3,6.983,131
98.6,6.997,133
100,7.011,135
101.4,7.055,137
102.8,7.083,139
104.2,7.098,141
105.6,7.126,143
107,7.155,144
108.4,7.184,146
109.8,7.227,148
111.1,7.256,150
112.5,7.313,152
113.9,7.356,154
115.3,7.414,156
116.7,7.428,158
118.1,7.457,159
119.6,7.5,161
120.9,7.543,163
122.3,7.572,165
123.7,7.586,167
125.1,7.615,169
126.5,7.658,171
127.9,7.687,173
129.3,7.73,174
130.7,7.759,176
132,7.787,178
133.4,7.83,180
134.8,7.859,182
136.2,7.902,184
137.6,7.931,186
139,7.974,188
140.4,8.017,189
141.8,8.046,191
143.2,8.089,193
144.5,8.118,195
145.9,8.161,197
147.3,8.19,199
148.7,8.218,201
150.1,8.261,203
151.5,8.29,204
152.9,8.319,206
154.3,8.348,208
155.7,8.376,210
157.1,8.405,212
158.4,8.434,214
159.8,8.477,216
161.2,8.506,218
162.6,8.534,219
164,8.578,221
165.4,8.606,223
166.8,8.649,225
168.2,8.678,227
169.5,8.693,229
170.9,8.721,231
172.3,8.75,233
173.7,8.779,234
175.1,8.822,236
176.5,8.865,238
177.9,8.922,240
179.3,8.951,242
180.7,8.994,244
182,9.037,246
183.4,9.08,248
184.8,9.124,249
186.2,9.167,251
187.6,9.195,253
189,9.224,255
190.4,9.253,257
191.8,9.282,259
193.2,9.325,261
194.6,9.368,263
195.9,9.397,264
197.3,9.44,266
198.7,9.468,268
200,9.497,270
201,9.511,272
203,9.54,274
204,9.583,276
206,9.612,278
207,9.641,279
208,9.655,281
210,9.684,283
211,9.713,285
213,9.741,287
214,9.784,289
215,9.813,291
217,9.871,293
218,9.899,294
220,9.928,296
221,9.957,298
222,9.971,300
224,10,302
225,10.043,304
226,10.086,306
228,10.129,308
229,10.172,309
231,10.23,311
232,10.259,313
233,10.316,315
235,10.33,317
236,10.374,319
238,10.417,321
239,10.445,323
240,10.474,324
242,10.517,326
243,10.546,328
245,10.575,330
246,10.618,332
247,10.647,334
249,10.675,336
250,10.718,338
251,10.747,339
253,10.805,341
254,10.833,343
256,10.891,345
257,10.92,347
258,10.948,349
260,10.977,351
261,11.006,353
263,11.049,354
264,11.092,356
265,11.135,358
267,11.135,360
268,11.164,362
270,11.207,364
271,11.25,366
272,11.279,368
274,11.336,369
275,11.365,371
276,11.394,373
278,11.422,375
279,11.466,377
281,11.509,379
282,11.537,381
283,11.58,383
285,11.624,384
286,11.667,386
288,11.695,388
289,11.724,390
290,11.767,392
292,11.796,394
293,11.839,396
295,11.868,398
296,11.897,399
297,11.897,401
299,11.925,403
300,11.94,405
301,11.968,407
303,12.011,409
304,12.055,411
306,12.112,413
307,12.155,414
308,12.184,416
310,12.227,418
311,12.27,420
313,12.313,422
314,12.328,424
315,12.356,426
317,12.385,428
318,12.443,429
320,12.486,431
321,12.529,433
322,12.586,435
324,12.629,437
325,12.658,439
327,12.716,441
328,12.759,443
329,12.802,445
331,12.83,446
332,12.859,448
333,12.874,450
335,12.902,452
336,12.945,454
338,12.974,456
339,13.003,458
340,13.06,460
342,13.075,461
343,13.103,463
345,13.175,465
346,13.218,467
347,13.261,469
349,13.305,471
350,13.348,473
352,13.391,475
353,13.434,476
354,13.477,478
356,13.534,480
357,13.563,482
358,13.592,484
360,13.635,486
361,13.664,488
363,13.693,490
364,13.721,491
365,13.764,493
367,13.807,495
368,13.836,497
370,13.879,499
371,13.922,501
372,13.994,503
374,14.037,505
375,14.08,506
377,14.124,508
378,14.181,510
379,14.239,512
381,14.296,514
382,14.325,516
383,14.368,518
385,14.382,520
386,14.411,521
388,14.454,523
389,14.483,525
390,14.511,527
392,14.555,529
393,14.598,531
395,14.641,533
396,14.713,535
397,14.77,536
399,14.799,538
400,14.842,540
402,14.871,542
403,14.914,544
404,14.943,546
406,15,548
407,15.014,550
409,15.086,552
410,15.115,554
412,15.115,555
413,15.115,557
414,15.129,559
416,15.172,561
417,15.23,563
418,15.259,565
420,15.259,567
421,15.287,569
423,15.345,570
424,15.345,572
425,15.374,574
427,15.445,576
428,15.489,578
430,15.503,580
431,15.517,582
432,15.517,584
434,15.589,585
435,15.69,587
436,15.704,589
438,15.747,591
439,15.848,593
441,15.92,595
442,15.934,597
443,15.991,599
445,16.092,600
446,16.135,602
448,16.164,604
449,16.193,606
450,16.236,608
452,16.279,610
453,16.307,612
455,16.322,614
456,16.379,615
457,16.451,617
459,16.466,619
460,16.509,621
462,16.552,623
463,16.58,625
464,16.624,627
466,16.71,629
467,16.667,630
468,16.739,632
470,16.782,634
471,16.81,636
473,16.839,638
474,16.868,640
475,16.983,642
477,16.954,644
478,17.026,645
480,17.055,647
481,17.083,649
482,17.126,651
484,17.155,653
485,17.227,655
486,17.284,657
488,17.328,659
489,17.342,660
491,17.399,662
492,17.414,664
493,17.399,666
495,17.371,668
496,17.385,670
498,17.457,672
499,17.601,674
501,17.572,676
502,17.629,678
503,17.687,680
505,17.73,682
506,17.802,683
508,17.917,685
509,17.989,687
510,18.017,689
512,18.089,691
513,18.175,693
515,18.19,695
516,18.233,697
517,18.29,698
519,18.391,700
520,18.506,702
522,18.52,704
523,18.606,706
524,18.693,708
526,18.664,710
527,18.736,712
528,18.793,713
530,18.836,715
531,18.922,717
533,18.98,719
534,19.023,721
535,19.066,723
537,19.109,725
538,19.138,727
540,19.181,728
541,19.224,730
542,19.267,732
544,19.339,734
545,19.425,736
547,19.425,738
548,19.468,740
549,19.511,742
551,19.655,743
552,19.684,745
553,19.698,747
555,19.713,749
556,19.828,751
558,19.842,753
559,19.842,755
560,19.828,757
562,19.885,758
563,19.885,760
565,19.885,762
566,19.899,764
567,20.03,766
569,20.1,768
570,20.09,770
572,20.11,772
573,20.19,774
575,20.26,776
576,20.33,778
577,20.39,779
579,20.46,781
580,20.5,783
582,20.6,785
583,20.68,787
584,20.78,789
586,20.86,791
587,20.92,793
588,20.99,794
590,21.03,796
591,21.14,798
593,21.18,800
594,21.25,802
595,21.28,804
597,21.35,806
598,21.47,808
600,21.49,809
601,21.52,811
602,21.55,813
604,21.65,815
605,21.72,817
607,21.74,819
608,21.75,821
609,21.88,823
611,21.82,824
612,21.84,826
613,21.88,828
615,21.94,830
616,21.95,832
618,21.98,834
619,22.03,836
620,22.04,838
622,22.03,839
623,22.07,841
625,22.05,843
626,21.98,845
627,21.95,847
629,21.95,849
630,21.9,851
632,21.9,853
633,21.84,854
634,21.82,856
636,21.85,858
637,21.91,860
638,22.14,862
640,22.23,864
641,22.37,866
643,22.49,868
644,22.63,870
646,22.72,872
647,22.82,874
649,22.96,875
650,23.06,877
651,23.19,879
653,23.28,881
654,23.29,883
655,23.41,885
657,23.48,887
658,23.53,889
660,23.59,890
661,23.69,892
662,23.74,894
664,23.78,896
665,23.86,898
667,23.99,900
668,23.98,902
669,23.98,904
671,24.07,905
672,24.12,907
674,24.18,909
675,24.21,911
676,24.22,913
678,24.3,915
679,24.32,917
680,24.38,919
682,24.47,920
683,24.48,922
685,24.57,924
686,24.58,926
687,24.66,928
689,24.74,930
690,24.86,932
692,24.87,934
693,24.83,935
694,24.96,937
696,24.97,939
697,25.04,941
699,25.09,943
700,25.16,945
702,25.22,947
703,25.23,949
704,25.24,951
706,25.27,953
707,25.27,955
709,25.33,956
710,25.37,958
711,25.42,960
713,25.43,962
714,25.56,964
715,25.53,966
717,25.56,968
718,25.59,970
720,25.57,971
721,25.56,973
722,25.73,975
724,25.7,977
725,25.78,979
727,25.83,981
728,25.89,983
729,25.95,985
731,26.03,986
732,26.14,988
734,26.24,990
735,26.31,992
736,26.36,994
738,26.44,996
739,26.52,998
740,26.61,1000
742,26.67,1001
743,26.72,1003
745,26.78,1005
746,26.8,1007
747,26.81,1009
749,26.82,1011
750,26.84,1013
752,26.84,1015
753,26.8,1016
754,26.74,1018
756,26.71,1020
757,26.59,1022
759,26.51,1024
760,26.55,1026
761,26.44,1028
763,20.52,1030
764,0.10057,1031
765,0.10057,1033
767,0.10057,1035
768,0.11494,1037
770,0.10057,1039
771,0.10057,1041
772,0.10057,1043
774,0.11494,1045
775,0.10057,1046
777,0.10057,1048
778,0.10057,1050
779,0.10057,1052
781,0.10057,1054
782,0.10057,1056
784,0.10057,1058
785,0.08621,1060
786,0.10057,1061
788,0.08621,1063
789,0.10057,1065
790,0.10057,1067
792,0.08621,1069
793,0.08621,1071
795,0.08621,1073
796,0.10057,1075
797,0.10057,1076
799,0.10057,1078
800,0.10057,1080
802,0.08621,1082
803,0.10057,1084
804,0.08621,1086
806,0.08621,1088
807,0.10057,1090
809,0.10057,1091
810,0.10057,1093
811,0.10057,1095
813,0.08621,1097
814,0.08621,1099
815,0.10057,1101
817,0.10057,1103
818,0.10057,1105
820,0.10057,1106
821,0.10057,1108
822,0.10057,1110
824,0.10057,1112
825,0.10057,1114
827,0.10057,1116
828,0.10057,1118
829,0.10057,1120
831,0.08621,1121
832,0.10057,1123
834,0.10057,1125
835,0.08621,1127
836,0.10057,1129
838,0.10057,1131
839,0.10057,1133
840,0.10057,1135
842,0.10057,1136
843,0.10057,1138
845,0.10057,1140
846,0.10057,1142
847,0.10057,1144
849,0.10057,1146
850,0.10057,1148
852,0.10057,1150
853,0.10057,1151
854,0.10057,1153
856,0.10057,1155
857,0.10057,1157
859,0.10057,1159
860,0.10057,1161
861,0.10057,1163
863,0.10057,1165
864,0.10057,1166
865,0.10057,1168
867,0.10057,1170
868,0.10057,1172
870,0.10057,1174
871,0.10057,1176
872,0.10057,1178
874,0.10057,1180
875,0.10057,1181
877,0.11494,1183
878,0.10057,1185
879,0.10057,1187
881,0.10057,1189
882,0.10057,1191
884,0.10057,1193
885,0.10057,1195
886,0.10057,1196
888,0.10057,1198
889,0.11494,1200
890,0.11494,1202
892,0.10057,1204
893,0.11494,1206
895,0.11494,1208
896,0.11494,1210
897,0.11494,1211
899,0.11494,1213
900,0.11494,1215
902,0.11494,1217
903,0.11494,1219
904,0.11494,1221
906,0.11494,1223
907,0.10057,1225
909,0.11494,1226
910,0.10057,1228
911,0.11494,1230
913,0.10057,1232
914,0.11494,1234
915,0.10057,1236
917,0.10057,1238
918,0.10057,1240
920,0.10057,1241
921,0.10057,1243
922,0.11494,1245
924,0.11494,1247
925,0.10057,1249
927,0.10057,1251
928,0.10057,1253
929,0.11494,1255
931,0.10057,1256
932,0.10057,1258
934,0.10057,1260
935,0.11494,1262
936,0.10057,1264
938,0.10057,1266
939,0.10057,1268
940,0.10057,1270
942,0.11494,1271
943,0.10057,1273
945,0.10057,1275
946,0.10057,1277
947,0.10057,1279
949,0.10057,1281
950,0.10057,1283
952,0.10057,1285
953,0.10057,1286
954,0.10057,1288
956,0.10057,1290
957,0.11494,1292
959,0.10057,1294
960,0.10057,1296
961,0.10057,1298
963,0.10057,1300
964,0.10057,1301
965,0.10057,1303
967,0.10057,1305
968,0.10057,1307
970,0.11494,1309
971,0.11494,1311
972,0.10057,1313
974,0.10057,1315
975,0.10057,1316
977,0.10057,1318
978,0.11494,1320
979,0.10057,1322
981,0.11494,1324
982,0.10057,1326
984,0.11494,1328
985,0.11494,1330
986,0.10057,1331
988,0.10057,1333
989,0.10057,1335
990,0.10057,1337
992,0.10057,1339
993,0.11494,1341
995,0.11494,1343
996,0.10057,1345
997,0.10057,1346
999,0.10057,1349
1001,0.10057,1351
1002,0.10057,1353
1003,0.11494,1355
1005,0.11494,1357
1006,0.11494,1358
1008,0.10057,1360
1009,0.10057,1362
1010,0.10057,1364
1012,0.10057,1366
1013,0.11494,1368
1015,0.10057,1370
1016,0.11494,1372
1017,0.11494,1373
1019,0.12931,1375
1020,0.10057,1377
1022,0.11494,1379
1023,0.10057,1381
1024,0.11494,1383
1026,0.10057,1385
1027,0.11494,1387
1028,0.10057,1388
1030,0.10057,1390
1031,0.11494,1392
1033,0.10057,1394
1034,0.10057,1396
1035,0.11494,1398
1037,0.11494,1400
1038,0.11494,1402
1040,0.10057,1403
1041,0.10057,1405
1042,0.11494,1407
1044,0.11494,1409
1045,0.11494,1411
1047,0.11494,1413
1048,0.11494,1415
1049,0.11494,1417
1051,0.10057,1418
1052,0.11494,1420
1053,0.11494,1422
1055,0.11494,1424
1056,0.10057,1426
1058,0.11494,1428
1059,0.11494,1430
1060,0.11494,1432
1062,0.10057,1433
1063,0.10057,1435
1065,0.10057,1437
1066,0.11494,1439
1067,0.11494,1441
1069,0.11494,1443
1070,0.11494,1445
1072,0.11494,1447
1073,0.10057,1448
1074,0.11494,1450
1076,0.10057,1452
1077,0.11494,1454
1078,0.10057,1456
1080,0.10057,1458
1081,0.10057,1460
1083,0.10057,1462
1084,0.11494,1463
1085,0.11494,1465
1087,0.10057,1467
1088,0.11494,1469
1090,0.11494,1471
1091,0.10057,1473
1092,0.10057,1475
1094,0.11494,1477
1095,0.11494,1478
1097,0.11494,1480
1098,0.10057,1482
1099,0.10057,1484
1101,0.11494,1486
1102,0.11494,1488
1103,0.11494,1490
1105,0.11494,1492
1106,0.11494,1493
1108,0.10057,1495
1109,0.11494,1497
1110,0.11494,1499
1112,0.11494,1501
1113,0.11494,1503
1115,0.11494,1505
1116,0.12931,1507
1117,0.11494,1508
1119,0.11494,1510
1120,0.10057,1512
1122,0.10057,1514
1123,0.11494,1516
1124,0.11494,1518
1126,0.11494,1520
1127,0.10057,1522
1128,0.10057,1523
1130,0.10057,1525
1131,0.11494,1527
1133,0.10057,1529
1134,0.11494,1531
1135,0.10057,1533
1137,0.10057,1535
1138,0.10057,1537
1140,0.10057,1538
1141,0.10057,1540
1142,0.11494,1542
1144,0.10057,1544
1145,0.10057,1546
1147,0.11494,1548
1148,0.10057,1550
1149,0.11494,1552
1151,0.11494,1553
1152,0.11494,1555
1153,0.11494,1557
1155,0.11494,1559
1156,0.11494,1561
1158,0.11494,1563
1159,0.11494,1565
1160,0.11494,1567
1162,0.10057,1568
1163,0.10057,1570
1165,0.10057,1572
1166,0.11494,1574
1167,0.11494,1576
1169,0.11494,1578
1170,0.11494,1580
1172,0.10057,1582
1173,0.10057,1583
1174,0.11494,1585
1176,0.11494,1587
1177,0.10057,1589
1178,0.10057,1591
1180,0.11494,1593
1181,0.10057,1595
1183,0.10057,1597
1184,0.10057,1598
1185,0.10057,1600
1187,0.10057,1602
1188,0.10057,1604
1190,0.10057,1606
1191,0.10057,1608
1192,0.10057,1610
1194,0.11494,1612
1195,0.10057,1613
1197,0.11494,1615
1198,0.11494,1617
1199,0.11494,1619
1201,0.11494,1621
1202,0.11494,1623
1203,0.12931,1625
1205,0.12931,1627
1206,0.12931,1628
1208,0.12931,1630
1209,0.11494,1632
1210,0.11494,1634
1212,0.11494,1636
1213,0.12931,1638
1215,0.12931,1640
1216,0.14368,1642
1217,0.12931,1643
1219,0.12931,1645
1220,0.12931,1647
1222,0.14368,1649
1223,0.12931,1651
1224,0.12931,1653
1226,0.12931,1655
1227,0.12931,1657
1228,0.12931,1658
1230,0.12931,1660
1231,0.12931,1662
1233,0.12931,1664
1234,0.12931,1666
1235,0.12931,1668
1237,0.12931,1670
1238,0.12931,1672
1240,0.12931,1673
1241,0.12931,1675
1242,0.12931,1677
1244,0.12931,1679
1245,0.12931,1681
1247,0.12931,1683
1248,0.12931,1685
1249,0.12931,1687
1251,0.12931,1688
1252,0.12931,1690
1253,0.12931,1692
1255,0.12931,1694
1256,0.12931,1696
1258,0.14368,1698
1259,0.14368,1700
1260,0.14368,1702
1262,0.14368,1703
1263,0.14368,1705
1265,0.14368,1707
1266,0.12931,1709
1267,0.12931,1711
1269,0.12931,1713
1270,0.14368,1715
1272,0.14368,1717
1273,0.14368,1718
1274,0.14368,1720
1276,0.14368,1722
1277,0.12931,1724
1278,0.12931,1726
1280,0.14368,1728
1281,0.14368,1730
1283,0.14368,1732
1284,0.14368,1733
1285,0.14368,1735
1287,0.14368,1737
1288,0.12931,1739
1290,0.12931,1741
1291,0.14368,1743
1292,0.12931,1745
1294,0.10057,1747
1295,0.10057,1748
1297,0.10057,1750
1298,0.10057,1752
1299,0.08621,1754
1301,0.08621,1756
1302,0.10057,1758
1303,0.11494,1760
1305,0.10057,1762
1306,0.11494,1763
1308,0.11494,1765
1309,0.11494,1767
1310,0.11494,1769
1312,0.10057,1771
1313,0.10057,1773
1315,0.11494,1775
1316,0.11494,1777
1317,0.10057,1778
1319,0.11494,1780
1320,0.10057,1782
1322,0.10057,1784
1323,0.11494,1786
1324,0.10057,1788
1326,0.10057,1790
1327,0.11494,1792
1328,0.11494,1793
1330,0.11494,1795
1331,0.11494,1797
1333,0.11494,1799
1334,0.11494,1801
1335,0.11494,1803
1337,0.11494,1805
1338,0.10057,1807
1340,0.11494,1808
1341,0.11494,1810
1342,0.11494,1812
1344,0.12931,1814
1345,0.12931,1816
1347,0.12931,1818
1348,0.12931,1820
1349,0.14368,1822
1351,0.14368,1823
1352,0.14368,1825
1353,0.14368,1827
1355,0.14368,1829
1356,0.14368,1831
1358,0.14368,1833
1359,0.12931,1835
1360,0.14368,1837
1362,0.15805,1838
1363,0.14368,1840
1365,0.14368,1842
1366,0.14368,1844
1367,0.14368,1846
1369,0.12931,1848
1370,0.12931,1850
1372,0.14368,1852
1373,0.14368,1853
1374,0.15805,1855
1376,0.14368,1857
1377,0.15805,1859
1378,0.15805,1861
1380,0.15805,1863
1381,0.15805,1865
1383,0.14368,1867
1384,0.14368,1868
1385,0.14368,1870
1387,0.14368,1872
1388,0.14368,1874
1390,0.14368,1876
1391,0.14368,1878
1392,0.14368,1880
1394,0.15805,1882
1395,0.15805,1883
1397,0.14368,1885
1398,0.14368,1887
1399,0.14368,1889
1401,0.14368,1891
1402,0.14368,1893
1404,0.14368,1895
1405,0.14368,1897
1406,0.14368,1898
1408,0.14368,1900
1409,0.15805,1902
1410,0.15805,1904
1412,0.15805,1906
1413,0.15805,1908
1415,0.15805,1910
1416,0.17241,1912
1417,0.14368,1913
1419,0.15805,1915
1420,0.15805,1917
1422,0.14368,1919
1423,0.17241,1921
1424,0.15805,1923
1426,0.14368,1925
1427,0.15805,1927
1429,0.15805,1928
1430,0.15805,1930
1431,0.15805,1932
1433,0.15805,1934
1434,0.15805,1936
1435,0.15805,1938
1437,0.15805,1940
1438,0.15805,1942
1440,0.15805,1943
1441,0.15805,1945
1442,0.14368,1947
1444,0.15805,1949
1445,0.15805,1951
1447,0.15805,1953
1448,0.15805,1955
1449,0.15805,1957
1451,0.15805,1958
1452,0.15805,1960
1454,0.15805,1962
1455,0.15805,1964
1456,0.15805,1966
1458,0.15805,1968
1459,0.14368,1970
1460,0.15805,1972
1462,0.15805,1973
1463,0.15805,1975
1465,0.15805,1977
1466,0.15805,1979
1467,0.15805,1981
1469,0.15805,1983
1470,0.15805,1985
1472,0.15805,1987
1473,0.17241,1988
1474,0.15805,1990
1476,0.17241,1992
1477,0.15805,1994
1479,0.15805,1996
1480,0.15805,1998
1481,0.15805,2000
1483,0.15805,2002
1484,0.15805,2003
1485,0.17241,2005
1487,0.15805,2007
1488,0.15805,2009
1490,0.17241,2011
1491,0.15805,2013
1492,0.15805,2015
1494,0.17241,2017
1495,0.17241,2019
1497,0.15805,2020
1498,0.17241,2022
1500,0.17241,2025
1501,0.17241,2027
1503,0.15805,2029
1504,0.15805,2030
1505,0.17241,2032
1507,0.15805,2034
1508,0.17241,2036
1510,0.17241,2038
1511,0.17241,2040
1512,0.15805,2042
1514,0.17241,2044
1515,0.17241,2045
1517,0.17241,2047
1518,0.17241,2049
1519,0.17241,2051
1521,0.18678,2053
1522,0.17241,2055
1523,0.17241,2057
1525,0.17241,2059
1526,0.17241,2060
1528,0.17241,2062
1529,0.15805,2064
1530,0.15805,2066
1532,0.15805,2068
1533,0.17241,2070
1535,0.18678,2072
1536,0.18678,2074
1537,0.17241,2075
1539,0.17241,2077
1540,0.15805,2079
1542,0.17241,2081
1543,0.15805,2083
1544,0.15805,2085
1546,0.17241,2087
1547,0.17241,2089
1548,0.15805,2090
1550,0.15805,2092
1551,0.12931,2094
1553,0.11494,2096
1554,0.11494,2098
1555,0.10057,2100
1557,0.11494,2102
1558,0.11494,2104
1560,0.10057,2105
1561,0.11494,2107
1562,0.11494,2109
1564,0.11494,2111
1565,0.11494,2113
1567,0.11494,2115
1568,0.12931,2117
1569,0.11494,2119
1571,0.11494,2120
1572,0.11494,2122
1573,0.11494,2124
1575,0.12931,2126
1576,0.12931,2128
1578,0.12931,2130
1579,0.12931,2132
1580,0.12931,2134
1582,0.14368,2135
1583,0.14368,2137
1585,0.14368,2139
1586,0.14368,2141
1587,0.14368,2143
1589,0.15805,2145
1590,0.15805,2147
1592,0.15805,2149
1593,0.15805,2150
1594,0.15805,2152
1596,0.15805,2154
1597,0.14368,2156
1598,0.14368,2158
1600,0.15805,2160
1601,0.14368,2162
1603,0.14368,2164
1604,0.15805,2165
1605,0.17241,2167
1607,0.15805,2169
1608,0.14368,2171
1610,0.14368,2173
1611,0.14368,2175
1612,0.14368,2177
1614,0.15805,2179
1615,0.15805,2180
1617,0.14368,2182
1618,0.14368,2184
1619,0.15805,2186
1621,0.17241,2188
1622,0.15805,2190
1623,0.15805,2192
1625,0.15805,2194
1626,0.17241,2195
1628,0.17241,2197
1629,0.15805,2199
1630,0.15805,2201
1632,0.14368,2203
1633,0.14368,2205
1635,0.14368,2207
1636,0.15805,2209
1637,0.15805,2210
1639,0.15805,2212
1640,0.14368,2214
1642,0.15805,2216
1643,0.15805,2218
1644,0.15805,2220
1646,0.15805,2222
1647,0.15805,2224
1649,0.15805,2225
1650,0.15805,2227
1651,0.15805,2229
1653,0.14368,2231
1654,0.15805,2233
1655,0.15805,2235
1657,0.17241,2237
1658,0.18678,2239
1660,0.17241,2240
1661,0.18678,2242
1662,0.17241,2244
1664,0.18678,2246
1665,0.17241,2248
1667,0.17241,2250
1668,0.17241,2252
1669,0.17241,2254
1671,0.15805,2255
1672,0.17241,2257
1674,0.17241,2259
1675,0.17241,2261
1676,0.15805,2263
1678,0.17241,2265
1679,0.15805,2267
1680,0.15805,2269
1682,0.15805,2270
1683,0.15805,2272
1685,0.17241,2274
1686,0.17241,2276
1687,0.17241,2278
1689,0.18678,2280
1690,0.18678,2282
1692,0.18678,2284
1693,0.17241,2285
1694,0.17241,2287
1696,0.18678,2289
1697,0.18678,2291
1699,0.17241,2293
1700,0.17241,2295
1701,0.18678,2297
1703,0.17241,2299
1704,0.17241,2300
1705,0.18678,2302
1707,0.17241,2304
1708,0.17241,2306
1710,0.17241,2308
1711,0.18678,2310
1712,0.17241,2312
1714,0.17241,2314
1715,0.17241,2315
1717,0.17241,2317
1718,0.17241,2319
1719,0.18678,2321
1721,0.18678,2323
1722,0.18678,2325
1724,0.17241,2327
1725,0.15805,2329
1726,0.17241,2330
1728,0.17241,2332
1729,0.17241,2334
1730,0.17241,2336
1732,0.17241,2338
1733,0.17241,2340
1735,0.18678,2342
1736,0.18678,2344
1737,0.17241,2345
1739,0.18678,2347
1740,0.18678,2349
1742,0.18678,2351
1743,0.18678,2353
1744,0.18678,2355
1746,0.2011,2357
1747,0.2011,2359
1749,0.2011,2361
1750,0.18678,2362
1751,0.2011,2364
1753,0.2011,2366
1754,0.2155,2368
1755,0.2011,2370
1757,0.2011,2372
1758,0.2011,2374
1760,0.2011,2376
1761,0.2155,2377
1762,0.2155,2379
1764,0.2011,2381
1765,0.2011,2383
1767,0.2155,2385
1768,0.2011,2387
1769,0.2011,2389
1771,0.2011,2391
1772,0.2155,2392
1774,0.2011,2394
1775,0.2155,2396
1776,0.2011,2398
1778,0.2011,2400
1779,0.2155,2402
1780,0.2155,2404
1782,0.2155,2406
1783,0.2155,2407
1785,0.2011,2409
1786,0.2011,2411
1787,0.2011,2413
1789,0.2155,2415
1790,0.18678,2417
1792,0.2011,2419
1793,0.2155,2421
1794,0.18678,2422
1796,0.2011,2424
1797,0.2011,2426
1799,0.2011,2428
1800,0.2155,2430
1801,0.2011,2432
1803,0.2011,2434
1804,0.2011,2436
1806,0.2011,2437
1807,0.2155,2439
1808,0.2155,2441
1810,0.2155,2443
1811,0.2155,2445
1812,0.2011,2447
1814,0.2155,2449
1815,0.2011,2451
1817,0.2011,2452
1818,0.2011,2454
1819,0.2011,2456
1821,0.18678,2458
1822,0.18678,2460
1824,0.2011,2462
1825,0.2011,2464
1826,0.2011,2466
1828,0.2011,2467
1829,0.2011,2469
1831,0.2011,2471
1832,0.2155,2473
1833,0.2155,2475
1835,0.2011,2477
1836,0.2011,2479
1837,0.2011,2481
1839,0.2155,2482
1840,0.2155,2484
1842,0.2011,2486
1843,0.2011,2488
1844,0.2011,2490
1846,0.2011,2492
1847,0.2011,2494
1849,0.2011,2496
1850,0.2155,2497
1851,0.2155,2499
1853,0.2299,2501
1854,0.2011,2503
1856,0.2011,2505
1857,0.2155,2507
1858,0.2155,2509
1860,0.2155,2511
1861,0.2011,2512
1862,0.2011,2514
1864,0.2155,2516
1865,0.2155,2518
1867,0.2299,2520
1868,0.2299,2522
1869,0.2155,2524
1871,0.2155,2526
1872,0.2299,2527
1874,0.2155,2529
1875,0.2155,2531
1876,0.2155,2533
1878,0.2155,2535
1879,0.2299,2537
1881,0.2011,2539
1882,0.2155,2541
1883,0.2011,2542
1885,0.2011,2544
1886,0.2155,2546
1887,0.2155,2548
1889,0.2155,2550
1890,0.2155,2552
1892,0.2155,2554
1893,0.2299,2556
1894,0.2299,2557
1896,0.2011,2559
1897,0.2155,2561
1899,0.2155,2563
1900,0.2299,2565
1901,0.2299,2567
1903,0.2155,2569
1904,0.2299,2571
1906,0.2155,2572
1907,0.2155,2574
1908,0.2155,2576
1910,0.2155,2578
1911,0.2299,2580
1912,0.2299,2582
1914,0.2299,2584
1915,0.2443,2586
1917,0.2155,2587
1918,0.2155,2589
1919,0.2299,2591
1921,0.2299,2593
1922,0.2443,2595
1924,0.2443,2597
1925,0.2299,2599
1926,0.2299,2601
1928,0.2443,2602
1929,0.2299,2604
1931,0.2299,2606
1932,0.2443,2608
1933,0.2443,2610
1935,0.2299,2612
1936,0.2299,2614
1937,0.2443,2616
1939,0.2443,2617
1940,0.2443,2619
1942,0.2299,2621
1943,0.2299,2623
1944,0.2443,2625
1946,0.2299,2627
1947,0.2299,2629
1949,0.2299,2631
1950,0.2155,2632
1951,0.2299,2634
1953,0.2299,2636
1954,0.2443,2638
1956,0.2155,2640
1957,0.2155,2642
1958,0.2299,2644
1960,0.2155,2646
1961,0.2299,2647
1962,0.2299,2649
1964,0.2443,2651
1965,0.2443,2653
1967,0.2299,2655
1968,0.2299,2657
1969,0.2299,2659
1971,0.2443,2661
1972,0.2443,2662
1974,0.2443,2664
1975,0.2299,2666
1976,0.2299,2668
1978,0.2299,2670
1979,0.2443,2672
1981,0.2443,2674
1982,0.2299,2676
1983,0.2443,2677
1985,0.2443,2679
1986,0.2155,2681
1988,0.2299,2683
1989,0.2443,2685
1990,0.2443,2687
1992,0.2299,2689
1993,0.2443,2691
1994,0.2586,2692
1996,0.2155,2694
1997,0.2299,2696
1999,0.2443,2698
2000,0.2299,2701
2000,0.2299,2702
2000,0.2299,2704
2000,0.2443,2706
2010,0.2586,2708
2010,0.2299,2710
2010,0.2299,2712
2010,0.2443,2714
2010,0.2443,2716
2010,0.2299,2717
2010,0.2299,2719
2020,0.2443,2721
2020,0.2443,2723
2020,0.2299,2725
2020,0.2299,2727
2020,0.2299,2729
2020,0.2443,2731
2020,0.2299,2732
2030,0.2299,2734
2030,0.2155,2736
2030,0.2155,2738
2030,0.2011,2740
2030,0.2155,2742
2030,0.2155,2744
2030,0.2155,2746
2040,0.2299,2747
2040,0.2299,2749
2040,0.2299,2751
2040,0.2443,2753
2040,0.2299,2755
2040,0.2299,2757
2040,0.2299,2759
2040,0.2443,2761
2050,0.2299,2762
2050,0.2299,2764
2050,0.2443,2766
2050,0.2443,2768
2050,0.2299,2770
2050,0.2299,2772
2050,0.2443,2774
2060,0.2299,2776
2060,0.2299,2778
2060,0.2443,2779
2060,0.2155,2781
2060,0.2155,2783
2060,0.2299,2785
2060,0.2443,2787
2070,0.2443,2789
2070,0.2443,2791
2070,0.2155,2793
2070,0.2155,2794
2070,0.2155,2796
2070,0.2299,2798
2070,0.2299,2800
2080,0.2299,2802
2080,0.2155,2804
2080,0.2299,2806
2080,0.2299,2807