File: wishlist/Koerner_2005_Polymer/RawDataFromAuthors/cnttobreak/cntpu1p.csv
Strain (%),Stress (MPa),Time (sec)
0.0411,0.5143,
0.514,0.619,1
0.983,0.7333,1
1.452,0.8095,2
1.925,0.9143,3
2.4,1,3
2.87,1.0857,4
3.34,1.1714,5
3.81,1.2476,6
4.28,1.3143,6
4.74,1.3905,7
5.22,1.4571,8
5.69,1.5143,8
6.16,1.5714,9
6.63,1.6286,10
7.11,1.6857,10
7.58,1.7333,11
8.05,1.781,12
8.52,1.8286,12
8.99,1.8762,13
9.46,1.9143,14
9.93,1.9619,14
10.4,2,15
10.87,2.048,16
11.34,2.086,17
11.82,2.114,17
12.28,2.152,18
12.76,2.181,19
13.23,2.219,19
13.7,2.248,20
14.17,2.276,21
14.64,2.305,21
15.11,2.333,22
15.58,2.362,23
16.05,2.381,23
16.52,2.41,24
16.99,2.438,25
17.46,2.467,25
17.93,2.476,26
18.41,2.505,27
18.88,2.524,28
19.35,2.552,28
19.82,2.571,29
20.3,2.59,30
20.8,2.61,30
21.2,2.629,31
21.7,2.648,32
22.2,2.667,32
22.6,2.686,33
23.1,2.705,34
23.6,2.724,34
24.1,2.733,35
24.5,2.752,36
25,2.771,36
25.5,2.79,37
25.9,2.8,38
26.4,2.81,39
26.9,2.829,39
27.4,2.838,40
27.8,2.857,41
28.3,2.876,41
28.8,2.876,42
29.2,2.895,43
29.7,2.905,43
30.2,2.914,44
30.6,2.933,45
31.1,2.943,45
31.6,2.952,46
32.1,2.962,47
32.5,2.971,47
33,2.981,48
33.5,2.99,49
33.9,3,50
34.4,3.01,50
34.9,3.019,51
35.4,3.029,52
35.8,3.038,52
36.3,3.048,53
36.8,3.048,54
37.2,3.057,54
37.7,3.067,55
38.2,3.076,56
38.7,3.086,56
39.1,3.095,57
39.6,3.095,58
40.1,3.105,58
40.5,3.114,59
41,3.114,60
41.5,3.124,61
41.9,3.124,61
42.4,3.133,62
42.9,3.133,63
43.4,3.152,63
43.8,3.143,64
44.3,3.152,65
44.8,3.162,65
45.2,3.162,66
45.7,3.171,67
46.2,3.181,67
46.7,3.181,68
47.1,3.19,69
47.6,3.19,69
48.1,3.2,70
48.6,3.2,71
49,3.21,72
49.5,3.21,72
50,3.219,73
50.4,3.229,74
50.9,3.229,74
51.4,3.229,75
51.8,3.238,76
52.3,3.248,76
52.8,3.248,77
53.3,3.257,78
53.7,3.267,78
54.2,3.267,79
54.7,3.267,80
55.1,3.276,80
55.6,3.276,81
56.1,3.286,82
56.6,3.286,83
57,3.286,83
57.5,3.286,84
58,3.295,85
58.4,3.295,85
58.9,3.295,86
59.4,3.305,87
59.8,3.305,87
60.3,3.314,88
60.8,3.314,89
61.3,3.314,89
61.7,3.324,90
62.2,3.324,91
62.7,3.333,91
63.1,3.333,92
63.6,3.343,93
64.1,3.343,94
64.6,3.352,94
65,3.343,95
65.5,3.362,96
66,3.362,96
66.4,3.362,97
66.9,3.371,98
67.4,3.371,98
67.8,3.371,99
68.3,3.381,100
68.8,3.381,100
69.3,3.39,101
69.7,3.39,102
70.2,3.4,102
70.7,3.4,103
71.1,3.41,104
71.6,3.41,105
72.1,3.41,105
72.6,3.419,106
73,3.429,107
73.5,3.429,107
74,3.429,108
74.4,3.438,109
74.9,3.448,109
75.4,3.448,110
75.9,3.457,111
76.3,3.467,111
76.8,3.467,112
77.3,3.467,113
77.7,3.476,113
78.2,3.476,114
78.7,3.486,115
79.2,3.476,116
79.6,3.495,116
80.1,3.505,117
80.6,3.505,118
81,3.514,118
81.5,3.514,119
82,3.524,120
82.4,3.524,120
82.9,3.524,121
83.4,3.533,122
83.9,3.533,122
84.3,3.543,123
84.8,3.543,124
85.3,3.552,124
85.7,3.552,125
86.2,3.562,126
86.7,3.562,127
87.2,3.562,127
87.6,3.571,128
88.1,3.571,129
88.6,3.581,129
89,3.59,130
89.5,3.6,131
90,3.6,131
90.5,3.61,132
90.9,3.61,133
91.4,3.619,133
91.9,3.629,134
92.3,3.629,135
92.8,3.638,135
93.3,3.638,136
93.8,3.657,137
94.2,3.657,138
94.7,3.657,138
95.2,3.667,139
95.6,3.676,140
96.1,3.676,140
96.6,3.686,141
97,3.695,142
97.5,3.695,142
98,3.705,143
98.5,3.714,144
98.9,3.724,144
99.4,3.733,145
99.9,3.733,146
100.3,3.743,146
100.8,3.752,147
101.3,3.762,148
101.8,3.762,149
102.2,3.771,149
102.7,3.781,150
103.2,3.79,151
103.6,3.8,151
104.1,3.8,152
104.6,3.81,153
105,3.819,153
105.5,3.829,154
106,3.838,155
106.5,3.848,155
106.9,3.848,156
107.4,3.857,157
107.9,3.867,157
108.3,3.867,158
108.8,3.876,159
109.3,3.886,160
109.8,3.895,160
110.2,3.905,161
110.7,3.914,162
111.2,3.924,162
111.6,3.933,163
112.1,3.933,164
112.6,3.943,164
113.1,3.952,165
113.5,3.962,166
114,3.971,166
114.5,3.971,167
114.9,3.981,168
115.4,3.99,168
115.9,4,169
116.3,4.019,170
116.8,4.019,171
117.3,4.029,171
117.8,4.038,172
118.2,4.048,173
118.7,4.048,173
119.2,4.067,174
119.6,4.076,175
120.1,4.086,175
120.6,4.095,176
121.1,4.105,177
121.5,4.114,177
122,4.124,178
122.5,4.124,179
122.9,4.143,179
123.4,4.152,180
123.9,4.152,181
124.4,4.171,182
124.8,4.181,182
125.3,4.19,183
125.8,4.2,184
126.2,4.21,184
126.7,4.219,185
127.2,4.229,186
127.7,4.238,186
128.1,4.248,187
128.6,4.267,188
129.1,4.267,188
129.5,4.276,189
130,4.295,190
130.5,4.305,190
130.9,4.314,191
131.4,4.324,192
131.9,4.333,193
132.4,4.343,193
132.8,4.362,194
133.3,4.371,195
133.8,4.381,195
134.2,4.39,196
134.7,4.4,197
135.2,4.41,197
135.7,4.419,198
136.1,4.438,199
136.6,4.438,199
137.1,4.457,200
137.5,4.467,201
138,4.476,201
138.5,4.486,202
139,4.495,203
139.4,4.505,204
139.9,4.514,204
140.4,4.524,205
140.8,4.543,206
141.3,4.552,206
141.8,4.562,207
142.2,4.571,208
142.7,4.571,208
143.2,4.59,209
143.7,4.6,210
144.1,4.61,210
144.6,4.629,211
145.1,4.638,212
145.5,4.648,212
146,4.667,213
146.5,4.667,214
147,4.686,215
147.4,4.705,215
147.9,4.705,216
148.4,4.724,217
148.8,4.733,217
149.3,4.752,218
149.8,4.762,219
150.3,4.771,219
150.7,4.79,220
151.2,4.8,221
151.7,4.81,221
152.1,4.819,222
152.6,4.829,223
153.1,4.838,223
153.6,4.857,224
154,4.876,225
154.5,4.876,226
155,4.895,226
155.4,4.905,227
155.9,4.914,228
156.4,4.924,228
156.8,4.943,229
157.3,4.952,230
157.8,4.962,230
158.3,4.971,231
158.7,4.99,232
159.2,5,232
159.7,5.019,233
160.2,5.029,234
160.7,5.038,235
161.1,5.048,235
161.6,5.067,236
162.1,5.067,237
162.6,5.086,237
163,5.095,238
163.5,5.105,239
164,5.114,239
164.4,5.124,240
164.9,5.143,241
165.4,5.152,241
165.9,5.162,242
166.3,5.171,243
166.8,5.181,243
167.3,5.19,244
167.7,5.2,245
168.2,5.219,246
168.7,5.229,246
169.2,5.238,247
169.6,5.248,248
170.1,5.257,248
170.6,5.267,249
171,5.276,250
171.5,5.295,250
172,5.305,251
172.5,5.314,252
172.9,5.324,252
173.4,5.343,253
173.9,5.352,254
174.3,5.371,254
174.8,5.381,255
175.3,5.4,256
175.7,5.41,257
176.2,5.419,257
176.7,5.438,258
177.2,5.457,259
177.6,5.467,259
178.1,5.476,260
178.6,5.495,261
179,5.505,261
179.5,5.514,262
180,5.524,263
180.5,5.543,263
180.9,5.543,264
181.4,5.552,265
181.9,5.562,265
182.3,5.581,266
182.8,5.6,267
183.3,5.61,268
183.8,5.629,268
184.2,5.638,269
184.7,5.657,270
185.2,5.667,270
185.6,5.686,271
186.1,5.695,272
186.6,5.705,272
187,5.714,273
187.5,5.733,274
188,5.743,274
188.5,5.762,275
188.9,5.771,276
189.4,5.781,276
189.9,5.8,277
190.3,5.819,278
190.8,5.829,279
191.3,5.838,279
191.8,5.848,280
192.2,5.857,281
192.7,5.876,281
193.2,5.876,282
193.6,5.895,283
194.1,5.905,283
194.6,5.924,284
195.1,5.933,285
195.5,5.943,285
196,5.952,286
196.5,5.971,287
196.9,5.99,287
197.4,6.01,288
197.9,6.019,289
198.3,6.029,290
198.8,6.038,290
199.3,6.057,291
199.8,6.067,292
200,6.086,292
201,6.095,293
201,6.105,294
202,6.114,294
202,6.124,295
203,6.133,296
203,6.143,296
204,6.162,297
204,6.171,298
204,6.181,298
205,6.19,299
205,6.21,300
206,6.229,301
206,6.238,301
207,6.248,302
207,6.257,303
208,6.267,303
208,6.276,304
209,6.286,305
209,6.305,305
210,6.314,306
210,6.324,307
211,6.333,307
211,6.343,308
212,6.352,309
212,6.371,309
212,6.381,310
213,6.381,311
213,6.39,312
214,6.41,312
214,6.41,313
215,6.419,314
215,6.438,314
216,6.438,315
216,6.457,316
217,6.467,316
217,6.476,317
218,6.486,318
218,6.495,318
219,6.505,319
219,6.524,320
220,6.533,320
220,6.543,321
220,6.552,322
221,6.571,323
221,6.59,323
222,6.61,324
222,6.61,325
223,6.629,325
223,6.638,326
224,6.648,327
224,6.667,327
225,6.667,328
225,6.686,329
226,6.695,329
226,6.705,330
227,6.724,331
227,6.733,331
228,6.743,332
228,6.752,333
228,6.762,334
229,6.771,334
229,6.781,335
230,6.79,336
230,6.8,336
231,6.81,337
231,6.829,338
232,6.848,338
232,6.848,339
233,6.857,340
233,6.876,340
234,6.886,341
234,6.895,342
235,6.914,342
235,6.924,343
236,6.943,344
236,6.952,345
236,6.962,345
237,6.981,346
237,6.99,347
238,7,347
238,7.01,348
239,7.029,349
239,7.038,349
240,7.057,350
240,7.076,351
241,7.086,351
241,7.095,352
242,7.105,353
242,7.124,353
243,7.143,354
243,7.162,355
244,7.171,356
244,7.181,356
244,7.2,357
245,7.219,358
245,7.229,358
246,7.238,359
246,7.257,360
247,7.267,360
247,7.276,361
248,7.295,362
248,7.305,362
249,7.324,363
249,7.333,364
250,7.343,364
250,7.362,365
251,7.371,366
251,7.381,367
252,7.39,367
252,7.4,368
252,7.419,369
253,7.429,369
253,7.438,370
254,7.448,371
254,7.457,371
255,7.476,372
255,7.486,373
256,7.495,373
256,7.505,374
257,7.524,375
257,7.533,376
258,7.543,376
258,7.562,377
259,7.562,378
259,7.581,378
260,7.59,379
260,7.61,380
261,7.619,380
261,7.629,381
262,7.648,382
262,7.667,383
262,7.676,383
263,7.695,384
263,7.705,385
264,7.714,385
264,7.743,386
265,7.752,387
265,7.762,387
266,7.781,388
266,7.79,389
267,7.81,389
267,7.819,390
268,7.829,391
268,7.838,391
269,7.848,392
269,7.857,393
270,7.876,394
270,7.886,394
271,7.895,395
271,7.895,396
271,7.914,396
272,7.924,397
272,7.914,398
273,7.933,398
273,7.933,399
274,7.952,400
274,7.962,400
275,7.952,401
275,7.971,402
276,7.981,402
276,7.99,403
277,7.99,404
277,8,405
278,8.029,405
278,8.029,406
279,8.048,407
279,8.057,407
279,8.067,408
280,8.076,409
280,8.095,409
281,8.105,410
281,8.114,411
282,8.124,411
282,8.143,412
283,8.152,413
283,8.162,413
284,8.181,414
284,8.181,415
285,8.2,416
285,8.21,416
286,8.219,417
286,8.219,418
287,8.238,418
287,8.248,419
287,8.257,420
288,8.276,420
288,8.286,421
289,8.295,422
289,8.305,422
290,8.324,423
290,8.333,424
291,8.343,424
291,8.362,425
292,8.371,426
292,8.381,427
293,8.4,427
293,8.41,428
294,8.429,429
294,8.438,429
295,8.457,430
295,8.476,431
295,8.486,431
296,8.495,432
296,8.505,433
297,8.524,433
297,8.543,434
298,8.552,435
298,8.562,435
299,8.581,436
299,8.59,437
300,8.61,438
300,8.619,438
301,8.629,439
301,8.648,440
302,8.657,440
302,8.676,441
303,8.686,442
303,8.695,442
303,8.705,443
304,8.724,444
304,8.724,444
305,8.743,445
305,8.752,446
306,8.762,446
306,8.771,447
307,8.79,448
307,8.8,449
308,8.81,449
308,8.819,450
309,8.838,451
309,8.848,451
310,8.857,452
310,8.867,453
311,8.876,453
311,8.895,454
311,8.905,455
312,8.914,455
312,8.924,456
313,8.943,457
313,8.952,457
314,8.962,458
314,8.981,459
315,8.99,460
315,9.01,460
316,9.038,461
316,9.057,462
317,9.067,462
317,9.086,463
318,9.105,464
318,9.124,464
319,9.143,465
319,9.162,466
319,9.181,466
320,9.2,467
320,9.229,468
321,9.248,468
321,9.267,469
322,9.286,470
322,9.295,471
323,9.314,471
323,9.324,472
324,9.333,473
324,9.343,473
325,9.352,474
325,9.371,475
326,9.381,475
326,9.39,476
327,9.4,477
327,9.419,477
327,9.429,478
328,9.438,479
328,9.448,479
329,9.448,480
329,9.467,481
330,9.476,482
330,9.486,482
331,9.505,483
331,9.505,484
332,9.524,484
332,9.524,485
333,9.533,486
333,9.543,486
334,9.562,487
334,9.581,488
335,9.581,488
335,9.6,489
335,9.619,490
336,9.629,490
336,9.648,491
337,9.667,492
337,9.676,493
338,9.695,493
338,9.714,494
339,9.724,495
339,9.743,495
340,9.752,496
340,9.762,497
341,9.771,497
341,9.781,498
342,9.8,499
342,9.81,499
343,9.829,500
343,9.848,501
343,9.867,501
344,9.876,502
344,9.905,503
345,9.905,504
345,9.924,504
346,9.943,505
346,9.962,506
347,9.971,506
347,9.99,507
348,10,508
348,10.019,509
349,10.038,509
349,10.048,510
350,10.067,511
350,10.076,511
351,10.095,512
351,10.114,513
352,10.133,513
352,10.143,514
353,10.162,515
353,10.181,515
354,10.19,516
354,10.21,517
354,10.229,517
355,10.248,518
355,10.276,519
356,10.286,520
356,10.295,520
357,10.314,521
357,10.324,522
358,10.343,522
358,10.352,523
359,10.362,524
359,10.381,524
360,10.39,525
360,10.4,526
361,10.419,526
361,10.429,527
362,10.438,528
362,10.457,528
362,10.476,529
363,10.495,530
363,10.514,531
364,10.533,531
364,10.552,532
365,10.571,533
365,10.59,533
366,10.6,534
366,10.619,535
367,10.638,535
367,10.648,536
368,10.667,537
368,10.686,537
369,10.705,538
369,10.714,539
370,10.743,539
370,10.752,540
370,10.771,541
371,10.79,542
371,10.8,542
372,10.819,543
372,10.829,544
373,10.848,544
373,10.857,545
374,10.867,546
374,10.886,546
375,10.895,547
375,10.905,548
376,10.924,548
376,10.943,549
377,10.952,550
377,10.971,550
378,11,551
378,11.019,552
378,11.048,553
379,11.067,553
379,11.095,554
380,11.124,555
380,11.133,555
381,11.152,556
381,11.171,557
382,11.181,557
382,11.2,558
383,11.229,559
383,11.238,559
384,11.257,560
384,11.267,561
385,11.286,561
385,11.295,562
386,11.324,563
386,11.343,564
386,11.352,564
387,11.371,565
387,11.4,566
388,11.419,566
388,11.429,567
389,11.457,568
389,11.476,568
390,11.495,569
390,11.505,570
391,11.533,570
391,11.562,571
392,11.581,572
392,11.61,572
393,11.638,573
393,11.667,574
394,11.705,575
394,11.743,575
394,11.771,576
395,11.81,577
395,11.838,577
396,11.876,578
396,11.905,579
397,11.933,579
397,11.952,580
398,11.971,581
398,11.99,581
399,12.01,582
399,12.029,583
400,12.048,583
400,12.067,584
401,12.076,585
401,12.095,586
402,12.114,586
402,12.124,587
402,12.133,588
403,12.152,588
403,12.152,589
404,12.171,590
404,12.181,590
405,12.2,591
405,12.219,592
406,12.238,592
406,12.248,593
407,12.267,594
407,12.286,594
408,12.305,595
408,12.314,596
409,12.333,597
409,12.343,597
410,12.343,598
410,12.362,599
410,12.362,599
411,12.381,600
411,12.39,601
412,12.39,601
412,12.4,602
413,12.39,603
413,12.39,603
414,12.4,604
414,12.4,605
415,12.41,605
415,12.41,606
416,12.41,607
416,12.419,608
417,12.429,608
417,12.438,609
418,12.438,610
418,12.448,610
418,12.457,611
419,12.457,612
419,12.467,612
420,12.486,613
420,12.495,614
421,12.505,615
421,12.524,615
422,12.543,616
422,12.562,617
423,12.571,617
423,12.59,618
424,12.6,619
424,12.61,619
425,12.629,620
425,12.648,621
426,12.667,622
426,12.676,622
427,12.705,623
427,12.724,624
428,12.743,624
428,12.752,625
429,12.79,626
429,12.81,626
429,12.838,627
430,12.876,628
430,12.895,628
431,12.914,629
431,12.943,630
432,12.962,630
432,12.981,631
433,13,632
433,13.019,633
434,13.038,633
434,13.048,634
435,13.076,635
435,13.095,635
436,13.124,636
436,13.143,637
437,13.181,637
437,13.2,638
437,13.229,639
438,13.257,639
438,13.276,640
439,13.305,641
439,13.324,641
440,13.352,642
440,13.371,643
441,13.4,644
441,13.429,644
442,13.448,645
442,13.476,646
443,13.505,646
443,13.524,647
444,13.552,648
444,13.571,648
445,13.59,649
445,13.61,650
446,13.629,650
446,13.648,651
446,13.657,652
447,13.676,652
447,13.686,653
448,13.714,654
448,13.724,655
449,13.752,655
449,13.762,656
450,13.781,657
450,13.8,657
451,13.829,658
451,13.848,659
452,13.857,659
452,13.876,660
453,13.886,661
453,13.905,661
454,13.914,662
454,13.933,663
454,13.943,663
455,13.962,664
455,13.971,665
456,13.99,666
456,14,666
457,14.019,667
457,14.029,668
458,14.048,668
458,14.067,669
459,14.086,670
459,14.095,670
460,14.114,671
460,14.133,672
461,14.152,672
461,14.171,673
462,14.19,674
462,14.21,674
462,14.229,675
463,14.248,676
463,14.267,677
464,14.276,677
464,14.295,678
465,14.324,679
465,14.343,679
466,14.362,680
466,14.381,681
467,14.4,681
467,14.419,682
468,14.429,683
468,14.448,683
469,14.467,684
469,14.486,685
470,14.505,685
470,14.524,686
470,14.543,687
471,14.552,688
471,14.562,688
472,14.571,689
472,14.59,690
473,14.6,690
473,14.619,691
474,14.638,692
474,14.657,692
475,14.686,693
475,14.705,694
476,14.724,694
476,14.752,695
477,14.781,696
477,14.81,696
478,14.848,697
478,14.876,698
478,14.905,699
479,14.943,699
479,14.971,700
480,15.01,701
481,15.057,702
481,15.086,702
482,15.114,703
482,15.133,704
482,15.162,704
483,15.19,705
483,15.21,706
484,15.229,706
484,15.257,707
485,15.286,708
485,15.314,708
486,15.343,709
486,15.381,710
487,15.419,711
487,15.457,711
488,15.486,712
488,15.533,713
489,15.552,713
489,15.581,714
490,15.6,715
490,15.619,715
490,15.638,716
491,15.657,717
491,15.676,717
492,15.695,718
492,15.724,719
493,15.752,719
493,15.781,720
494,15.819,721
494,15.857,722
495,15.895,722
495,15.933,723
496,15.971,724
496,16.019,724
497,16.067,725
497,16.105,726
498,16.152,726
498,16.2,727
498,16.238,728
499,16.267,728
499,16.295,729
500,16.314,730
500,16.324,730
501,16.343,731
501,16.362,732
502,16.371,733
502,16.381,733
503,16.39,734
503,16.4,735
504,16.41,735
504,16.419,736
505,16.429,737
505,16.438,737
506,16.438,738
506,16.429,739
506,16.429,739
507,16.419,740
507,16.41,741
508,16.4,741
508,16.4,742
509,16.4,743
509,16.381,744
510,16.371,744
510,16.371,745
511,16.362,746
511,16.352,746
512,16.343,747
512,16.352,748
513,16.362,748
513,16.371,749
514,16.41,750
514,16.438,750
514,16.486,751
515,16.533,752
515,16.581,752
516,16.648,753
516,16.705,754
517,16.752,755
517,16.81,755
518,16.867,756
518,16.924,757
519,16.971,757
519,17.038,758
520,17.086,759
520,17.133,759
521,17.19,760
521,17.248,761
522,17.295,761
522,17.352,762
522,17.4,763
523,17.438,763
523,17.476,764
524,17.495,765
524,17.514,766
525,17.514,767
526,17.524,767
526,17.505,768
526,17.505,769
527,17.495,769
527,17.476,770
528,17.476,771
528,17.467,771
529,17.467,772
529,17.457,773
530,17.457,773
530,17.457,774
531,17.457,775
531,17.457,775
532,17.457,776
532,17.476,777
533,17.505,778
533,17.552,778
534,17.581,779
534,17.629,780
534,17.667,780
535,17.705,781
535,17.743,782
536,17.781,782
536,17.819,783
537,17.857,784
537,17.895,784
538,17.924,785
538,17.943,786
539,17.962,786
539,17.981,787
540,17.981,788
540,17.99,789
541,18,789
541,17.99,790
542,18,791
542,17.99,791
542,17.981,792
543,17.99,793
543,17.99,793
544,17.981,794
544,17.971,795
545,17.962,795
545,17.943,796
546,17.924,797
546,17.914,797
547,17.914,798
547,17.914,799
548,17.924,800
548,17.924,800
549,17.933,801
549,17.962,802
550,17.99,802
550,18.01,803
550,18.038,804
551,18.067,804
551,18.086,805
552,18.105,806
552,18.133,806
553,18.152,807
553,18.181,808
554,18.2,808
554,18.21,809
555,18.229,810
555,18.257,811
556,18.286,811
556,18.324,812
557,18.352,813
557,18.41,813
558,18.448,814
558,18.486,815
559,18.505,815
559,18.533,816
559,18.552,817
560,18.59,817
560,18.61,818
561,18.629,819
561,18.648,819
562,18.667,820
562,18.657,821
563,18.657,822
563,18.657,822
564,18.657,823
564,18.667,824
565,18.667,824
565,18.686,825
566,18.686,826
566,18.705,826
567,18.724,827
567,18.733,828
567,18.752,828
568,18.771,829
568,18.79,830
569,18.819,830
569,18.848,831
570,18.886,832
570,18.914,833
571,18.952,833
571,18.981,834
572,19.019,835
572,19.038,835
573,19.067,836
573,19.076,837
574,19.095,837
574,19.124,838
575,19.143,839
575,19.162,839
575,19.19,840
576,19.219,841
576,19.257,841
577,19.286,842
577,19.324,843
578,19.381,844
578,19.419,844
579,19.457,845
579,19.495,846
580,19.533,846
580,19.562,847
581,19.6,848
581,19.638,848
582,19.676,849
582,19.714,850
583,19.752,850
583,19.781,851
583,19.819,852
584,19.867,852
584,19.905,853
585,19.943,854
585,19.99,855
586,20.05,856
587,20.09,856
587,20.13,857
588,20.16,858
588,20.2,858
588,20.25,859
589,20.29,860
589,20.32,861
590,20.35,861
590,20.38,862
591,20.41,863
591,20.43,863
592,20.46,864
592,20.49,865
593,20.5,865
593,20.53,866
594,20.55,867
594,20.58,867
595,20.6,868
595,20.62,869
596,20.64,869
596,20.67,870
596,20.69,871
597,20.7,872
597,20.71,872
598,20.73,873
598,20.75,874
599,20.77,874
599,20.78,875
600,20.8,876
600,20.82,876
601,20.84,877
601,20.85,878
602,20.87,878
602,20.87,879
603,20.88,880
603,20.88,880
604,20.87,881
604,20.86,882
604,20.85,883
605,20.83,883
605,20.81,884
606,20.8,885
606,20.79,885
607,20.78,886
607,20.76,887
608,20.75,887
608,20.75,888
609,20.74,889
609,20.73,889
610,20.73,890
610,20.74,891
611,20.76,891
611,20.76,892
612,20.78,893
612,20.8,894
612,20.8,894
613,20.82,895
613,20.83,896
614,20.85,896
614,20.87,897
615,20.89,898
615,20.91,898
616,20.94,899
616,20.97,900
617,21.01,900
617,21.05,901
618,21.08,902
618,21.1,902
619,21.15,903
619,21.18,904
620,21.2,905
620,21.23,905
620,21.25,906
621,21.29,907
621,21.3,907
622,21.34,908
622,21.39,909
623,21.43,909
623,21.48,910
624,21.53,911
624,21.57,911
625,21.62,912
625,21.65,913
626,21.69,913
626,21.72,914
627,21.74,915
627,21.76,916
628,21.78,916
628,21.8,917
629,21.8,918
629,21.81,918
629,21.83,919
630,21.85,920
630,21.87,920
631,21.89,921
631,21.9,922
632,21.92,922
632,21.93,923
633,21.94,924
633,21.95,924
634,21.95,925
634,21.97,926
635,21.98,927
635,22,927
636,22.02,928
636,22.05,929
637,22.06,929
637,22.08,930
637,22.1,931
638,22.11,931
638,22.12,932
639,22.13,933
639,22.13,933
640,22.13,934
640,22.15,935
641,22.14,935
641,22.14,936
642,22.12,937
642,22.1,938
643,22.09,938
643,22.08,939
644,22.05,940
644,21.94,940
645,21.53,941
645,16.59,942
645,0.07619,942
646,0.08571,943
646,0.07619,944
647,0.07619,944
647,0.07619,945
648,0.07619,946
648,0.08571,946
649,0.07619,947