File: wishlist/Koerner_2005_Polymer/RawDataFromAuthors/cnttobreak/neatpu1.csv
Strain (%),Stress (MPa),Time (sec)
0.0443,0.5175,
0.458,0.6317,1
0.875,0.7325,1
1.292,0.8401,2
1.705,0.9409,2
2.12,1.0349,3
2.54,1.1358,3
2.95,1.2231,4
3.37,1.3105,5
3.78,1.4046,5
4.2,1.4852,6
4.61,1.5726,6
5.03,1.6465,7
5.44,1.7272,7
5.86,1.8011,8
6.27,1.8683,8
6.69,1.9355,9
7.1,2.003,10
7.52,2.07,10
7.93,2.124,11
8.35,2.184,11
8.76,2.245,12
9.18,2.298,12
9.59,2.352,13
10.01,2.399,14
10.42,2.453,14
10.84,2.493,15
11.25,2.54,15
11.67,2.581,16
12.08,2.621,16
12.5,2.668,17
12.92,2.702,17
13.33,2.735,18
13.74,2.776,19
14.16,2.802,19
14.58,2.836,20
14.99,2.876,20
15.41,2.903,21
15.82,2.93,21
16.24,2.957,22
16.65,2.984,23
17.06,3.011,23
17.48,3.038,24
17.9,3.071,24
18.31,3.091,25
18.72,3.118,25
19.14,3.138,26
19.56,3.165,26
19.97,3.185,27
20.4,3.206,28
20.8,3.226,28
21.2,3.246,29
21.6,3.266,29
22,3.28,30
22.5,3.3,30
22.9,3.313,31
23.3,3.333,32
23.7,3.353,32
24.1,3.367,33
24.5,3.387,33
25,3.401,34
25.4,3.414,34
25.8,3.427,35
26.2,3.448,35
26.6,3.461,36
27,3.474,37
27.4,3.488,37
27.9,3.501,38
28.3,3.515,38
28.7,3.528,39
29.1,3.535,39
29.5,3.548,40
29.9,3.562,41
30.4,3.575,41
30.8,3.582,42
31.2,3.589,42
31.6,3.602,43
32,3.609,43
32.4,3.622,44
32.8,3.629,44
33.3,3.642,45
33.7,3.649,46
34.1,3.656,46
34.5,3.669,47
34.9,3.683,47
35.3,3.683,48
35.7,3.696,48
36.2,3.703,49
36.6,3.71,50
37,3.716,50
37.4,3.73,51
37.8,3.73,51
38.2,3.743,52
38.6,3.75,52
39.1,3.757,53
39.5,3.763,53
39.9,3.77,54
40.3,3.777,55
40.7,3.79,55
41.1,3.79,56
41.6,3.797,56
42,3.804,57
42.4,3.81,57
42.8,3.817,58
43.2,3.824,59
43.6,3.831,59
44,3.837,60
44.5,3.844,60
44.9,3.844,61
45.3,3.851,61
45.7,3.858,62
46.1,3.864,62
46.5,3.864,63
47,3.871,64
47.4,3.878,64
47.8,3.884,65
48.2,3.891,65
48.6,3.891,66
49,3.898,66
49.4,3.905,67
49.9,3.905,68
50.3,3.911,68
50.7,3.918,69
51.1,3.925,69
51.5,3.925,70
51.9,3.931,70
52.4,3.938,71
52.8,3.945,71
53.2,3.952,72
53.6,3.958,73
54,3.958,73
54.4,3.958,74
54.8,3.965,74
55.3,3.972,75
55.7,3.972,75
56.1,3.978,76
56.5,3.985,77
56.9,3.985,77
57.3,3.992,78
57.8,3.999,78
58.2,3.999,79
58.6,4.005,79
59,4.005,80
59.4,4.019,80
59.8,4.019,81
60.2,4.026,82
60.7,4.026,82
61.1,4.032,83
61.5,4.039,83
61.9,4.046,84
62.3,4.046,84
62.7,4.052,85
63.1,4.059,86
63.6,4.059,86
64,4.066,87
64.4,4.073,87
64.8,4.079,88
65.2,4.079,88
65.6,4.086,89
66,4.086,89
66.5,4.093,90
66.9,4.099,91
67.3,4.106,91
67.7,4.106,92
68.1,4.106,92
68.5,4.113,93
69,4.12,93
69.4,4.126,94
69.8,4.126,95
70.2,4.133,95
70.6,4.133,96
71,4.14,96
71.4,4.147,97
71.9,4.153,97
72.3,4.153,98
72.7,4.16,98
73.1,4.167,99
73.5,4.167,100
73.9,4.173,100
74.4,4.167,101
74.8,4.173,101
75.2,4.18,102
75.6,4.187,102
76,4.187,103
76.4,4.187,104
76.8,4.194,104
77.3,4.2,105
77.7,4.207,105
78.1,4.214,106
78.5,4.214,106
78.9,4.214,107
79.3,4.22,107
79.7,4.227,108
80.2,4.234,109
80.6,4.241,109
81,4.247,110
81.4,4.247,110
81.8,4.254,111
82.2,4.261,111
82.7,4.261,112
83.1,4.267,113
83.5,4.274,113
83.9,4.281,114
84.3,4.288,114
84.7,4.288,115
85.1,4.294,115
85.6,4.301,116
86,4.308,116
86.4,4.308,117
86.8,4.294,118
87.2,4.301,118
87.6,4.308,119
88.1,4.315,119
88.5,4.315,120
88.9,4.321,120
89.3,4.321,121
89.7,4.328,122
90.1,4.335,122
90.5,4.335,123
91,4.341,123
91.4,4.355,124
91.8,4.362,124
92.2,4.362,125
92.6,4.368,125
93,4.375,126
93.5,4.382,127
93.9,4.388,127
94.3,4.395,128
94.7,4.395,128
95.1,4.402,129
95.5,4.409,129
95.9,4.409,130
96.4,4.415,131
96.8,4.422,131
97.2,4.422,132
97.6,4.429,132
98,4.435,133
98.4,4.442,133
98.8,4.449,134
99.3,4.456,134
99.7,4.462,135
100.1,4.469,136
100.5,4.476,136
100.9,4.476,137
101.3,4.483,137
101.8,4.489,138
102.2,4.496,138
102.6,4.503,139
103,4.509,140
103.4,4.516,140
103.8,4.523,141
104.2,4.53,141
104.7,4.536,142
105.1,4.543,142
105.5,4.55,143
105.9,4.556,143
106.3,4.563,144
106.7,4.57,145
107.1,4.577,145
107.6,4.59,146
108,4.59,146
108.4,4.603,147
108.8,4.61,147
109.2,4.617,148
109.6,4.63,149
110.1,4.637,149
110.5,4.644,150
110.9,4.651,150
111.3,4.657,151
111.7,4.664,151
112.1,4.671,152
112.5,4.684,152
113,4.691,153
113.4,4.698,154
113.8,4.704,154
114.2,4.711,155
114.6,4.724,155
115,4.731,156
115.5,4.745,156
115.9,4.751,157
116.3,4.758,158
116.7,4.772,158
117.1,4.785,159
117.5,4.792,159
117.9,4.805,160
118.4,4.819,160
118.8,4.825,161
119.2,4.839,161
119.6,4.845,162
120,4.859,163
120.4,4.866,163
120.8,4.879,164
121.3,4.892,164
121.7,4.899,165
122.1,4.913,165
122.5,4.926,166
122.9,4.94,167
123.3,4.953,167
123.8,4.96,168
124.2,4.973,168
124.6,4.987,169
125.1,5,169
125.5,5.013,170
125.9,5.02,171
126.3,5.027,171
126.7,5.04,172
127.1,5.054,172
127.5,5.067,173
128,5.074,173
128.4,5.081,174
128.8,5.094,174
129.2,5.108,175
129.6,5.114,176
130,5.128,176
130.5,5.141,177
130.9,5.155,177
131.3,5.168,178
131.7,5.181,178
132.1,5.195,179
132.5,5.208,180
132.9,5.222,180
133.4,5.235,181
133.8,5.242,181
134.2,5.255,182
134.6,5.276,182
135,5.282,183
135.4,5.296,183
135.8,5.309,184
136.3,5.323,185
136.7,5.336,185
137.1,5.349,186
137.5,5.363,186
137.9,5.376,187
138.3,5.39,187
138.8,5.403,188
139.2,5.423,189
139.6,5.43,189
140,5.444,190
140.4,5.457,190
140.8,5.47,191
141.2,5.484,191
141.7,5.504,192
142.1,5.517,192
142.5,5.531,193
142.9,5.544,194
143.3,5.558,194
143.7,5.571,195
144.2,5.585,195
144.6,5.598,196
145,5.618,196
145.4,5.625,197
145.8,5.645,198
146.2,5.659,198
146.6,5.672,199
147.1,5.692,199
147.5,5.706,200
147.9,5.719,200
148.3,5.733,201
148.7,5.753,201
149.1,5.766,202
149.5,5.773,203
150,5.793,203
150.4,5.806,204
150.8,5.82,204
151.2,5.833,205
151.6,5.853,205
152,5.867,206
152.5,5.874,207
152.9,5.894,207
153.3,5.914,208
153.7,5.927,208
154.1,5.934,209
154.5,5.948,209
154.9,5.961,210
155.4,5.974,210
155.8,5.988,211
156.2,6.001,212
156.6,6.015,212
157,6.028,213
157.4,6.042,213
157.8,6.055,214
158.3,6.069,214
158.7,6.089,215
159.1,6.102,216
159.5,6.116,216
159.9,6.129,217
160.3,6.142,217
160.8,6.156,218
161.2,6.169,218
161.6,6.183,219
162,6.196,219
162.4,6.21,220
162.8,6.223,221
163.2,6.243,221
163.7,6.257,222
164.1,6.257,222
164.5,6.27,223
164.9,6.284,223
165.3,6.304,224
165.7,6.317,225
166.2,6.337,225
166.6,6.351,226
167,6.364,226
167.4,6.384,227
167.8,6.405,227
168.2,6.411,228
168.6,6.425,228
169.1,6.445,229
169.5,6.458,230
169.9,6.478,230
170.3,6.492,231
170.7,6.505,231
171.1,6.526,232
171.5,6.539,232
172,6.552,233
172.4,6.573,234
172.8,6.586,234
173.2,6.593,235
173.6,6.606,235
174,6.62,236
174.5,6.633,236
174.9,6.647,237
175.3,6.653,237
175.7,6.673,238
176.1,6.68,239
176.5,6.694,239
177,6.7,240
177.4,6.72,240
177.8,6.734,241
178.2,6.741,241
178.6,6.761,242
179,6.774,243
179.4,6.788,243
179.9,6.794,244
180.3,6.815,244
180.7,6.821,245
181.1,6.835,245
181.5,6.848,246
181.9,6.868,246
182.3,6.888,247
182.8,6.902,248
183.2,6.922,248
183.6,6.935,249
184,6.956,249
184.4,6.976,250
184.8,6.989,250
185.2,7.003,251
185.7,7.016,252
186.1,7.036,252
186.5,7.056,253
186.9,7.063,253
187.3,7.083,254
187.7,7.097,254
188.2,7.11,255
188.6,7.124,255
189,7.144,256
189.4,7.157,257
189.8,7.171,257
190.2,7.184,258
190.6,7.204,258
191.1,7.218,259
191.5,7.238,259
191.9,7.251,260
192.3,7.272,261
192.7,7.285,261
193.1,7.298,262
193.5,7.312,262
194,7.325,263
194.4,7.339,263
194.8,7.359,264
195.2,7.372,264
195.6,7.392,265
196,7.406,266
196.5,7.419,266
196.9,7.433,267
197.3,7.453,267
197.7,7.46,268
198.1,7.48,268
198.5,7.493,269
199.1,7.513,270
199.5,7.527,270
199.9,7.54,271
200,7.554,271
201,7.567,272
201,7.574,272
202,7.594,273
202,7.608,274
202,7.621,274
203,7.634,275
203,7.648,275
204,7.668,276
204,7.681,276
204,7.695,277
205,7.708,278
205,7.722,278
206,7.742,279
206,7.749,279
207,7.769,280
207,7.782,280
207,7.802,281
208,7.816,281
208,7.829,282
209,7.849,283
209,7.863,283
209,7.876,284
210,7.89,284
210,7.903,285
211,7.923,285
211,7.937,286
212,7.95,287
212,7.97,287
212,7.984,288
213,7.997,288
213,8.017,289
214,8.024,289
214,8.044,290
214,8.058,290
215,8.071,291
215,8.085,292
216,8.105,292
216,8.112,293
216,8.132,293
217,8.138,294
217,8.145,294
218,8.165,295
218,8.179,296
219,8.199,296
219,8.212,297
219,8.226,297
220,8.239,298
220,8.259,298
221,8.273,299
221,8.286,299
221,8.3,300
222,8.313,301
222,8.327,301
223,8.34,302
223,8.36,302
224,8.374,303
224,8.387,303
224,8.401,304
225,8.414,305
225,8.421,305
226,8.434,306
226,8.454,306
226,8.468,307
227,8.481,307
227,8.495,308
228,8.515,308
228,8.528,309
229,8.535,310
229,8.548,310
229,8.569,311
230,8.582,311
230,8.595,312
231,8.609,312
231,8.622,313
231,8.636,314
232,8.656,314
232,8.663,315
233,8.676,315
233,8.696,316
234,8.703,316
234,8.716,317
234,8.73,317
235,8.743,318
235,8.757,319
236,8.763,319
236,8.784,320
236,8.804,320
237,8.81,321
237,8.824,321
238,8.844,322
238,8.858,323
238,8.871,323
239,8.884,324
239,8.905,324
240,8.918,325
240,8.931,325
241,8.945,326
241,8.958,326
241,8.972,327
242,8.992,328
242,9.012,328
243,9.019,329
243,9.026,329
243,9.039,330
244,9.052,330
244,9.066,331
245,9.079,332
245,9.099,332
246,9.113,333
246,9.126,333
246,9.14,334
247,9.153,334
247,9.167,335
248,9.18,335
248,9.194,336
248,9.207,337
249,9.22,337
249,9.234,338
250,9.241,338
250,9.254,339
251,9.274,339
251,9.288,340
251,9.301,341
252,9.321,341
252,9.335,342
253,9.348,342
253,9.362,343
253,9.382,343
254,9.395,344
254,9.409,344
255,9.429,345
255,9.442,346
256,9.456,346
256,9.476,347
256,9.489,347
257,9.509,348
257,9.516,348
258,9.543,349
258,9.55,350
258,9.57,350
259,9.583,351
259,9.597,351
260,9.61,352
260,9.63,352
260,9.644,353
261,9.664,353
261,9.677,354
262,9.691,355
262,9.704,355
263,9.718,356
263,9.738,356
263,9.751,357
264,9.765,357
264,9.785,358
265,9.798,359
265,9.812,359
265,9.832,360
266,9.845,360
266,9.859,361
267,9.879,361
267,9.892,362
268,9.899,362
268,9.919,363
268,9.94,364
269,9.953,364
269,9.966,365
270,9.973,365
270,9.993,366
271,10.013,367
271,10.034,367
271,10.047,368
272,10.054,368
272,10.074,369
273,10.087,369
273,10.101,370
274,10.114,371
274,10.128,371
274,10.134,372
275,10.155,372
275,10.161,373
276,10.175,373
276,10.195,374
276,10.202,374
277,10.208,375
277,10.222,376
278,10.235,376
278,10.249,377
278,10.255,377
279,10.269,378
279,10.276,378
280,10.276,379
280,10.282,380
281,10.289,380
281,10.296,381
281,10.309,381
282,10.316,382
282,10.323,382
283,10.329,383
283,10.343,383
283,10.349,384
284,10.363,385
284,10.37,385
285,10.376,386
285,10.39,386
286,10.403,387
286,10.417,387
286,10.43,388
287,10.444,389
287,10.457,389
288,10.47,390
288,10.484,390
288,10.504,391
289,10.517,391
289,10.531,392
290,10.551,392
290,10.565,393
291,10.578,394
291,10.591,394
291,10.612,395
292,10.618,395
292,10.632,396
293,10.652,396
293,10.665,397
293,10.679,398
294,10.692,398
294,10.706,399
295,10.726,399
295,10.746,400
296,10.759,400
296,10.773,401
296,10.8,401
297,10.813,402
297,10.84,403
298,10.86,403
298,10.88,404
298,10.894,404
299,10.914,405
299,10.927,405
300,10.941,406
300,10.954,407
300,10.968,407
301,10.981,408
301,11.001,408
302,11.015,409
302,11.028,409
303,11.048,410
303,11.062,410
303,11.075,411
304,11.089,412
304,11.109,412
305,11.122,413
305,11.129,413
305,11.149,414
306,11.163,414
306,11.176,415
307,11.19,416
307,11.21,416
308,11.223,417
308,11.237,417
308,11.25,418
309,11.27,418
309,11.284,419
310,11.297,419
310,11.317,420
310,11.331,421
311,11.344,421
311,11.358,422
312,11.371,422
312,11.391,423
313,11.398,423
313,11.411,424
313,11.431,425
314,11.445,425
314,11.458,426
315,11.472,426
315,11.485,427
315,11.505,427
316,11.519,428
316,11.532,428
317,11.546,429
317,11.559,430
318,11.573,430
318,11.586,431
318,11.599,431
319,11.606,432
319,11.626,432
320,11.64,433
320,11.653,434
320,11.673,434
321,11.687,435
321,11.7,435
322,11.714,436
322,11.727,436
322,11.754,437
323,11.767,437
323,11.781,438
324,11.794,439
324,11.815,439
325,11.828,440
325,11.848,440
325,11.868,441
326,11.888,441
326,11.915,442
327,11.935,443
327,11.962,443
327,11.983,444
328,12.009,444
328,12.036,445
329,12.056,445
329,12.077,446
330,12.103,446
330,12.13,447
330,12.151,448
331,12.177,448
331,12.198,449
332,12.218,449
332,12.245,450
332,12.265,450
333,12.285,451
333,12.312,452
334,12.332,452
334,12.352,453
335,12.379,453
335,12.399,454
335,12.413,454
336,12.433,455
336,12.446,455
337,12.466,456
337,12.487,457
337,12.5,457
338,12.534,458
338,12.554,458
339,12.581,459
339,12.601,460
340,12.628,460
340,12.641,461
340,12.668,461
341,12.681,462
341,12.708,462
342,12.728,463
342,12.755,464
343,12.782,464
343,12.802,465
343,12.823,465
344,12.849,466
344,12.87,466
345,12.897,467
345,12.917,467
345,12.937,468
346,12.964,469
346,12.984,469
347,13.011,470
347,13.031,470
348,13.044,471
348,13.071,471
348,13.085,472
349,13.105,473
349,13.125,473
350,13.145,474
350,13.159,474
350,13.172,475
351,13.185,475
351,13.206,476
352,13.226,476
352,13.239,477
353,13.253,478
353,13.266,478
353,13.28,479
354,13.286,479
354,13.3,480
355,13.306,480
355,13.32,481
355,13.333,482
356,13.347,482
356,13.36,483
357,13.374,483
357,13.387,484
357,13.401,484
358,13.414,485
358,13.427,485
359,13.434,486
359,13.454,487
360,13.468,487
360,13.481,488
360,13.495,488
361,13.508,489
361,13.522,489
362,13.542,490
362,13.548,491
362,13.562,491
363,13.582,492
363,13.595,492
364,13.616,493
364,13.629,493
365,13.649,494
365,13.663,494
365,13.683,495
366,13.696,496
366,13.71,496
367,13.723,497
367,13.737,497
367,13.757,498
368,13.77,498
368,13.777,499
369,13.79,500
369,13.804,500
370,13.824,501
370,13.837,501
370,13.858,502
371,13.871,502
371,13.884,503
372,13.905,503
372,13.925,504
372,13.938,505
373,13.952,505
373,13.972,506
374,13.985,506
374,14.005,507
375,14.026,507
375,14.046,508
375,14.066,509
376,14.073,509
376,14.086,510
377,14.099,510
377,14.126,511
377,14.133,511
378,14.147,512
378,14.16,512
379,14.173,513
379,14.187,514
379,14.194,514
380,14.2,515
380,14.214,515
381,14.227,516
381,14.241,516
382,14.261,517
382,14.267,518
382,14.281,518
383,14.294,519
383,14.315,519
384,14.328,520
384,14.341,520
384,14.355,521
385,14.362,521
385,14.382,522
386,14.395,523
386,14.415,523
387,14.435,524
387,14.456,524
387,14.476,525
388,14.509,525
388,14.543,526
389,14.57,527
389,14.597,527
389,14.637,528
390,14.671,528
390,14.698,529
391,14.731,529
391,14.758,530
392,14.798,530
392,14.819,531
392,14.852,532
393,14.886,532
393,14.913,533
394,14.946,533
394,14.973,534
394,15,534
395,15.04,535
395,15.074,536
396,15.108,536
396,15.134,537
397,15.161,537
397,15.188,538
397,15.208,538
398,15.228,539
398,15.249,540
399,15.269,540
399,15.289,541
400,15.309,541
400,15.329,542
400,15.349,542
401,15.363,543
401,15.383,544
402,15.403,544
402,15.417,545
402,15.437,545
403,15.457,546
403,15.477,546
404,15.484,547
404,15.504,547
405,15.524,548
405,15.544,549
405,15.565,549
406,15.578,550
406,15.598,550
407,15.618,551
407,15.638,551
407,15.652,552
408,15.672,553
408,15.699,553
409,15.712,554
409,15.726,554
409,15.746,555
410,15.766,555
410,15.78,556
411,15.8,556
411,15.813,557
412,15.827,558
412,15.847,558
412,15.867,559
413,15.887,559
413,15.921,560
414,15.948,560
414,15.981,561
414,16.015,562
415,16.028,562
415,16.069,563
416,16.095,563
416,16.129,564
417,16.156,564
417,16.183,565
417,16.21,565
418,16.237,566
418,16.257,567
419,16.277,567
419,16.297,568
419,16.317,568
420,16.337,569
420,16.358,569
421,16.371,570
421,16.398,571
422,16.411,571
422,16.431,572
422,16.452,572
423,16.472,573
423,16.485,573
424,16.505,574
424,16.526,574
424,16.539,575
425,16.559,576
425,16.573,576
426,16.586,577
426,16.613,577
427,16.626,578
427,16.647,578
427,16.667,579
428,16.694,580
428,16.72,580
429,16.741,581
429,16.767,581
429,16.794,582
430,16.835,582
430,16.868,583
431,16.902,583
431,16.942,584
431,16.976,585
432,17.003,585
432,17.043,586
433,17.077,586
433,17.11,587
434,17.144,587
434,17.171,588
434,17.204,589
435,17.224,589
435,17.258,590
436,17.278,590
436,17.305,591
436,17.332,591
437,17.352,592
437,17.379,592
438,17.399,593
438,17.426,594
439,17.446,594
439,17.473,595
439,17.493,595
440,17.527,596
440,17.547,597
441,17.567,597
441,17.594,598
442,17.614,598
442,17.641,599
443,17.661,600
443,17.702,600
443,17.728,601
444,17.755,601
444,17.782,602
445,17.809,602
445,17.836,603
445,17.87,603
446,17.897,604
446,17.923,605
447,17.95,605
447,17.977,606
447,18.011,606
448,18.038,607
448,18.071,607
449,18.105,608
449,18.138,609
450,18.172,609
450,18.206,610
450,18.239,610
451,18.266,611
451,18.3,611
452,18.327,612
452,18.353,612
452,18.38,613
453,18.407,614
453,18.448,614
454,18.468,615
454,18.495,615
455,18.522,616
455,18.548,616
455,18.569,617
456,18.589,618
456,18.616,618
457,18.636,619
457,18.656,619
457,18.676,620
458,18.696,620
458,18.716,621
459,18.737,621
459,18.757,622
460,18.777,623
460,18.804,623
460,18.824,624
461,18.844,624
461,18.864,625
462,18.898,625
462,18.918,626
462,18.945,627
463,18.972,627
463,18.992,628
464,19.019,628
464,19.046,629
465,19.066,629
465,19.093,630
465,19.12,630
466,19.14,631
466,19.153,632
467,19.18,632
467,19.2,633
467,19.22,633
468,19.241,634
468,19.261,634
469,19.281,635
469,19.301,636
469,19.315,636
470,19.328,637
470,19.348,637
471,19.375,638
471,19.388,638
472,19.409,639
472,19.429,639
472,19.449,640
473,19.476,641
473,19.503,641
474,19.53,642
474,19.55,642
474,19.577,643
475,19.597,643
475,19.624,644
476,19.651,645
476,19.684,645
477,19.711,646
477,19.731,646
477,19.758,647
478,19.792,647
478,19.812,648
479,19.839,648
479,19.859,649
479,19.886,650
480,19.919,650
480,19.946,651
481,19.966,651
481,20,652
482,20.05,653
482,20.07,653
483,20.09,654
483,20.13,654
483,20.15,655
484,20.18,656
484,20.22,656
485,20.24,657
485,20.28,657
486,20.3,658
486,20.34,658
486,20.36,659
487,20.39,660
487,20.42,660
488,20.44,661
488,20.46,661
488,20.49,662
489,20.52,662
489,20.54,663
490,20.56,663
490,20.58,664
490,20.61,665
491,20.62,665
491,20.65,666
492,20.67,666
492,20.7,667
493,20.71,667
493,20.75,668
493,20.77,669
494,20.79,669
494,20.82,670
495,20.85,670
495,20.87,671
495,20.9,671
496,20.93,672
496,20.96,672
497,20.99,673
497,21.01,674
498,21.04,674
498,21.06,675
498,21.09,675
499,21.11,676
499,21.14,676
500,21.16,677
500,21.18,678
500,21.2,678
501,21.22,679
501,21.24,679
502,21.26,680
502,21.27,680
503,21.29,681
503,21.3,681
503,21.32,682
504,21.33,683
504,21.36,683
505,21.37,684
505,21.39,684
505,21.4,685
506,21.42,685
506,21.43,686
507,21.45,687
507,21.46,687
508,21.48,688
508,21.49,688
508,21.5,689
509,21.51,689
509,21.53,690
510,21.55,690
510,21.56,691
510,21.57,692
511,21.6,692
511,21.62,693
512,21.65,693
512,21.67,694
512,21.71,694
513,21.75,695
513,21.78,696
514,21.82,696
514,21.85,697
515,21.9,697
515,21.94,698
515,21.97,698
516,22.01,699
516,22.05,699
517,22.08,700
517,22.12,701
517,22.16,701
518,22.19,702
518,22.22,702
519,22.26,703
519,22.29,703
520,22.33,704
520,22.36,705
520,22.39,705
521,22.41,706
521,22.45,706
522,22.47,707
522,22.51,707
523,22.54,708
523,22.56,709
524,22.59,709
524,22.6,710
524,22.62,710
525,22.64,711
525,22.65,712
526,22.66,712
526,22.67,713
526,22.69,713
527,22.71,714
527,22.72,714
528,22.74,715
528,22.75,716
529,22.77,716
529,22.78,717
529,22.8,717
530,22.82,718
530,22.84,718
531,22.86,719
531,22.88,719
531,22.91,720
532,22.94,721
532,22.96,721
533,22.98,722
533,23.01,722
533,23.04,723
534,23.07,723
534,23.1,724
535,23.12,725
535,23.15,725
536,23.18,726
536,23.21,726
536,23.24,727
537,23.27,727
537,23.29,728
538,23.33,728
538,23.35,729
538,23.38,730
539,23.4,730
539,23.43,731
540,23.45,731
540,23.47,732
541,23.49,732
541,23.52,733
541,23.53,734
542,23.56,734
542,23.59,735
543,23.62,735
543,23.64,736
543,23.66,736
544,23.69,737
544,23.72,737
545,23.75,738
545,23.78,739
546,23.8,739
546,23.82,740
546,23.85,740
547,23.88,741
547,23.9,741
548,23.93,742
548,23.95,743
548,23.97,743
549,23.99,744
549,24.01,744
550,24.03,745
550,24.05,745
551,24.07,746
551,24.09,746
551,24.1,747
552,24.11,748
552,24.11,748
553,24.12,749
553,24.12,749
553,24.13,750
554,24.12,750
554,24.12,751
555,24.13,752
555,24.13,752
555,24.13,753
556,24.12,753
556,24.13,754
557,24.13,754
557,24.13,755
558,24.14,755
558,24.15,756
558,24.15,757
559,24.15,757
559,24.16,758
560,24.15,758
560,24.15,759
560,24.15,759
561,24.14,760
561,24.14,761
562,24.13,761
562,24.11,762
563,24.11,762
563,24.1,763
563,24.09,763
564,24.09,764
564,24.09,764
565,24.09,765
565,24.1,766
565,24.11,766
566,24.11,767
566,24.13,767
567,24.14,768
567,24.15,768
568,24.17,769
568,24.21,770
568,24.24,770
569,24.28,771
569,24.33,771
570,24.38,772
570,24.41,772
570,24.46,773
571,24.51,773
571,24.56,774
572,24.62,775
572,24.68,775
573,24.73,776
573,24.8,776
573,24.85,777
574,24.91,777
574,24.98,778
575,25.06,779
575,25.13,779
576,25.17,780
576,25.22,781
576,25.28,781
577,25.33,782
577,25.38,782
578,25.43,783
578,25.48,783
579,25.52,784
579,25.57,784
579,25.62,785
580,25.67,786
580,25.71,786
581,25.74,787
581,25.77,787
581,25.8,788
582,25.82,788
582,25.84,789
583,25.85,790
583,25.87,790
584,25.87,791
584,25.89,791
584,25.9,792
585,25.91,792
585,25.92,793
586,25.94,793
586,25.95,794
586,25.96,795
587,25.98,795
587,25.99,796
588,26,796
588,26.01,797
589,26.03,797
589,26.04,798
589,26.06,799
590,26.07,799
590,26.08,800
591,26.1,800
591,26.12,801
591,26.14,801
592,26.16,802
592,26.17,802
593,26.18,803
593,26.16,804
594,26.1,804
594,25.5,805
594,0.02688,805
595,0.02688,806
595,0.02688,806
596,0.02688,807
596,0.02688,808
596,0.02688,808
597,0.02016,809
597,0.02688,809
598,0.02016,810
598,0.02016,810
598,0.02016,811