File: wishlist/Koerner_2005_Polymer/RawDataFromAuthors/cnttobreak/neatpu.csv
Strain (%),Stress (MPa),Time (sec)
0.0239,0.5015,
0.502,0.6019,1
0.972,0.7099,2
1.446,0.8102,4
1.916,0.9105,5
2.39,1.0031,6
2.86,1.1034,7
3.34,1.196,8
3.81,1.2731,10
4.28,1.3657,11
4.76,1.4506,12
5.23,1.5201,13
5.7,1.6049,14
6.18,1.6821,15
6.65,1.7438,17
7.12,1.8133,18
7.59,1.8827,19
8.07,1.9522,20
8.54,2.014,21
9.02,2.076,23
9.49,2.13,24
9.96,2.191,25
10.43,2.238,26
10.91,2.299,27
11.38,2.346,29
11.85,2.392,30
12.33,2.438,31
12.8,2.485,32
13.27,2.531,33
13.75,2.577,34
14.22,2.623,36
14.69,2.662,37
15.16,2.701,38
15.64,2.739,39
16.11,2.778,40
16.59,2.809,42
17.06,2.84,43
17.53,2.87,44
18,2.909,45
18.48,2.94,46
18.95,2.971,48
19.42,2.994,49
19.9,3.017,50
20.4,3.048,51
20.8,3.079,52
21.3,3.102,53
21.8,3.125,55
22.3,3.148,56
22.7,3.171,57
23.2,3.194,58
23.7,3.218,59
24.2,3.241,61
24.6,3.256,62
25.1,3.272,63
25.6,3.295,64
26,3.31,65
26.5,3.333,67
27,3.349,68
27.5,3.372,69
27.9,3.387,70
28.4,3.395,71
28.9,3.418,72
29.4,3.434,74
29.8,3.449,75
30.3,3.465,76
30.8,3.48,77
31.3,3.488,78
31.7,3.503,80
32.2,3.519,81
32.7,3.534,82
33.1,3.549,83
33.6,3.557,84
34.1,3.573,86
34.6,3.588,87
35,3.603,88
35.5,3.611,89
36,3.611,90
36.5,3.627,91
36.9,3.634,93
37.4,3.657,94
37.9,3.657,95
38.3,3.673,96
38.8,3.681,97
39.3,3.688,99
39.8,3.696,100
40.2,3.704,101
40.7,3.711,102
41.2,3.727,103
41.7,3.735,105
42.1,3.735,106
42.6,3.75,107
43.1,3.758,108
43.5,3.765,109
44,3.773,110
44.5,3.781,112
45,3.781,113
45.4,3.796,114
45.9,3.796,115
46.4,3.804,116
46.9,3.804,118
47.3,3.812,119
47.8,3.819,120
48.3,3.827,121
48.8,3.835,122
49.2,3.835,124
49.7,3.843,125
50.2,3.843,126
50.6,3.85,127
51.1,3.85,128
51.6,3.866,129
52.1,3.866,131
52.5,3.873,132
53,3.873,133
53.5,3.881,134
54,3.881,135
54.4,3.889,137
54.9,3.897,138
55.4,3.897,139
55.9,3.904,140
56.3,3.904,141
56.8,3.912,143
57.3,3.912,144
57.7,3.92,145
58.2,3.92,146
58.7,3.927,147
59.2,3.935,148
59.6,3.935,150
60.1,3.943,151
60.6,3.943,152
61.1,3.951,153
61.5,3.958,154
62,3.958,156
62.5,3.966,157
62.9,3.974,158
63.4,3.974,159
63.9,3.974,160
64.4,3.981,162
64.8,3.981,163
65.3,3.989,164
65.8,3.997,165
66.3,4.005,166
66.7,4.005,167
67.2,4.012,169
67.7,4.02,170
68.2,4.028,171
68.6,4.028,172
69.1,4.028,173
69.6,4.035,175
70,4.043,176
70.5,4.043,177
71,4.051,178
71.5,4.051,179
71.9,4.059,181
72.4,4.074,182
72.9,4.066,183
73.4,4.082,184
73.8,4.082,185
74.3,4.09,186
74.8,4.097,188
75.2,4.097,189
75.7,4.105,190
76.2,4.105,191
76.7,4.105,192
77.1,4.12,194
77.6,4.12,195
78.1,4.128,196
78.6,4.128,197
79,4.128,198
79.5,4.144,200
80,4.151,201
80.5,4.151,202
80.9,4.159,203
81.4,4.159,204
81.9,4.167,205
82.3,4.174,207
82.8,4.174,208
83.3,4.182,209
83.8,4.19,210
84.2,4.19,211
84.7,4.198,213
85.2,4.205,214
85.7,4.213,215
86.1,4.213,216
86.6,4.221,217
87.1,4.228,219
87.5,4.228,220
88,4.236,221
88.5,4.244,222
89,4.244,223
89.4,4.259,224
89.9,4.267,226
90.4,4.267,227
90.9,4.275,228
91.3,4.282,229
91.8,4.29,230
92.3,4.298,232
92.8,4.306,233
93.2,4.313,234
93.7,4.321,235
94.2,4.329,236
94.6,4.336,238
95.1,4.344,239
95.6,4.352,240
96.1,4.36,241
96.5,4.367,242
97,4.375,243
97.5,4.383,245
98,4.39,246
98.4,4.398,247
98.9,4.406,248
99.4,4.414,249
99.9,4.429,251
100.3,4.437,252
100.8,4.444,253
101.3,4.452,254
101.7,4.468,255
102.2,4.475,257
102.7,4.483,258
103.2,4.491,259
103.6,4.498,260
104.1,4.514,261
104.6,4.529,262
105.1,4.537,264
105.5,4.545,265
106,4.545,266
106.5,4.552,267
106.9,4.568,268
107.4,4.583,270
107.9,4.591,271
108.4,4.606,272
108.8,4.614,273
109.3,4.63,274
109.8,4.637,276
110.3,4.645,277
110.7,4.66,278
111.2,4.668,279
111.7,4.684,280
112.2,4.691,281
112.6,4.707,283
113.1,4.715,284
113.6,4.73,285
114,4.738,286
114.5,4.753,287
115,4.761,289
115.5,4.776,290
115.9,4.792,291
116.4,4.807,292
116.9,4.823,293
117.4,4.83,295
117.8,4.846,296
118.3,4.853,297
118.8,4.869,298
119.2,4.884,299
119.7,4.9,300
120.2,4.907,302
120.7,4.923,303
121.1,4.931,304
121.6,4.954,305
122.1,4.969,306
122.6,4.977,308
123,5,309
123.6,5.015,310
124,5.031,311
124.5,5.046,312
125,5.062,314
125.5,5.077,315
125.9,5.085,316
126.4,5.108,317
126.9,5.123,318
127.3,5.139,320
127.8,5.154,321
128.3,5.17,322
128.8,5.177,323
129.2,5.193,324
129.7,5.201,326
130.2,5.216,327
130.7,5.231,328
131.1,5.247,329
131.6,5.262,330
132.1,5.278,331
132.5,5.293,333
133,5.309,334
133.5,5.332,335
134,5.347,336
134.4,5.355,337
134.9,5.37,339
135.4,5.386,340
135.9,5.401,341
136.3,5.409,342
136.8,5.432,343
137.3,5.448,345
137.8,5.471,346
138.2,5.486,347
138.7,5.502,348
139.2,5.517,349
139.6,5.525,350
140.1,5.548,352
140.6,5.563,353
141.1,5.579,354
141.5,5.594,355
142,5.61,356
142.5,5.625,358
143,5.633,359
143.4,5.656,360
143.9,5.671,361
144.4,5.687,362
144.8,5.702,364
145.3,5.718,365
145.8,5.733,366
146.3,5.748,367
146.7,5.764,368
147.2,5.779,369
147.7,5.795,371
148.2,5.818,372
148.6,5.833,373
149.1,5.849,374
149.6,5.864,375
150.1,5.872,377
150.5,5.895,378
151,5.91,379
151.5,5.926,380
151.9,5.941,381
152.4,5.957,383
152.9,5.972,384
153.4,5.995,385
153.8,6.011,386
154.3,6.026,387
154.8,6.042,388
155.3,6.057,390
155.7,6.073,391
156.2,6.088,392
156.7,6.103,393
157.2,6.127,394
157.6,6.142,396
158.1,6.157,397
158.6,6.173,398
159,6.188,399
159.5,6.204,400
160,6.227,402
160.5,6.242,403
160.9,6.25,404
161.4,6.265,405
161.9,6.281,406
162.4,6.304,407
162.8,6.319,409
163.3,6.335,410
163.8,6.358,411
164.2,6.373,412
164.7,6.389,413
165.2,6.404,415
165.7,6.427,416
166.1,6.443,417
166.6,6.466,418
167.1,6.489,419
167.6,6.512,421
168,6.535,422
168.5,6.543,423
169,6.559,424
169.5,6.574,425
169.9,6.59,426
170.4,6.605,428
170.9,6.628,429
171.3,6.651,430
171.8,6.667,431
172.3,6.682,432
172.8,6.698,434
173.2,6.713,435
173.7,6.736,436
174.2,6.752,437
174.7,6.767,438
175.1,6.79,440
175.6,6.806,441
176.1,6.821,442
176.5,6.836,443
177,6.86,444
177.5,6.875,445
178,6.89,447
178.4,6.906,448
178.9,6.921,449
179.4,6.944,450
179.9,6.96,451
180.3,6.983,453
180.8,6.998,454
181.3,7.014,455
181.8,7.029,456
182.2,7.052,457
182.7,7.06,459
183.2,7.083,460
183.6,7.091,461
184.1,7.106,462
184.6,7.13,463
185.1,7.145,464
185.5,7.16,466
186,7.184,467
186.5,7.199,468
187,7.215,469
187.4,7.238,470
187.9,7.253,472
188.4,7.269,473
188.8,7.284,474
189.3,7.299,475
189.8,7.323,476
190.3,7.338,478
190.7,7.353,479
191.2,7.369,480
191.7,7.384,481
192.2,7.4,482
192.6,7.423,483
193.1,7.431,485
193.6,7.446,486
194.1,7.454,487
194.5,7.485,488
195,7.492,489
195.6,7.515,491
196,7.523,492
196.5,7.546,493
197,7.562,494
197.5,7.577,496
197.9,7.593,497
198.4,7.608,498
198.9,7.623,499
199.4,7.639,500
199.8,7.647,502
200,7.662,503
201,7.677,504
201,7.693,505
202,7.701,506
202,7.724,507
203,7.739,509
203,7.755,510
204,7.77,511
204,7.785,512
205,7.809,513
205,7.824,515
206,7.84,516
206,7.855,517
206,7.87,518
207,7.886,519
207,7.909,521
208,7.924,522
208,7.94,523
209,7.963,524
209,7.978,525
210,7.994,526
210,8.017,528
211,8.032,529
211,8.048,530
212,8.071,531
212,8.094,532
213,8.102,534
213,8.125,535
214,8.14,536
214,8.164,537
214,8.179,538
215,8.194,540
215,8.21,541
216,8.233,542
216,8.248,543
217,8.264,544
217,8.287,545
218,8.295,547
218,8.31,548
219,8.318,549
219,8.341,550
220,8.356,551
220,8.372,553
221,8.387,554
221,8.41,555
222,8.426,556
222,8.441,557
223,8.457,559
223,8.488,560
223,8.503,561
224,8.519,562
224,8.542,563
225,8.557,564
225,8.58,566
226,8.596,567
226,8.619,568
227,8.642,569
227,8.657,570
228,8.681,572
228,8.696,573
229,8.711,574
229,8.727,575
230,8.75,576
230,8.765,578
231,8.781,579
231,8.796,580
232,8.819,581
232,8.835,582
232,8.858,583
233,8.873,585
233,8.889,586
234,8.904,587
234,8.92,588
235,8.943,589
235,8.966,591
236,8.981,592
236,8.997,593
237,9.02,594
237,9.035,595
238,9.059,597
238,9.074,598
239,9.09,599
239,9.113,600
240,9.128,601
240,9.136,602
241,9.144,604
241,9.159,605
241,9.182,606
242,9.198,607
242,9.213,608
243,9.236,610
243,9.244,611
244,9.259,612
244,9.275,613
245,9.29,614
245,9.298,616
246,9.321,617
246,9.336,618
247,9.352,619
247,9.367,620
248,9.383,621
248,9.398,623
249,9.398,624
249,9.421,625
250,9.437,626
250,9.452,627
250,9.468,629
251,9.483,630
251,9.498,631
252,9.522,632
252,9.537,633
253,9.552,635
253,9.568,636
254,9.583,637
254,9.599,638
255,9.614,639
255,9.63,640
256,9.645,642
256,9.66,643
257,9.676,644
257,9.684,645
258,9.707,646
258,9.722,648
258,9.738,649
259,9.753,650
259,9.761,651
260,9.776,652
260,9.792,654
261,9.807,655
261,9.807,656
262,9.83,657
262,9.846,658
263,9.861,659
263,9.877,661
264,9.884,662
264,9.907,663
265,9.915,664
265,9.938,665
266,9.946,667
266,9.969,668
267,9.985,669
267,10.008,670
268,10.023,672
268,10.039,673
269,10.054,674
269,10.069,675
270,10.085,676
270,10.1,678
270,10.123,679
271,10.139,680
271,10.154,681
272,10.17,682
272,10.193,684
273,10.208,685
273,10.231,686
274,10.247,687
274,10.262,688
275,10.285,689
275,10.301,691
276,10.316,692
276,10.34,693
277,10.355,694
277,10.37,695
278,10.394,697
278,10.409,698
278,10.432,699
279,10.455,700
279,10.471,701
280,10.494,703
280,10.509,704
281,10.517,705
281,10.54,706
282,10.556,707
282,10.571,708
283,10.594,710
283,10.61,711
284,10.617,712
284,10.633,713
285,10.656,714
285,10.671,716
286,10.694,717
286,10.71,718
287,10.725,719
287,10.748,720
287,10.764,722
288,10.779,723
288,10.802,724
289,10.818,725
289,10.841,726
290,10.856,727
290,10.88,729
291,10.903,730
291,10.934,731
292,10.949,732
292,10.98,733
293,11.003,735
293,11.026,736
294,11.049,737
294,11.065,738
295,11.088,739
295,11.103,741
296,11.127,742
296,11.142,743
296,11.165,744
297,11.181,745
297,11.196,746
298,11.219,748
298,11.235,749
299,11.25,750
299,11.265,751
300,11.281,752
300,11.296,754
301,11.312,755
301,11.327,756
302,11.335,757
302,11.35,758
303,11.366,760
303,11.381,761
304,11.397,762
304,11.412,763
305,11.435,764
305,11.451,765
305,11.474,767
306,11.481,768
306,11.497,769
307,11.52,770
307,11.535,771
308,11.543,773
308,11.559,774
309,11.574,775
309,11.59,776
310,11.597,777
310,11.605,779
311,11.605,780
311,11.613,781
312,11.62,782
312,11.628,783
313,11.628,784
313,11.644,786
314,11.651,787
314,11.659,788
314,11.667,789
315,11.674,790
315,11.682,792
316,11.698,793
316,11.705,794
317,11.721,795
317,11.736,796
318,11.752,798
318,11.767,799
319,11.782,800
319,11.798,801
320,11.806,802
320,11.821,803
321,11.836,805
321,11.852,806
322,11.867,807
322,11.883,808
322,11.898,809
323,11.898,811
323,11.914,812
324,11.929,813
324,11.944,814
325,11.952,815
325,11.96,817
326,11.975,818
326,11.991,819
327,12.006,820
327,12.022,821
328,12.037,822
328,12.052,824
329,12.068,825
329,12.083,826
330,12.099,827
330,12.114,828
331,12.13,830
331,12.137,831
331,12.145,832
332,12.153,833
332,12.168,834
333,12.184,836
333,12.191,837
334,12.215,838
334,12.222,839
335,12.245,840
335,12.253,841
336,12.276,843
336,12.292,844
337,12.299,845
337,12.323,846
338,12.338,847
338,12.353,849
339,12.369,850
339,12.384,851
340,12.4,852
340,12.423,853
340,12.446,855
341,12.469,856
341,12.492,857
342,12.515,859
343,12.539,860
343,12.562,861
343,12.577,862
344,12.6,863
344,12.623,864
345,12.639,866
345,12.662,867
346,12.677,868
346,12.693,869
347,12.716,870
347,12.739,872
348,12.755,873
348,12.778,874
349,12.793,875
349,12.809,876
350,12.824,878
350,12.84,879
351,12.855,880
351,12.87,881
352,12.886,882
352,12.909,883
352,12.924,885
353,12.948,886
353,12.963,887
354,12.986,888
354,13.002,889
355,13.017,891
355,13.04,892
356,13.063,893
356,13.079,894
357,13.094,895
357,13.117,897
358,13.133,898
358,13.148,899
359,13.171,900
359,13.187,901
360,13.194,902
360,13.21,904
361,13.233,905
361,13.248,906
361,13.272,907
362,13.287,908
362,13.31,910
363,13.333,911
363,13.349,912
364,13.372,913
364,13.395,914
365,13.418,916
365,13.441,917
366,13.465,918
366,13.488,919
367,13.511,920
367,13.534,921
368,13.565,923
368,13.58,924
369,13.603,925
369,13.619,926
369,13.642,927
370,13.657,929
370,13.681,930
371,13.696,931
371,13.719,932
372,13.735,933
372,13.742,935
373,13.765,936
373,13.781,937
374,13.789,938
374,13.804,939
375,13.819,940
375,13.827,942
376,13.843,943
376,13.858,944
377,13.873,945
377,13.889,946
378,13.904,948
378,13.92,949
378,13.943,950
379,13.958,951
379,13.974,952
380,13.989,954
380,14.012,955
381,14.02,956
381,14.028,957
382,14.051,958
382,14.066,959
383,14.074,961
383,14.09,962
384,14.105,963
384,14.113,964
385,14.128,965
385,14.136,967
386,14.144,968
386,14.159,969
387,14.167,970
387,14.19,971
387,14.205,973
388,14.213,974
388,14.228,975
389,14.252,976
389,14.259,977
390,14.267,978
390,14.282,980
391,14.29,981
391,14.306,982
392,14.321,983
392,14.336,984
393,14.352,986
393,14.375,987
394,14.398,988
394,14.421,989
395,14.444,990
395,14.475,992
396,14.498,993
396,14.529,994
396,14.56,995
397,14.591,996
397,14.614,997
398,14.645,999
398,14.684,1000
399,14.707,1001
399,14.745,1002
400,14.769,1003
400,14.792,1005
401,14.823,1006
401,14.838,1007
402,14.861,1008
402,14.884,1009
403,14.907,1011
403,14.923,1012
404,14.946,1013
404,14.961,1014
405,14.977,1015
405,14.992,1016
406,15.015,1018
406,15.031,1019
407,15.054,1021
407,15.062,1022
408,15.077,1023
408,15.1,1024
409,15.108,1025
409,15.123,1026
409,15.139,1028
410,15.154,1029
410,15.162,1030
411,15.177,1031
411,15.185,1032
412,15.201,1034
412,15.216,1035
413,15.231,1036
413,15.247,1037
414,15.262,1038
414,15.285,1040
415,15.309,1041
415,15.332,1042
416,15.347,1043
416,15.37,1044
417,15.386,1045
417,15.409,1047
417,15.432,1048
418,15.448,1049
418,15.471,1050
419,15.494,1051
419,15.509,1053
420,15.532,1054
420,15.548,1055
421,15.571,1056
421,15.579,1057
422,15.594,1059
422,15.602,1060
423,15.61,1061
423,15.625,1062
424,15.633,1063
424,15.64,1064
425,15.656,1066
425,15.671,1067
426,15.687,1068
426,15.702,1069
426,15.725,1070
427,15.748,1072
427,15.772,1073
428,15.779,1074
428,15.795,1075
429,15.81,1076
429,15.818,1078
430,15.826,1079
430,15.841,1080
431,15.856,1081
431,15.864,1082
432,15.88,1083
432,15.895,1085
433,15.91,1086
433,15.918,1087
434,15.934,1088
434,15.949,1089
435,15.957,1091
435,15.972,1092
435,15.98,1093
436,15.995,1094
436,16.003,1095
437,16.011,1097
437,16.026,1098
438,16.042,1099
438,16.057,1100
439,16.065,1101
439,16.073,1102
440,16.08,1104
440,16.103,1105
441,16.111,1106
441,16.119,1107
442,16.134,1108
442,16.15,1110
443,16.157,1111
443,16.173,1112
444,16.188,1113
444,16.188,1114
444,16.196,1116
445,16.204,1117
445,16.211,1118
446,16.219,1119
446,16.235,1120
447,16.235,1121
447,16.242,1123
448,16.242,1124
448,16.25,1125
449,16.25,1126
449,16.258,1127
450,16.258,1129
450,16.265,1130
451,16.281,1131
451,16.281,1132
452,16.304,1133
452,16.319,1135
453,16.335,1136
453,16.35,1137
453,16.366,1138
454,16.381,1139
454,16.404,1140
455,16.42,1142
455,16.443,1143
456,16.458,1144
456,16.474,1145
457,16.497,1146
457,16.512,1148
458,16.535,1149
458,16.559,1150
459,16.574,1151
459,16.597,1152
460,16.62,1154
460,16.644,1155
461,16.667,1156
461,16.698,1157
461,16.721,1158
462,16.744,1159
462,16.767,1161
463,16.79,1162
463,16.813,1163
464,16.836,1164
464,16.86,1165
465,16.883,1167
465,16.906,1168
466,16.929,1169
466,16.952,1170
467,16.975,1171
467,16.998,1173
468,17.014,1174
468,17.029,1175
469,17.045,1176
469,17.06,1177
470,17.076,1178
470,17.091,1180
470,17.114,1181
471,17.13,1182
471,17.145,1183
472,17.176,1184
472,17.191,1186
473,17.207,1187
473,17.222,1188
474,17.238,1189
474,17.253,1190
475,17.253,1192
475,17.269,1193
476,17.276,1194
476,17.292,1195
477,17.307,1196
477,17.323,1197
478,17.346,1199
478,17.361,1200
479,17.369,1201
479,17.392,1202
479,17.407,1203
480,17.431,1205
480,17.446,1206
481,17.461,1207
481,17.477,1208
482,17.5,1209
483,17.523,1211
483,17.539,1212
483,17.554,1214
484,17.569,1215
484,17.585,1216
485,17.6,1217
485,17.616,1218
486,17.623,1219
486,17.639,1221
487,17.639,1222
487,17.647,1223
488,17.662,1224
488,17.662,1225
489,17.662,1227
489,17.67,1228
490,17.685,1229
490,17.693,1230
491,17.708,1231
491,17.716,1233
492,17.731,1234
492,17.747,1235
492,17.762,1236
493,17.785,1237
493,17.801,1238
494,17.816,1240
494,17.84,1241
495,17.855,1242
495,17.87,1243
496,17.886,1244
496,17.909,1246
497,17.924,1247
497,17.948,1248
498,17.963,1249
498,17.978,1250
499,18.002,1252
499,18.017,1253
500,18.04,1254
500,18.063,1255
501,18.079,1256
501,18.102,1257
501,18.117,1259
502,18.14,1260
502,18.164,1261
503,18.179,1262
503,18.202,1263
504,18.218,1265
504,18.233,1266
505,18.248,1267
505,18.272,1268
506,18.287,1269
506,18.318,1271
507,18.341,1272
507,18.356,1273
508,18.38,1274
508,18.395,1275
509,18.418,1276
509,18.426,1278
510,18.441,1279
510,18.457,1280
510,18.472,1281
511,18.495,1282
511,18.511,1284
512,18.526,1285
512,18.542,1286
513,18.565,1287
513,18.58,1288
514,18.603,1290
514,18.619,1291
515,18.65,1292
515,18.665,1293
516,18.696,1294
516,18.719,1295
517,18.742,1297
517,18.765,1298
518,18.789,1299
518,18.812,1300
518,18.843,1301
519,18.866,1303
519,18.889,1304
520,18.904,1305
520,18.92,1306
521,18.943,1307
521,18.958,1309
522,18.974,1310
522,18.989,1311
523,18.997,1312
523,19.012,1313
524,19.028,1314
524,19.035,1316
525,19.051,1317
525,19.066,1318
526,19.082,1319
526,19.09,1320
527,19.097,1322
527,19.113,1323
527,19.12,1324
528,19.136,1325
528,19.144,1326
529,19.151,1328
529,19.159,1329
530,19.151,1330
530,19.151,1331
531,19.151,1332
531,19.151,1333
532,19.151,1335
532,19.151,1336
533,19.136,1337
533,19.128,1338
534,19.12,1339
534,19.105,1341
535,19.09,1342
535,19.051,1343
536,19.028,1344
536,18.989,1345
536,18.943,1347
537,18.881,1348
537,18.812,1349
538,18.735,1350
538,18.642,1351
539,18.542,1352
539,18.449,1354
540,18.349,1355
540,18.248,1356
541,18.156,1357
541,18.071,1358
542,17.994,1360
542,17.932,1361
543,17.87,1362
543,17.824,1363
544,17.77,1364
544,17.731,1366
545,17.693,1367
545,17.662,1368
545,17.639,1369
546,17.631,1370
546,17.631,1371
547,17.639,1373
547,17.647,1374
548,17.67,1375
548,17.693,1376
549,17.724,1377
549,17.747,1379
550,17.77,1380
550,17.801,1381
551,17.84,1382
551,17.87,1383
552,17.894,1385
552,17.932,1386
553,17.955,1387
553,17.994,1388
554,18.009,1389
554,18.032,1390
554,18.048,1392
555,18.063,1393
555,18.079,1394
556,18.086,1395
556,18.094,1396
557,18.102,1398
557,18.11,1399
558,18.117,1400
558,18.125,1401
559,18.133,1402
559,18.133,1404
560,18.14,1405
560,18.148,1406
561,18.156,1407
561,18.156,1408
562,18.156,1409
562,18.148,1411
562,18.14,1412
563,18.133,1413
563,18.11,1414
564,18.086,1415
564,18.063,1417
565,18.032,1418
565,18.002,1419
566,17.971,1420
566,17.94,1421
567,17.917,1423
567,17.886,1424
568,17.855,1425
568,17.824,1426
569,17.801,1427
569,17.778,1428
570,17.755,1430
570,17.731,1431
571,17.716,1432
571,17.693,1433
571,17.67,1434
572,17.639,1436
572,17.6,1437
573,17.562,1438
573,17.523,1439
574,17.485,1440
574,17.446,1442
575,17.407,1443
575,17.361,1444
576,17.315,1445
576,17.261,1446
577,17.207,1447
577,17.137,1449
578,17.076,1450
578,16.998,1451
579,16.921,1452
579,16.829,1453
580,16.736,1455
580,16.644,1456
580,16.535,1457
581,16.443,1458
581,16.327,1459
582,16.219,1461
582,16.096,1462
583,15.972,1463
583,15.841,1464
584,15.71,1465
584,15.579,1466
585,15.478,1468
585,15.424,1469
586,15.386,1470
586,15.355,1471
587,15.347,1472
587,15.355,1474
588,15.37,1475
588,15.401,1476
589,15.424,1477
589,15.463,1478
589,15.502,1480
590,15.548,1481
590,15.586,1482
591,15.64,1483
591,15.687,1484
592,15.741,1485
592,15.795,1487
593,15.849,1488
593,15.903,1489
594,15.957,1490
594,16.019,1491
595,16.073,1493
595,16.127,1494
596,16.173,1495
596,16.227,1496
597,16.273,1497
597,16.304,1499
598,16.327,1500
598,16.343,1501
598,16.358,1502
599,16.381,1503
599,16.397,1504
600,16.42,1506
600,16.458,1507
601,16.489,1508
601,16.52,1509
602,16.566,1510
602,16.613,1512
603,16.651,1513
603,16.705,1514
604,16.759,1515
604,16.821,1516
605,16.883,1518
605,16.952,1519
606,17.014,1520
606,17.083,1521
606,17.145,1522
607,17.215,1523
607,17.284,1525
608,17.353,1526
608,17.423,1527
609,17.485,1528
609,17.546,1529
610,17.616,1531
610,17.677,1532
611,17.747,1533
611,17.816,1534
612,17.878,1535
612,17.948,1537
613,18.009,1538
613,18.071,1539
614,18.133,1540
614,18.187,1541
615,18.248,1542
615,18.302,1544
615,18.364,1545
616,18.426,1546
616,18.472,1547
617,18.526,1548
617,18.588,1550
618,18.634,1551
618,18.681,1552
619,18.735,1553
619,18.789,1554
620,18.85,1556
620,18.904,1557
621,18.958,1558
621,19.005,1559
622,19.066,1560
622,19.113,1561
623,19.167,1563
623,19.221,1564
624,19.267,1565
624,19.321,1566
624,19.375,1567
625,19.421,1569
625,19.468,1570
626,19.514,1571
626,19.56,1572
627,19.614,1573
627,19.66,1575
628,19.715,1576
628,19.769,1577
629,19.815,1578
629,19.869,1579
630,19.915,1580
630,19.969,1582
631,20.05,1584
631,20.11,1585
632,20.16,1586
632,20.22,1587
633,20.27,1588
633,20.33,1590
634,20.39,1591
634,20.44,1592
635,20.49,1593
635,20.56,1594
636,20.62,1595
636,20.67,1597
637,20.73,1598
637,20.78,1599
638,20.83,1600
638,20.88,1601
639,20.93,1603
639,20.97,1604
639,21.01,1605
640,21.06,1606
640,21.09,1607
641,21.13,1609
641,21.17,1610
642,21.21,1611
642,21.25,1612
643,21.29,1613
643,21.32,1614
644,21.35,1616
644,21.39,1617
645,21.43,1618
645,21.46,1619
646,21.49,1620
646,21.54,1622
647,21.57,1623
647,21.61,1624
647,21.64,1625
648,21.69,1626
648,21.74,1628
649,21.77,1629
649,21.81,1630
650,21.87,1631
650,21.91,1632
651,21.94,1633
651,21.99,1635
652,22.04,1636
652,22.08,1637
653,22.14,1638
653,22.18,1639
654,22.22,1641
654,22.26,1642
655,22.31,1643
655,22.36,1644
656,22.4,1645
656,22.43,1647
656,22.47,1648
657,22.51,1649
658,22.56,1651
658,22.6,1652
659,22.63,1653
659,22.67,1654
660,22.7,1656
660,22.74,1657
661,22.76,1658
661,22.8,1659
662,22.82,1660
662,22.85,1662
662,22.87,1663
663,22.89,1664
663,22.91,1665
664,22.92,1666
664,22.95,1668
665,22.98,1669
665,23,1670
666,23.03,1671
666,23.06,1672
667,23.09,1673
667,23.11,1675
668,23.13,1676
668,23.16,1677
669,23.18,1678
669,23.2,1679
670,23.23,1681
670,23.25,1682
671,23.28,1683
671,23.3,1684
671,23.33,1685
672,23.36,1687
672,23.37,1688
673,23.4,1689
673,23.43,1690
674,23.46,1691
674,23.5,1692
675,23.53,1694
675,23.56,1695
676,23.59,1696
676,23.62,1697
677,23.64,1698
677,23.67,1700
678,23.69,1701
678,23.72,1702
679,23.74,1703
679,23.77,1704
680,23.79,1706
680,23.8,1707
680,23.83,1708
681,23.85,1709
681,23.87,1710
682,23.89,1711
682,23.89,1713
683,23.88,1714
683,23.36,1715
684,22.79,1716
684,21.25,1717
685,2.863,1719
685,0.03086,1720
686,0.03086,1721
686,0.03086,1722
687,0.02315,1723
687,0.02315,1725
688,0.03086,1726
688,0.02315,1727
688,0.03086,1728
689,0.02315,1729
689,0.02315,1730
690,0.02315,1731
Strain (%),Stress (MPa),Time (sec)
0.0683,0.5147,
0.994,0.6192,1
1.925,0.7237,2
2.86,0.8202,2
3.8,0.9167,3
4.72,1.0052,4
5.66,1.0936,5
6.58,1.1821,5
7.52,1.2545,6
8.45,1.3349,7
9.39,1.3992,8
10.32,1.4635,8
11.24,1.5359,9
12.18,1.5922,10
13.11,1.6485,11
14.04,1.6967,11
14.98,1.7369,12
15.9,1.7852,13
16.84,1.8254,14
17.78,1.8656,14
18.7,1.9058,15
19.63,1.938,16
20.6,1.9702,17
21.5,2.002,17
22.4,2.043,18
23.4,2.067,19
24.3,2.099,20
25.2,2.123,20
26.2,2.147,21
27.1,2.163,22
28,2.187,23
28.9,2.203,23
29.9,2.227,24
30.8,2.252,25
31.7,2.268,26
32.7,2.284,26
33.6,2.3,27
34.5,2.316,28
35.5,2.34,29
36.4,2.348,29
37.3,2.364,30
38.3,2.38,31
39.2,2.388,32
40.1,2.404,32
41.1,2.42,33
42,2.429,34
42.9,2.445,35
43.9,2.453,35
44.8,2.469,36
45.7,2.477,37
46.7,2.485,38
47.6,2.493,38
48.5,2.509,39
49.4,2.517,40
50.4,2.533,41
51.3,2.541,41
52.2,2.549,42
53.2,2.557,43
54.1,2.565,44
55,2.573,44
56,2.581,45
56.9,2.597,46
57.8,2.605,47
58.8,2.613,47
59.7,2.622,48
60.6,2.63,49
61.6,2.638,50
62.5,2.654,50
63.4,2.662,51
64.3,2.67,52
65.3,2.678,53
66.2,2.686,53
67.1,2.694,54
68.1,2.71,55
69,2.718,56
69.9,2.726,56
70.9,2.734,57
71.8,2.742,58
72.7,2.75,59
73.7,2.758,59
74.6,2.766,60
75.5,2.774,61
76.5,2.79,62
77.4,2.798,62
78.3,2.806,63
79.3,2.814,64
80.2,2.823,65
81.1,2.831,65
82.1,2.839,66
83,2.847,67
83.9,2.855,68
84.9,2.863,68
85.8,2.871,69
86.7,2.879,70
87.6,2.887,71
88.6,2.895,71
89.5,2.903,72
90.4,2.911,73
91.4,2.927,74
92.3,2.927,74
93.2,2.935,75
94.2,2.943,76
95.1,2.951,77
96,2.959,77
97,2.967,78
97.9,2.975,79
98.8,2.983,80
99.8,2.991,80
100.7,2.999,81
101.6,2.999,82
102.5,3.007,83
103.5,3.024,83
104.4,3.024,84
105.3,3.032,85
106.3,3.04,86
107.2,3.048,86
108.1,3.056,87
109.1,3.064,88
110,3.08,89
110.9,3.088,89
111.9,3.088,90
112.8,3.104,91
113.7,3.104,92
114.7,3.112,92
115.6,3.12,93
116.5,3.136,94
117.5,3.136,95
118.4,3.144,95
119.3,3.152,96
120.3,3.16,97
121.2,3.168,98
122.1,3.176,98
123,3.184,99
124,3.184,100
124.9,3.2,101
125.8,3.209,101
126.8,3.209,102
127.7,3.225,103
128.6,3.233,104
129.6,3.241,104
130.5,3.249,105
131.4,3.257,106
132.4,3.257,107
133.3,3.273,107
134.2,3.281,108
135.2,3.289,109
136.1,3.297,110
137,3.313,110
138,3.321,111
138.9,3.329,112
139.8,3.337,113
140.8,3.345,113
141.7,3.353,114
142.6,3.361,115
143.5,3.369,116
144.5,3.385,116
145.4,3.393,117
146.3,3.402,118
147.3,3.41,119
148.2,3.418,119
149.1,3.434,120
150.1,3.442,121
151,3.45,122
151.9,3.458,122
152.9,3.474,123
153.8,3.482,124
154.7,3.498,125
155.7,3.506,125
156.6,3.522,126
157.5,3.53,127
158.4,3.538,128
159.4,3.554,128
160.3,3.57,129
161.2,3.586,130
162.2,3.595,131
163.1,3.603,131
164,3.619,132
165,3.635,133
165.9,3.651,134
166.8,3.659,134
167.8,3.675,135
168.7,3.691,136
169.6,3.699,137
170.6,3.715,137
171.5,3.723,138
172.4,3.739,139
173.4,3.747,140
174.3,3.763,140
175.2,3.771,141
176.2,3.796,142
177.1,3.804,143
178,3.82,143
178.9,3.828,144
179.9,3.844,145
180.8,3.86,146
181.7,3.868,146
182.7,3.884,147
183.6,3.9,148
184.5,3.908,149
185.5,3.924,149
186.4,3.94,150
187.3,3.956,151
188.3,3.972,152
189.2,3.981,152
190.1,3.997,153
191.1,4.013,154
192,4.029,155
192.9,4.037,155
193.9,4.053,156
194.8,4.069,157
195.7,4.085,158
196.6,4.101,158
197.6,4.117,159
198.5,4.133,160
199.4,4.149,161
200,4.165,161
201,4.182,162
202,4.198,163
203,4.214,164
204,4.23,164
205,4.246,165
206,4.27,166
207,4.278,167
208,4.294,167
209,4.31,168
210,4.326,169
211,4.342,170
212,4.358,170
212,4.375,171
213,4.391,172
214,4.407,173
215,4.423,173
216,4.439,174
217,4.463,175
218,4.479,176
219,4.487,176
220,4.503,177
221,4.527,178
222,4.543,179
223,4.559,179
224,4.576,180
225,4.6,181
226,4.616,182
226,4.632,182
227,4.648,183
228,4.664,184
229,4.68,185
230,4.704,185
231,4.72,186
232,4.736,187
233,4.752,188
234,4.769,188
235,4.785,189
236,4.809,190
237,4.825,191
238,4.841,191
239,4.865,192
240,4.873,193
240,4.897,194
241,4.913,194
242,4.929,195
243,4.945,196
244,4.97,197
245,4.986,197
246,5.002,198
247,5.026,199
248,5.042,200
249,5.058,200
250,5.082,201
251,5.106,202
252,5.122,203
253,5.138,203
254,5.163,204
255,5.179,205
256,5.195,206
256,5.219,206
257,5.227,207
258,5.251,208
259,5.267,209
260,5.283,209
261,5.299,210
262,5.323,211
263,5.34,212
264,5.356,212
265,5.38,213
266,5.396,214
267,5.412,215
268,5.428,215
269,5.452,216
270,5.46,217
270,5.476,218
271,5.492,218
272,5.508,219
273,5.524,220
274,5.541,221
275,5.557,221
276,5.573,222
277,5.589,223
278,5.605,224
279,5.621,224
280,5.637,225
281,5.661,226
282,5.677,227
283,5.701,227
283,5.717,228
284,5.742,229
285,5.758,230
286,5.782,230
287,5.806,231
288,5.822,232
289,5.838,233
290,5.862,233
291,5.886,234
292,5.902,235
293,5.927,236
294,5.943,236
295,5.959,237
296,5.975,238
297,5.991,239
297,6.007,239
298,6.031,240
299,6.047,241
300,6.063,242
301,6.079,242
302,6.095,243
303,6.111,244
304,6.136,245
305,6.152,245
306,6.176,246
307,6.192,247
308,6.208,248
309,6.232,248
310,6.248,249
311,6.264,250
311,6.288,251
312,6.304,251
313,6.329,252
314,6.345,253
315,6.361,254
316,6.393,254
317,6.409,255
318,6.433,256
319,6.449,257
320,6.465,257
321,6.481,258
322,6.506,259
323,6.53,260
324,6.546,260
324,6.562,261
325,6.586,262
326,6.602,263
327,6.618,263
328,6.642,264
329,6.658,265
330,6.674,266
331,6.69,266
332,6.715,267
333,6.723,268
334,6.739,269
335,6.763,269
336,6.787,270
337,6.803,271
338,6.819,272
338,6.835,272
339,6.851,273
340,6.867,274
341,6.883,275
342,6.9,275
343,6.924,276
344,6.932,277
345,6.956,278
346,6.972,278
347,6.988,279
348,7.012,280
349,7.028,281
350,7.052,281
351,7.06,282
352,7.085,283
352,7.109,284
353,7.125,284
354,7.141,285
355,7.165,286
356,7.181,287
357,7.197,287
358,7.221,288
359,7.237,289
360,7.261,290
361,7.277,290
362,7.294,291
363,7.31,292
364,7.326,293
365,7.35,293
365,7.366,294
366,7.382,295
367,7.398,296
368,7.406,296
369,7.422,297
370,7.438,298
371,7.454,299
372,7.47,299
373,7.495,300
374,7.503,301
375,7.527,302
376,7.543,302
377,7.567,303
378,7.575,304
379,7.591,305
380,7.615,305
380,7.631,306
381,7.647,307
382,7.663,308
383,7.688,308
384,7.704,309
385,7.72,310
386,7.744,311
387,7.76,311
388,7.784,312
389,7.8,313
390,7.824,314
391,7.84,314
392,7.865,315
393,7.889,316
394,7.905,317
394,7.921,317
395,7.953,318
396,7.969,319
397,7.977,320
398,8.001,320
399,8.017,321
400,8.041,322
401,8.058,323
402,8.082,323
403,8.098,324
404,8.122,325
405,8.138,326
406,8.162,326
407,8.178,327
407,8.21,328
408,8.218,329
409,8.234,329
410,8.259,330
411,8.267,331
412,8.275,332
413,8.291,332
414,8.299,333
415,8.307,334
416,8.323,335
417,8.331,335
418,8.339,336
419,8.347,337
420,8.355,338
421,8.363,338
421,8.371,339
422,8.387,340
423,8.395,341
424,8.411,341
425,8.419,342
426,8.435,343
427,8.46,344
428,8.476,344
429,8.5,345
430,8.516,346
431,8.54,347
432,8.556,347
433,8.58,348
434,8.596,349
435,8.612,350
435,8.628,350
436,8.645,351
437,8.661,352
438,8.677,353
439,8.693,353
440,8.717,354
441,8.733,355
442,8.757,356
443,8.773,356
444,8.797,357
445,8.813,358
446,8.838,359
447,8.854,359
448,8.862,360
448,8.878,361
449,8.894,362
450,8.902,362
451,8.918,363
452,8.926,364
453,8.942,365
454,8.95,365
455,8.958,366
456,8.974,367
457,8.982,368
458,8.998,368
459,9.022,369
460,9.039,370
461,9.055,371
462,9.071,371
462,9.095,372
463,9.119,373
464,9.135,374
465,9.159,374
466,9.175,375
467,9.207,376
468,9.232,377
469,9.256,377
470,9.288,378
471,9.312,379
472,9.344,380
473,9.368,380
474,9.392,381
475,9.417,382
476,9.441,383
476,9.457,383
477,9.489,384
478,9.513,385
479,9.529,386
480,9.561,386
481,9.577,387
482,9.593,388
483,9.618,389
484,9.634,389
485,9.65,390
486,9.666,391
487,9.682,392
488,9.698,392
489,9.722,393
489,9.746,394
490,9.762,395
491,9.786,395
492,9.803,396
493,9.819,397
494,9.843,398
495,9.859,398
496,9.875,399
497,9.891,400
498,9.907,401
499,9.923,401
500,9.939,402
501,9.955,403
502,9.963,404
503,9.971,404
503,9.979,405
504,9.995,406
506,10.02,407
507,10.028,408
508,10.052,409
508,10.068,409
509,10.1,410
510,10.124,411
511,10.148,412
512,10.172,412
513,10.205,413
514,10.237,414
515,10.261,415
516,10.293,415
517,10.325,416
518,10.349,417
519,10.373,418
520,10.398,418
521,10.414,419
521,10.438,420
522,10.462,421
523,10.478,421
524,10.494,422
525,10.51,423
526,10.526,424
527,10.55,424
528,10.558,425
529,10.574,426
530,10.591,427
531,10.607,427
532,10.623,428
533,10.639,429
534,10.655,430
535,10.671,430
535,10.687,431
536,10.695,432
537,10.711,433
538,10.719,433
539,10.727,434
540,10.735,435
541,10.751,436
542,10.759,436
543,10.759,437
544,10.767,438
545,10.776,439
546,10.784,439
547,10.792,440
548,10.8,441
549,10.816,442
549,10.824,442
550,10.84,443
551,10.848,444
552,10.864,445
553,10.872,445
554,10.888,446
555,10.896,447
556,10.912,448
557,10.928,448
558,10.944,449
559,10.96,450
560,10.985,451
561,11.001,451
562,11.025,452
562,11.057,453
563,11.081,454
564,11.113,454
565,11.137,455
566,11.162,456
567,11.186,457
568,11.202,457
569,11.218,458
570,11.242,459
571,11.258,460
572,11.282,460
573,11.306,461
574,11.322,462
575,11.346,463
576,11.354,463
576,11.371,464
577,11.395,465
578,11.411,466
579,11.435,466
580,11.459,467
581,11.491,468
582,11.523,469
583,11.547,469
584,11.572,470
585,11.596,471
586,11.612,472
587,11.628,472
588,11.644,473
589,11.66,474
589,11.684,475
590,11.7,475
591,11.716,476
592,11.732,477
593,11.749,478
594,11.757,478
595,11.773,479
596,11.789,480
597,11.805,481
598,11.821,481
599,11.845,482
600,11.853,483
601,11.869,484
602,11.885,484
603,11.893,485
603,11.909,486
604,11.917,487
605,11.917,487
606,11.933,488
607,11.925,489
608,11.933,490
609,11.925,490
610,11.925,491
611,11.925,492
612,11.925,493
613,11.933,493
614,11.942,494
615,11.95,495
616,11.958,496
617,11.982,496
617,11.998,497
618,12.022,498
619,12.046,499
620,12.07,499
621,12.102,500
622,12.118,501
623,12.151,502
624,12.167,502
625,12.207,503
626,12.231,504
627,12.263,505
628,12.295,505
629,12.328,506
630,12.36,507
630,12.392,508
631,12.416,508
632,12.44,509
633,12.456,510
634,12.472,511
635,12.48,511
636,12.504,512
637,12.512,513
638,12.537,514
639,12.545,514
640,12.561,515
641,12.569,516
642,12.585,517
643,12.601,517
644,12.625,518
645,12.633,519
646,12.649,520
646,12.665,520
647,12.681,521
648,12.697,522
649,12.705,523
650,12.722,523
651,12.73,524
652,12.746,525
653,12.762,526
654,12.778,526
655,12.794,527
656,12.81,528
657,12.818,529
658,12.826,529
659,12.842,530
660,12.85,531
660,12.866,532
661,12.874,532
662,12.882,533
663,12.906,534
664,12.923,535
665,12.939,535
666,12.955,536
667,12.979,537
668,12.995,538
669,13.019,538
670,13.035,539
671,13.067,540
672,13.083,541
673,13.124,541
674,13.156,542
674,13.196,543
675,13.228,544
676,13.268,544
677,13.309,545
678,13.349,546
679,13.381,547
680,13.421,547
681,13.453,548
682,13.494,549
683,13.526,550
684,13.566,550
685,13.598,551
686,13.63,552
687,13.654,553
687,13.687,553
688,13.719,554
689,13.751,555
690,13.775,556
691,13.807,556
692,13.831,557
693,13.863,558
694,13.88,559
695,13.896,559
696,13.92,560
697,13.936,561
698,13.96,562
699,13.976,562
700,14,563
701,14.016,564
701,14.024,565
702,14.04,565
703,14.048,566
704,14.073,567
705,14.081,568
706,14.089,568
707,14.097,569
708,14.113,570
709,14.129,571
710,14.145,571
711,14.161,572
712,14.169,573
713,14.185,574
714,14.201,574
715,14.217,575
715,14.225,576
716,14.233,577
717,14.241,577
718,14.241,578
719,14.241,579
720,14.241,580
721,14.249,580
722,14.249,581
723,14.249,582
724,14.257,583
725,14.265,583
726,14.274,584
727,14.29,585
728,14.306,586
728,14.322,586
729,14.346,587
730,14.37,588
731,14.386,589
732,14.418,589
733,14.434,590
734,14.458,591
735,14.491,592
736,14.515,592
737,14.555,593
738,14.587,594
739,14.635,595
740,14.676,595
741,14.724,596
742,14.764,597
742,14.804,598
743,14.844,598
744,14.885,599
745,14.933,600
746,14.981,601
747,15.021,601
748,15.078,602
749,15.126,603
750,15.166,604
751,15.198,605
752,15.239,605
753,15.271,606
754,15.303,607
755,15.335,608
756,15.367,608
757,15.399,609
758,15.423,610
759,15.448,611
760,15.472,611
761,15.496,612
761,15.528,613
762,15.552,614
763,15.576,614
764,15.6,615
765,15.633,616
766,15.657,617
767,15.673,617
768,15.689,618
769,15.697,619
770,15.705,620
771,15.721,620
772,15.729,621
773,15.745,622
774,15.761,623
775,15.777,623
775,15.793,624
776,15.809,625
777,15.826,626
778,15.85,626
779,15.874,627
780,15.898,628
781,15.93,629
782,15.954,629
783,15.986,630
784,16.01,631
785,16.035,632
786,16.059,632
787,16.083,633
788,16.107,634
789,16.131,635
789,16.155,635
790,16.179,636
791,16.195,637
792,16.22,638
793,16.244,638
794,16.268,639
795,16.3,640
796,16.332,641
797,16.364,641
798,16.388,642
799,16.421,643
800,16.453,644
801,16.493,644
802,16.525,645
802,16.557,646
803,16.589,647
804,16.606,647
805,16.638,648
806,16.654,649
807,16.662,650
808,16.686,650
809,16.702,651
810,16.718,652
811,16.742,653
812,16.758,653
813,16.774,654
814,16.782,655
815,16.791,656
816,16.791,656
816,16.799,657
817,16.799,658
818,16.799,659
819,16.799,659
820,16.807,660
821,16.807,661
822,16.799,662
823,16.807,662
824,16.815,663
825,16.831,664
826,16.847,665
827,16.863,665
828,16.895,666
829,16.911,667
829,16.935,668
830,16.967,668
831,17.008,669
832,17.056,670
833,17.112,671
834,17.168,671
835,17.233,672
836,17.289,673
837,17.337,674
838,17.386,674
839,17.426,675
840,17.466,676
841,17.498,677
842,17.546,678
843,17.579,679
844,17.603,679
845,17.635,680
846,17.659,681
847,17.683,682
848,17.723,682
849,17.755,683
850,17.788,684
850,17.828,685
851,17.852,685
852,17.876,686
853,17.9,687
854,17.924,688
855,17.957,688
856,17.989,689
857,18.013,690
858,18.045,691
859,18.069,691
860,18.093,692
861,18.117,693
862,18.141,694
863,18.166,694
864,18.182,695
864,18.206,696
865,18.222,697
866,18.246,697
867,18.262,698
868,18.278,699
869,18.302,700
870,18.326,700
871,18.359,701
872,18.375,702
873,18.391,703
874,18.399,703
875,18.407,704
876,18.415,705
877,18.415,706
878,18.423,706
878,18.431,707
879,18.439,708
880,18.455,709
881,18.487,709
882,18.511,710
883,18.535,711
884,18.568,712
885,18.592,712
886,18.624,713
887,18.648,714
888,18.672,715
889,18.696,715
890,18.72,716
891,18.745,717
891,18.769,718
892,18.793,718
893,18.825,719
894,18.857,720
895,18.881,721
896,18.913,721
897,18.946,722
898,18.986,723
899,19.01,724
900,19.034,724
901,19.066,725
902,19.09,726
903,19.114,727
904,19.139,727
905,19.171,728
905,19.203,729
906,19.227,730
907,19.251,730
908,19.275,731
909,19.299,732
910,19.324,733
911,19.34,733
912,19.348,734
913,19.356,735
914,19.364,736
915,19.38,736
916,19.396,737
917,19.412,738
918,19.428,739
919,19.444,739
919,19.476,740
920,19.5,741
921,19.533,742
922,19.565,742
923,19.597,743
924,19.621,744
925,19.653,745
926,19.677,745
927,19.71,746
928,19.734,747
929,19.766,748
930,19.782,748
931,19.806,749
932,19.822,750
932,19.838,751
933,19.854,751
934,19.87,752
935,19.878,753
936,19.854,754
937,19.838,754
938,19.806,755
939,19.782,756
940,19.774,757
941,19.758,757
942,19.742,758
943,19.718,759
944,19.693,760
945,19.677,760
946,19.669,761
946,19.661,762
947,19.653,763
948,19.653,763
949,19.661,764
950,19.677,765
951,19.693,766
952,19.718,766
953,19.734,767
954,19.75,768
955,19.758,769
956,19.758,769
957,19.758,770
958,19.766,771
959,19.782,772
959,19.798,772
960,19.814,773
961,19.83,774
962,19.854,775
963,19.886,775
964,19.919,776
965,19.951,777
966,19.991,778
967,20.05,779
968,20.11,779
969,20.17,780
970,20.21,781
971,20.26,782
972,20.31,782
973,20.37,783
974,20.42,784
975,20.47,785
976,20.51,785
977,20.54,786
978,20.55,787
979,20.56,788
980,20.57,788
980,20.58,789
981,20.58,790
982,20.58,791
983,20.57,791
984,20.56,792
985,20.57,793
986,20.57,794
987,20.58,794
988,20.59,795
989,20.6,796
990,20.61,797
991,20.62,797
992,20.63,799
993,20.63,799
994,20.63,800
995,20.63,801
996,20.63,802
997,20.63,802
998,20.63,803
999,20.65,804
1000,20.67,805
1001,20.69,805
1001,20.71,806
1002,20.74,807
1003,20.75,808
1004,20.76,808
1005,20.79,809
1006,20.8,810
1007,20.81,811
1008,20.84,811
1009,20.85,812
1010,20.89,813
1011,20.94,814
1012,21,814
1013,21.07,815
1014,21.13,816
1015,21.2,817
1015,21.25,817
1016,21.32,818
1017,21.37,819
1018,21.43,820
1019,21.49,820
1020,21.56,821
1021,21.62,822
1022,21.66,823
1023,21.7,823
1024,21.74,824
1025,21.79,825
1026,21.83,826
1027,21.88,826
1028,21.92,827
1028,21.96,828
1029,21.99,829
1030,22.03,829
1031,22.07,830
1032,22.09,831
1033,22.11,832
1034,22.15,832
1035,22.16,833
1036,22.17,834
1037,22.17,835
1038,22.15,835
1039,22.14,836
1040,22.13,837
1041,22.11,838
1042,22.11,838
1042,22.09,839
1043,22.09,840
1044,22.1,841
1045,22.13,841
1046,22.17,842
1047,22.22,843
1048,22.25,844
1049,22.3,844
1050,22.34,845
1051,22.39,846
1052,22.44,847
1053,22.48,847
1054,22.56,849
1055,22.6,849
1056,22.64,850
1057,22.68,851
1058,22.73,852
1059,22.77,852
1060,22.81,853
1061,22.85,854
1062,22.89,855
1063,22.91,855
1063,22.94,856
1064,22.97,857
1065,23,858
1066,23.03,858
1067,23.07,859
1068,23.09,860
1069,23.13,861
1070,23.14,861
1071,23.14,862
1072,23.15,863
1073,23.15,864
1074,23.16,864
1075,23.17,865
1076,23.18,866
1077,23.19,867
1077,23.2,867
1078,23.22,868
1079,23.22,869
1080,23.22,870
1081,23.24,870
1082,23.26,871
1083,23.28,872
1084,23.3,873
1085,23.32,873
1086,23.34,874
1087,23.38,875
1088,23.41,876
1089,23.44,876
1090,23.47,877
1090,23.51,878
1091,23.55,879
1092,23.59,879
1093,23.63,880
1094,23.67,881
1095,23.72,882
1096,23.76,882
1097,23.79,883
1098,23.83,884
1099,23.87,885
1100,23.89,885
1101,23.93,886
1102,23.97,887
1103,24,888
1104,24.02,888
1104,24.04,889
1105,24.08,890
1106,24.1,891
1107,24.12,891
1108,24.15,892
1109,24.17,893
1110,24.2,894
1111,24.24,894
1112,24.27,895
1113,24.3,896
1114,24.33,897
1115,24.37,897
1116,24.41,898
1117,24.43,899
1118,24.46,900
1118,24.49,900
1119,24.52,901
1120,24.53,902
1121,24.55,903
1122,24.57,903
1123,24.57,904
1124,24.58,905
1125,24.58,906
1126,24.57,906
1127,24.57,907
1128,24.57,908
1129,24.58,909
1130,24.6,909
1131,24.61,910
1131,24.62,911
1132,24.63,912
1133,24.66,912
1134,24.67,913
1135,24.68,914
1136,24.71,915
1137,24.73,915
1138,24.75,916
1139,24.78,917
1140,24.82,918
1141,24.84,918
1142,24.86,919
1143,24.89,920
1144,24.91,921
1145,24.94,921
1145,24.95,922
1146,24.96,923
1147,24.98,924
1148,24.98,924
1149,24.98,925
1150,24.98,926
1151,24.99,927
1152,24.99,927
1153,24.99,928
1154,24.97,929
1155,24.93,930
1156,24.89,930
1157,24.84,931
1158,24.79,932
1158,24.75,933
1159,24.71,933
1160,24.68,934
1161,24.66,935
1162,24.66,936
1163,24.68,936
1164,24.7,937
1165,24.74,938
1166,24.78,939
1167,24.82,939
1168,24.86,940
1169,24.93,941
1170,24.99,942
1171,25.07,943
1172,25.13,943
1173,25.18,944
1174,25.22,945
1175,25.26,946
1176,25.29,946
1177,25.32,947
1178,25.35,948
1179,25.35,949
1179,25.37,949
1180,25.39,950
1181,25.39,951
1182,25.4,952
1183,25.42,952
1184,25.44,953
1185,25.46,954
1186,25.49,955
1187,25.52,955
1188,25.52,956
1189,25.52,957
1190,25.52,958
1191,25.52,958
1192,25.52,959
1193,25.53,960
1193,25.54,961
1194,25.55,961
1195,25.56,962
1196,25.56,963
1197,25.57,964
1198,25.59,964
1199,25.61,965
1200,25.65,966
1201,25.69,967
1202,25.75,967
1203,25.81,968
1204,25.87,969
1205,25.94,970
1206,26.01,970
1206,26.08,971
1207,26.15,972
1208,26.22,973
1209,26.3,973
1210,26.36,974
1211,26.42,975
1212,26.46,976
1213,26.51,976
1214,26.54,977
1215,26.57,978
1216,26.6,979
1217,26.64,979
1218,26.67,980
1219,26.71,981
1220,26.73,982
1220,26.75,982
1221,26.78,983
1222,26.79,984
1223,26.82,985
1224,26.83,985
1225,26.84,986
1226,26.85,987
1227,26.84,988
1228,26.83,988
1229,26.83,989
1230,26.82,990
1231,26.82,991
1232,26.83,991
1233,26.83,992
1234,26.84,993
1234,26.85,994
1235,26.87,994
1236,26.87,995
1237,26.88,996
1238,26.88,997
1239,26.89,997
1240,26.91,998
1241,26.9,999
1242,26.89,1000
1243,26.88,1000
1244,26.87,1001
1245,26.87,1002
1246,26.87,1003
1247,26.87,1003
1247,26.88,1004
1248,26.89,1005
1249,26.9,1006
1250,26.9,1006
1251,26.91,1007
1252,26.93,1008
1253,26.94,1009
1254,26.95,1009
1255,26.97,1010
1256,27,1011
1257,27.04,1012
1258,27.07,1012
1259,27.09,1013
1260,27.11,1014
1261,27.12,1015
1261,27.13,1015
1262,27.16,1016
1263,27.19,1017
1264,27.24,1018
1265,27.28,1018
1266,27.33,1019
1267,27.38,1020
1268,27.44,1021
1269,27.49,1021
1270,27.53,1022
1271,27.57,1024
1272,27.59,1024
1273,27.61,1025
1274,27.61,1026
1275,27.61,1027
1276,27.61,1027
1277,27.62,1028
1278,27.62,1029
1279,27.62,1030
1280,27.6,1030
1281,27.59,1031
1282,27.57,1032
1283,27.57,1033
1284,27.57,1033
1285,27.56,1034
1285,27.55,1035
1286,27.53,1036
1287,27.51,1036
1288,27.49,1037
1289,27.48,1038
1290,27.47,1039
1291,27.47,1039
1292,27.45,1040
1293,27.45,1041
1294,27.44,1042
1295,27.45,1042
1296,27.45,1043
1297,27.45,1044
1298,27.48,1045
1298,27.49,1045
1299,27.52,1046
1300,27.54,1047
1301,27.56,1048
1302,27.57,1048
1303,27.57,1049
1304,27.57,1050
1305,27.56,1051
1306,27.53,1051
1307,27.51,1052
1308,27.47,1053
1309,27.44,1054
1310,27.4,1054
1311,27.36,1055
1312,27.32,1056
1312,27.3,1057
1313,27.27,1057
1314,27.25,1058
1315,27.23,1059
1316,27.2,1060
1317,27.18,1060
1318,27.16,1061
1319,27.12,1062
1320,27.1,1063
1321,27.08,1063
1322,27.04,1064
1323,27,1065
1324,26.93,1066
1325,26.86,1066
1326,26.79,1067
1326,26.7,1068
1327,26.62,1069
1328,26.54,1069
1329,26.44,1070
1330,26.34,1071
1331,26.24,1072
1332,26.13,1072
1333,25.99,1073
1334,25.85,1074
1335,25.68,1075
1336,25.48,1075
1337,25.25,1076
1338,25,1077
1339,24.7,1078
1339,24.37,1078
1340,24.01,1079
1341,23.59,1080
1342,23.11,1081
1343,22.48,1081
1344,21.73,1082
1345,20.85,1083
1346,19.669,1084
1347,17.498,1084
1348,0.06433,1085
1349,0.06433,1086
1350,0.06433,1087
1351,0.06433,1087
1352,0.05629,1088
1353,0.05629,1089
1353,0.05629,1090
1354,0.05629,1090
1355,0.05629,1091
1356,0.06433,1092
1357,0.06433,1093
1358,0.05629,1093
1359,0.06433,1094
1360,0.06433,1095
1361,0.06433,1096
1362,0.05629,1096
1363,0.06433,1097
1364,0.05629,1098
1365,0.05629,1099
1366,0.05629,1099
1367,0.05629,1100
1367,0.05629,1101
1368,0.05629,1102
1369,0.05629,1102
1370,0.05629,1103
1371,0.05629,1104
1372,0.06433,1105
1373,0.06433,1105
1374,0.05629,1106
1375,0.06433,1107
1376,0.06433,1108
1377,0.05629,1108
1378,0.06433,1109
1379,0.05629,1110
1380,0.06433,1111
1380,0.06433,1111
1381,0.06433,1112
1382,0.06433,1113
1383,0.06433,1114
1384,0.06433,1114
1385,0.06433,1115
1386,0.06433,1116
1387,0.06433,1117
1388,0.06433,1117
1389,0.06433,1118
1390,0.06433,1119
1391,0.07237,1120
1391,0.06433,1120