File: in-progress/Koerner_2005_Polymer/RawDataFromAuthors/cnttobreak/cnt10apu.csv
Strain (%),Stress (MPa),Time (sec)
0.0485,0.551,
0.91,1.3408,1
1.76,2.039,1
2.62,2.645,2
3.46,3.178,3
4.31,3.618,4
5.18,4.004,4
6.03,4.335,5
6.86,4.592,6
7.74,4.849,6
8.58,5.033,7
9.44,5.216,8
10.3,5.382,8
11.15,5.51,9
12,5.62,10
12.85,5.749,11
13.7,5.859,11
14.56,5.951,12
15.41,6.025,13
16.27,6.08,13
17.12,6.153,14
17.97,6.208,15
18.82,6.263,15
19.67,6.3,16
20.5,6.355,17
21.4,6.392,18
22.2,6.429,18
23.1,6.465,19
23.9,6.502,20
24.8,6.539,20
25.7,6.557,21
26.5,6.594,22
27.4,6.631,23
28.2,6.649,23
29.1,6.686,24
29.9,6.704,25
30.8,6.723,25
31.6,6.741,26
32.5,6.759,27
33.3,6.778,27
34.2,6.796,28
35,6.814,29
35.9,6.833,30
36.7,6.851,30
37.6,6.869,31
38.4,6.906,32
39.3,6.925,32
40.2,6.943,33
41,6.961,34
41.9,6.98,34
42.7,6.998,35
43.6,7.016,36
44.4,7.035,37
45.3,7.053,37
46.1,7.071,38
47,7.09,39
47.8,7.108,39
48.7,7.108,40
49.6,7.127,41
50.4,7.145,41
51.3,7.163,42
52.1,7.163,43
53,7.2,44
53.8,7.218,44
54.7,7.237,45
55.5,7.255,46
56.4,7.274,46
57.2,7.274,47
58.1,7.292,48
58.9,7.31,49
59.8,7.329,49
60.6,7.347,50
61.5,7.347,51
62.3,7.365,51
63.2,7.384,52
64,7.402,53
64.9,7.42,53
65.8,7.42,54
66.6,7.439,55
67.5,7.457,56
68.3,7.457,56
69.2,7.476,57
70,7.494,58
70.9,7.494,58
71.7,7.512,59
72.6,7.549,60
73.4,7.549,60
74.3,7.567,61
75.1,7.586,62
76,7.586,63
76.8,7.604,63
77.7,7.604,64
78.6,7.623,65
79.4,7.641,65
80.3,7.659,66
81.1,7.659,67
82,7.678,68
82.8,7.696,68
83.7,7.714,69
84.5,7.733,70
85.4,7.751,70
86.2,7.769,71
87.1,7.788,72
87.9,7.806,72
88.8,7.825,73
89.6,7.843,74
90.5,7.861,75
91.4,7.88,75
92.2,7.898,76
93.1,7.916,77
93.9,7.935,77
94.8,7.953,78
95.6,7.971,79
96.5,7.971,79
97.3,7.99,80
98.2,7.99,81
99,8.008,82
99.9,8.027,82
100.7,8.045,83
101.6,8.063,84
102.5,8.063,84
103.3,8.1,85
104.2,8.1,86
105,8.118,86
105.9,8.137,87
106.7,8.155,88
107.6,8.155,89
108.4,8.174,89
109.3,8.192,90
110.1,8.192,91
111,8.21,91
111.8,8.229,92
112.7,8.247,93
113.5,8.265,94
114.4,8.265,94
115.3,8.284,95
116.1,8.284,96
116.9,8.302,96
117.8,8.32,97
118.7,8.357,98
119.5,8.376,98
120.4,8.394,99
121.2,8.394,100
122.1,8.412,101
122.9,8.431,101
123.8,8.449,102
124.6,8.449,103
125.5,8.449,103
126.3,8.467,104
127.2,8.467,105
128.1,8.486,105
128.9,8.504,106
129.8,8.504,107
130.6,8.523,108
131.5,8.523,108
132.3,8.541,109
133.2,8.559,110
134,8.596,110
134.9,8.614,111
135.7,8.633,112
136.6,8.651,113
137.4,8.669,113
138.3,8.706,114
139.1,8.725,115
140,8.761,115
140.8,8.78,116
141.7,8.798,117
142.5,8.816,117
143.4,8.835,118
144.3,8.853,119
145.1,8.853,120
146,8.89,120
146.8,8.908,121
147.7,8.927,122
148.5,8.945,122
149.4,8.963,123
150.2,8.982,124
151.1,9.018,124
151.9,9.055,125
152.8,9.074,126
153.6,9.11,127
154.5,9.129,127
155.4,9.147,128
156.2,9.165,129
157.1,9.184,129
157.9,9.22,130
158.8,9.22,131
159.6,9.257,131
160.5,9.294,132
161.3,9.312,133
162.2,9.312,134
163,9.331,134
163.9,9.331,135
164.7,9.331,136
165.6,9.349,136
166.5,9.367,137
167.3,9.367,138
168.1,9.386,139
169,9.404,139
169.9,9.423,140
170.7,9.459,141
171.6,9.478,141
172.4,9.496,142
173.3,9.533,143
174.1,9.569,143
175,9.606,144
175.8,9.625,145
176.7,9.643,146
177.5,9.643,146
178.4,9.68,147
179.3,9.68,148
180.1,9.68,148
181,9.68,149
181.8,9.698,150
182.7,9.716,150
183.5,9.735,151
184.4,9.753,152
185.2,9.772,153
186.1,9.79,153
186.9,9.827,154
187.8,9.845,155
188.6,9.882,155
189.5,9.9,156
190.3,9.918,157
191.2,9.918,158
192,9.955,158
192.9,9.992,159
193.8,10.01,160
194.6,10.029,160
195.5,10.047,161
196.3,10.065,162
197.2,10.084,162
198,10.102,163
198.9,10.102,164
199.7,10.12,165
201,10.139,165
201,10.139,166
202,10.157,167
203,10.157,167
204,10.194,168
205,10.212,169
206,10.249,169
207,10.267,170
207,10.286,171
208,10.304,172
209,10.323,172
210,10.323,173
211,10.341,174
212,10.359,174
213,10.359,175
213,10.396,176
214,10.414,176
215,10.433,177
216,10.451,178
217,10.488,179
218,10.506,179
218,10.543,180
219,10.561,181
220,10.616,181
221,10.635,182
222,10.653,183
223,10.653,184
224,10.672,184
224,10.69,185
225,10.708,186
226,10.727,186
227,10.745,187
228,10.782,188
229,10.8,188
230,10.837,189
230,10.874,190
231,10.91,191
232,10.929,191
233,10.929,192
234,10.947,193
235,10.965,193
236,10.984,194
236,11.002,195
237,11.039,195
238,11.076,196
239,11.094,197
240,11.094,198
241,11.112,198
242,11.131,199
242,11.149,200
243,11.167,200
244,11.186,201
245,11.241,202
246,11.278,203
247,11.296,203
248,11.333,204
248,11.388,205
249,11.425,205
250,11.443,206
251,11.48,207
252,11.498,207
253,11.498,208
253,11.516,209
254,11.535,210
255,11.553,210
256,11.572,211
257,11.572,212
258,11.59,212
259,11.608,213
259,11.627,214
260,11.645,214
261,11.663,215
262,11.682,216
263,11.7,217
264,11.737,217
265,11.755,218
265,11.774,219
266,11.792,219
267,11.829,220
268,11.829,221
269,11.847,221
270,11.865,222
271,11.884,223
271,11.884,224
272,11.902,224
273,11.902,225
274,11.921,226
275,11.939,226
276,11.976,227
277,11.976,228
277,12.012,229
278,12.031,229
279,12.031,230
280,12.067,231
281,12.086,231
282,12.104,232
282,12.123,233
283,12.141,233
284,12.141,234
285,12.178,235
286,12.178,236
287,12.214,236
288,12.233,237
288,12.251,238
289,12.251,238
290,12.251,239
291,12.269,240
292,12.269,240
293,12.306,241
294,12.325,242
294,12.325,243
295,12.343,243
296,12.361,244
297,12.361,245
298,12.361,245
299,12.38,246
300,12.38,247
300,12.398,248
301,12.398,248
302,12.416,249
303,12.416,250
304,12.416,250
305,12.435,251
306,12.453,252
306,12.472,252
307,12.49,253
308,12.508,254
309,12.563,255
310,12.582,255
311,12.618,256
312,12.655,257
312,12.692,257
313,12.729,258
314,12.747,259
315,12.802,260
316,12.839,260
317,12.857,261
318,12.876,262
318,12.894,262
319,12.931,263
320,12.967,264
321,12.986,264
322,13.023,265
323,13.041,266
324,13.078,267
324,13.096,267
325,13.114,268
326,13.133,269
327,13.151,269
328,13.169,270
329,13.206,271
330,13.206,271
330,13.243,272
331,13.261,273
332,13.28,274
333,13.316,274
334,13.353,275
335,13.372,276
335,13.39,276
336,13.427,277
337,13.427,278
338,13.463,279
339,13.482,279
340,13.5,280
341,13.537,281
341,13.574,281
342,13.592,282
343,13.61,283
344,13.647,283
345,13.684,284
346,13.702,285
347,13.721,286
347,13.739,286
348,13.757,287
349,13.794,288
350,13.812,288
351,13.849,289
352,13.867,290
353,13.886,290
353,13.904,291
354,13.923,292
355,13.941,293
356,13.959,293
357,13.996,294
358,14.033,295
359,14.051,295
359,14.051,296
360,14.07,297
361,14.088,298
362,14.125,298
363,14.143,299
364,14.161,300
365,14.143,300
365,14.161,301
366,14.143,302
367,14.143,302
368,14.125,303
369,14.106,304
370,14.106,305
370,14.088,305
371,14.07,306
372,14.051,307
373,14.07,307
374,14.07,308
375,14.088,309
376,14.106,309
376,14.125,310
377,14.161,311
378,14.161,312
379,14.18,312
380,14.161,313
381,14.161,314
382,14.161,314
382,14.18,315
383,14.216,316
384,14.272,316
385,14.308,317
386,14.363,318
387,14.4,319
388,14.437,319
388,14.474,320
389,14.51,321
390,14.529,321
391,14.547,322
392,14.565,323
393,14.602,324
394,14.621,324
394,14.639,325
395,14.657,326
396,14.676,326
397,14.694,327
398,14.731,328
399,14.767,328
399,14.804,329
400,14.823,330
401,14.859,331
402,14.914,331
403,14.951,332
404,14.988,333
405,15.043,333
406,15.08,334
406,15.098,335
407,15.153,336
408,15.19,336
409,15.227,337
410,15.263,338
411,15.3,338
412,15.337,339
412,15.355,340
413,15.392,340
414,15.41,341
415,15.447,342
416,15.465,343
417,15.484,343
417,15.502,344
418,15.539,345
419,15.557,345
420,15.576,346
421,15.612,347
422,15.631,347
423,15.649,348
423,15.667,349
424,15.686,350
425,15.704,350
426,15.723,351
427,15.741,352
428,15.759,352
429,15.778,353
429,15.796,354
430,15.814,355
431,15.833,355
432,15.87,356
433,15.906,357
434,15.925,357
435,15.943,358
435,15.961,359
436,15.98,359
437,15.961,360
438,15.98,361
439,15.98,362
440,16.016,362
441,16.016,363
441,16.035,364
442,16.053,364
443,16.072,365
444,16.072,366
445,16.09,366
446,16.127,367
446,16.127,368
447,16.108,369
448,16.09,369
449,16.108,370
450,16.127,371
451,16.127,371
452,16.127,372
452,16.127,373
453,16.127,374
454,16.127,374
455,16.127,375
456,16.108,376
457,16.108,376
458,16.09,377
458,16.09,378
459,16.09,378
460,16.108,379
461,16.127,380
462,16.163,381
463,16.2,381
464,16.237,382
464,16.292,383
465,16.329,383
466,16.384,384
467,16.402,385
468,16.439,385
469,16.439,386
470,16.494,387
470,16.512,388
471,16.549,388
472,16.586,389
473,16.604,390
474,16.623,390
475,16.641,391
476,16.623,392
476,16.623,392
477,16.586,393
478,16.586,394
479,16.623,395
480,16.678,395
481,16.714,396
481,16.77,397
482,16.806,397
483,16.843,398
484,16.898,399
485,16.935,400
486,16.972,400
487,17.008,401
487,17.063,402
488,17.1,402
489,17.137,403
490,17.174,404
491,17.21,404
492,17.247,405
493,17.284,406
493,17.284,407
494,17.302,407
495,17.302,408
496,17.302,409
497,17.302,409
498,17.284,410
499,17.284,411
499,17.284,411
500,17.284,412
501,17.265,413
502,17.265,414
503,17.265,414
504,17.247,415
505,17.247,416
505,17.247,416
506,17.247,417
507,17.247,418
508,17.247,419
509,17.247,419
510,17.265,420
510,17.284,421
511,17.284,421
512,17.302,422
513,17.321,423
514,17.321,423
515,17.357,424
516,17.376,425
516,17.394,426
517,17.412,426
518,17.412,427
519,17.412,428
520,17.449,428
521,17.486,429
522,17.559,430
523,17.614,431
524,17.651,431
524,17.688,432
525,17.725,433
526,17.78,434
527,17.816,434
528,17.853,435
529,17.89,436
530,17.945,436
530,18.019,437
531,18.055,438
532,18.092,438
533,18.147,439
534,18.184,440
535,18.239,441
536,18.239,441
536,18.276,442
537,18.257,443
538,18.257,443
539,18.257,444
540,18.239,445
541,18.257,445
542,18.276,446
542,18.294,447
543,18.331,448
544,18.367,448
545,18.404,449
546,18.441,450
547,18.478,450
548,18.514,451
548,18.533,452
549,18.551,453
550,18.588,453
551,18.606,454
552,18.625,455
553,18.661,455
553,18.716,456
554,18.753,457
555,18.79,457
556,18.827,458
557,18.882,459
558,18.919,460
559,18.937,460
559,18.992,461
560,19.029,462
561,19.047,462
562,19.084,463
563,19.102,464
564,19.139,464
565,19.157,465
565,19.176,466
566,19.212,467
567,19.231,467
568,19.268,468
569,19.286,469
570,19.304,469
571,19.304,470
571,19.304,471
572,19.286,472
573,19.286,472
574,19.286,473
575,19.268,474
576,19.268,474
577,19.268,475
577,19.268,476
578,19.268,476
579,19.286,477
580,19.268,478
581,19.268,479
582,19.231,479
582,19.231,480
583,19.249,481
584,19.268,481
585,19.304,482
586,19.341,483
587,19.378,483
588,19.433,484
588,19.47,485
589,19.506,486
590,19.561,486
591,19.616,487
592,19.653,488
593,19.708,488
594,19.727,489
594,19.763,490
595,19.819,490
596,19.837,491
597,19.892,492
598,19.929,493
599,19.947,493
600,19.984,494
600,20,495
601,20.02,495
602,20.04,496
603,20.08,497
604,20.08,498
605,20.11,498
606,20.17,499
607,20.19,500
607,20.22,500
608,20.24,501
609,20.22,502
610,20.24,503
611,20.24,503
612,20.22,504
612,20.24,505
613,20.24,505
614,20.26,506
615,20.26,507
616,20.3,507
617,20.31,508
618,20.33,509
618,20.35,510
619,20.37,510
620,20.41,511
621,20.44,512
622,20.48,512
623,20.52,513
624,20.53,514
624,20.57,515
625,20.61,515
626,20.65,516
627,20.68,517
628,20.72,517
629,20.76,518
630,20.77,519
630,20.81,519
631,20.83,520
632,20.85,521
633,20.85,522
634,20.85,522
635,20.87,523
636,20.87,524
636,20.88,524
637,20.9,525
638,20.9,526
639,20.92,526
640,20.9,527
641,20.92,528
642,20.94,529
642,20.98,529
643,20.99,530
644,21.05,531
645,21.09,531
646,21.1,532
647,21.12,533
647,21.14,533
648,21.18,534
649,21.2,535
650,21.21,536
651,21.23,536
652,21.27,537
653,21.29,538
653,21.32,538
654,21.36,539
655,21.4,540
656,21.42,541
657,21.43,541
658,21.45,542
659,21.47,543
659,21.51,543
660,21.53,544
661,21.55,545
662,21.58,545
663,21.62,546
664,21.66,547
665,21.69,548
665,21.71,548
666,21.75,549
667,21.77,550
668,21.8,550
669,21.82,551
670,21.84,552
671,21.88,552
671,21.91,553
672,21.95,554
673,21.97,555
674,21.99,555
675,22,556
676,22.02,557
676,22.02,557
677,22.04,558
678,22.06,559
679,22.08,560
680,22.1,560
681,22.11,561
682,22.13,562
682,22.15,562
683,22.19,563
684,22.21,564
685,22.22,564
686,22.24,565
687,22.28,566
688,22.3,567
688,22.33,567
689,22.35,568
690,22.37,569
691,22.37,569
692,22.39,570
693,22.39,571
694,22.39,571
694,22.39,572
695,22.41,573
696,22.43,574
697,22.46,574
698,22.5,575
699,22.54,576
700,22.56,577
701,22.59,577
702,22.61,578
703,22.63,579
703,22.65,580
704,22.68,580
705,22.7,581
706,22.72,582
707,22.76,582
708,22.79,583
709,22.83,584
709,22.87,585
710,22.9,585
711,22.92,586
712,22.94,587
713,22.98,587
714,23.01,588
715,23.05,589
715,23.09,589
716,23.11,590
717,23.14,591
718,23.18,592
719,23.2,592
720,23.22,593
720,23.22,594
721,23.22,594
722,23.23,595
723,23.25,596
724,23.25,596
725,23.27,597
726,23.27,598
726,23.27,599
727,23.29,599
728,23.31,600
729,23.35,601
730,23.36,601
731,23.4,602
732,23.46,603
732,23.49,603
733,23.53,604
734,23.55,605
735,23.55,606
736,23.57,606
737,23.57,607
738,23.57,608
738,23.57,608
739,23.57,609
740,23.57,610
741,23.58,611
742,23.58,611
743,23.58,612
744,23.6,613
744,23.58,613
745,23.58,614
746,23.58,615
747,23.57,615
748,23.57,616
749,23.58,617
749,23.58,618
750,23.62,618
751,23.68,619
752,23.75,620
753,23.8,620
754,23.86,621
755,23.91,622
755,23.99,622
756,24.06,623
757,24.12,624
758,24.19,625
759,24.25,625
760,24.28,626
761,24.34,627
761,24.37,627
762,24.41,628
763,24.43,629
764,24.47,630
765,24.48,630
766,24.48,631
767,24.5,632
767,24.54,632
768,24.58,633
769,24.61,634
770,24.65,634
771,24.69,635
772,24.72,636
773,24.74,637
773,24.8,637
774,24.81,638
775,24.87,639
776,24.87,639
777,24.91,640
778,24.92,641
779,24.94,641
779,24.96,642
780,24.96,643
781,24.96,644
782,24.96,644
783,24.98,645
784,24.98,646
784,24.98,646
785,24.98,647
786,24.98,648
787,24.98,648
788,24.98,649
789,24.96,650
790,24.94,651
790,24.92,651
791,24.91,652
792,24.89,653
793,24.87,653
794,24.83,654
795,24.8,655
796,24.76,656
796,24.76,656
797,24.76,657
798,24.76,658
799,24.78,658
800,24.8,659
801,24.8,660
802,24.78,660
802,24.8,661
803,24.85,662
804,24.87,663
805,24.92,663
806,24.98,664
807,25.05,665
808,25.15,666
809,25.24,666
810,25.29,667
810,25.37,668
811,25.42,668
812,25.48,669
813,25.49,670
814,25.51,671
815,25.49,671
816,25.48,672
816,25.48,673
817,25.46,673
818,25.44,674
819,25.4,675
820,25.35,676
821,25.31,676
822,25.27,677
822,25.26,678
823,25.24,678
824,25.22,679
825,25.2,680
826,25.22,680
827,25.18,681
828,25.2,682
828,25.18,683
829,25.2,683
830,25.18,684
831,25.18,685
832,25.16,685
833,25.18,686
833,25.18,687
834,25.24,687
835,25.26,688
836,25.31,689
837,25.33,690
838,25.35,690
839,25.37,691
839,25.37,692
840,25.38,692
841,25.37,693
842,25.37,694
843,25.33,694
844,25.33,695
845,25.33,696
845,25.38,697
846,25.46,697
847,25.57,698
848,25.66,699
849,25.77,699
850,25.86,700
851,25.97,701
851,26.06,702
852,26.12,702
853,26.17,703
854,26.23,704
855,26.3,704
856,26.38,705
857,26.43,706
857,26.49,706
858,26.56,707
859,26.63,708
860,26.69,709
861,26.72,709
862,26.76,710
863,26.76,711
863,26.78,711
864,26.78,712
865,26.82,713
866,26.85,713
867,26.85,714
868,26.87,715
868,26.87,716
869,26.89,716
870,26.93,717
871,26.96,718
872,27,718
873,27.06,719
874,27.07,720
874,27.09,721
875,27.13,721
876,27.13,722
877,27.13,723
878,27.11,723
879,27.11,724
880,27.11,725
880,27.11,725
881,27.15,726
882,27.18,727
883,27.2,728
884,27.24,728
885,27.26,729
886,27.28,730
886,27.28,730
887,27.29,731
888,27.26,732
889,27.22,732
890,27.18,733
891,27.17,734
892,27.18,735
892,27.18,735
893,27.18,736
894,27.2,737
895,27.24,737
896,27.28,738
897,27.31,739
897,27.37,739
898,27.42,740
899,27.46,741
900,27.53,742
901,27.61,743
902,27.66,743
903,27.72,744
904,27.73,745
905,27.75,746
906,27.77,746
907,27.77,747
907,27.81,748
908,27.83,748
909,27.83,749
910,27.85,750
911,27.85,750
912,27.86,751
913,27.86,752
913,27.88,753
914,27.92,753
915,27.94,754
916,27.97,755
917,28.03,755
918,28.08,756
918,28.16,757
919,28.21,758
920,28.29,758
921,28.34,759
922,28.4,760
923,28.47,760
924,28.51,761
924,28.56,762
925,28.6,762
926,28.65,763
927,28.69,764
928,28.71,765
929,28.73,765
930,28.75,766
930,28.78,767
931,28.8,767
932,28.84,768
933,28.86,769
934,28.87,769
935,28.87,770
936,28.89,771
936,28.91,772
937,28.93,772
938,28.93,773
939,28.95,774
940,28.97,774
941,28.97,775
942,28.98,776
942,29,776
943,29.04,777
944,29.04,778
945,29.08,779
946,29.09,779
947,29.13,780
948,29.17,781
948,29.2,781
949,29.24,782
950,29.26,783
951,29.3,784
952,29.3,784
953,29.31,785
953,29.31,786
954,29.31,786
955,29.31,787
956,29.31,788
957,29.31,788
958,29.31,789
959,29.31,790
959,29.33,791
960,29.35,791
961,29.37,792
962,29.39,793
963,29.42,793
964,29.44,794
965,29.46,795
965,29.48,795
966,29.5,796
967,29.46,797
968,29.46,798
969,29.42,798
970,29.41,799
971,29.39,800
971,29.41,800
972,29.39,801
973,29.39,802
974,29.39,803
975,29.39,803
976,29.39,804
977,29.39,805
977,29.39,805
978,29.42,806
979,29.42,807
980,29.42,807
981,29.39,808
982,29.35,809
982,29.3,810
983,29.2,810
984,29.2,811
985,29.17,812
986,29.2,812
987,29.2,813
988,29.22,814
988,29.28,814
989,29.31,815
990,29.37,816
991,29.44,817
992,29.46,817
993,29.46,818
994,29.48,819
994,29.46,819
995,29.46,820
996,29.52,821
997,29.57,821
998,29.61,822
999,29.65,823
1000,29.74,824
1001,29.79,825
1002,29.85,825
1003,29.88,826
1003,29.94,827
1004,29.98,827
1005,29.99,828
1006,30.03,829
1007,30.03,830
1008,30.07,831
1009,30.1,831
1010,30.12,832
1011,30.16,833
1012,30.2,834
1012,30.23,834
1013,30.29,835
1014,30.32,836
1015,30.34,836
1016,30.38,837
1017,30.42,838
1018,30.45,838
1018,30.47,839
1019,30.51,840
1020,30.55,841
1021,30.58,841
1022,30.6,842
1023,30.62,843
1024,30.62,843
1024,30.64,844
1025,30.62,845
1026,30.6,845
1027,30.58,846
1028,30.58,847
1029,30.6,848
1030,30.64,848
1030,30.67,849
1031,30.71,850
1032,30.77,850
1033,30.82,851
1034,30.86,852
1035,30.91,853
1035,30.99,853
1036,31.06,854
1037,31.13,855
1038,31.19,855
1039,31.22,856
1040,31.26,857
1041,31.28,857
1041,31.32,858
1042,31.32,859
1043,31.33,860
1044,31.32,860
1045,31.32,861
1046,31.28,862
1047,31.26,862
1047,31.24,863
1048,31.22,864
1049,31.19,864
1050,31.17,865
1051,31.15,866
1052,31.17,867
1053,31.21,867
1053,31.26,868
1054,31.32,869
1055,31.37,869
1056,31.41,870
1057,31.46,871
1058,31.52,872
1059,31.57,872
1059,31.65,873
1060,31.7,874
1061,31.74,874
1062,31.78,875
1063,31.79,876
1064,31.83,876
1065,31.89,877
1065,31.92,878
1066,31.96,879
1067,32,879
1068,32.03,880
1069,32.05,881
1070,32.03,881
1070,32.01,882
1071,32,883
1072,31.98,883
1073,31.94,884
1074,31.92,885
1075,31.9,886
1076,31.87,886
1076,31.83,887
1077,31.81,888
1078,31.79,888
1079,31.76,889
1080,31.76,890
1081,31.79,890
1082,31.83,891
1082,31.87,892
1083,31.9,893
1084,31.94,893
1085,31.96,894
1086,32,895
1087,32.01,895
1088,32.03,896
1088,32.05,897
1089,32.05,898
1090,32.03,898
1091,32.03,899
1092,32.01,900
1093,32.03,900
1094,32.03,901
1094,32.05,902
1095,32.03,902
1096,32.05,903
1097,32.07,904
1098,32.11,905
1099,32.14,905
1100,32.2,906
1100,32.25,907
1101,32.35,907
1102,32.42,908
1103,32.49,909
1104,32.62,910
1105,32.68,911
1106,32.75,911
1107,32.82,912
1108,32.91,913
1109,32.97,913
1109,33.02,914
1110,33.12,915
1111,33.17,916
1112,33.21,916
1113,33.21,917
1114,33.21,918
1115,33.21,918
1115,33.25,919
1116,33.26,920
1117,33.3,920
1118,33.34,921
1119,33.36,922
1120,33.41,923
1120,33.43,923
1121,33.47,924
1122,33.48,925
1123,33.48,925
1124,33.5,926
1125,33.56,927
1126,33.58,927
1126,33.61,928
1127,33.65,929
1128,33.67,930
1129,33.7,930
1130,33.7,931
1131,33.69,932
1132,33.69,932
1132,33.69,933
1133,33.7,934
1134,33.72,935
1135,33.74,935
1136,33.76,936
1137,33.8,937
1138,33.85,937
1138,33.94,938
1139,34.02,939
1140,34.09,939
1141,34.15,940
1142,34.2,941
1143,34.26,942
1144,34.31,942
1144,34.38,943
1145,34.4,944
1146,34.46,944
1147,34.49,945
1148,34.51,946
1149,34.53,946
1150,34.53,947
1150,34.51,948
1151,34.51,949
1152,34.48,949
1153,34.46,950
1154,34.42,951
1155,34.4,951
1155,34.42,952
1156,34.42,953
1157,34.4,953
1158,34.37,954
1159,34.33,955
1160,34.27,956
1161,34.27,956
1161,34.26,957
1162,34.27,958
1163,34.29,958
1164,34.31,959
1165,34.35,960
1166,34.38,961
1167,34.38,961
1167,34.42,962
1168,34.44,963
1169,34.44,963
1170,34.46,964
1171,34.44,965
1172,34.4,965
1173,34.38,966
1173,34.35,967
1174,34.33,968
1175,34.33,968
1176,34.33,969
1177,34.33,970
1178,34.35,970
1179,34.37,971
1179,34.37,972
1180,34.38,972
1181,34.38,973
1182,34.42,974
1183,34.44,975
1184,34.46,975
1184,34.46,976
1185,34.48,977
1186,34.46,977
1187,34.44,978
1188,34.42,979
1189,34.42,980
1190,34.4,980
1190,34.4,981
1191,34.4,982
1192,34.4,982
1193,34.38,983
1194,34.37,984
1195,34.38,984
1196,34.4,985
1196,34.44,986
1197,34.49,987
1198,34.53,987
1199,34.59,988
1200,34.66,989
1201,34.73,989
1202,34.82,990
1202,34.92,991
1203,34.97,991
1205,35.12,993
1206,35.17,993
1207,35.21,994
1207,35.25,995
1208,35.27,996
1209,35.32,996
1210,35.34,997
1211,35.38,998
1212,35.41,998
1213,35.39,999
1213,35.41,1000
1214,35.43,1001
1215,35.43,1001
1216,35.45,1002
1217,35.47,1003
1218,35.47,1003
1219,35.49,1004
1219,35.49,1005
1220,35.5,1005
1221,35.49,1006
1222,35.49,1007
1223,35.5,1008
1224,35.49,1008
1225,35.49,1009
1225,35.45,1010
1226,35.41,1010
1227,35.34,1011
1228,35.21,1012
1229,35.03,1012
1230,9.551,1013
1230,0.12857,1014
1231,0.12857,1015
1232,0.14694,1015
1233,0.12857,1016
1234,0.14694,1017
1235,0.14694,1017
1235,0.14694,1018