File: in-progress/Koerner_2005_Polymer/RawDataFromAuthors/cnttobreak/cnt5cpu.csv
Strain (%),Stress (MPa),Time (sec)
0.0387,0.5435,
1.128,1.1987,1
2.22,1.772,2
3.31,2.256,3
4.4,2.658,4
5.49,3.001,5
6.58,3.291,6
7.67,3.537,7
8.76,3.753,8
9.85,3.939,9
10.93,4.08,10
12.03,4.214,11
13.11,4.326,12
14.2,4.423,13
15.29,4.497,14
16.38,4.564,15
17.47,4.624,16
18.56,4.676,17
19.65,4.72,18
20.7,4.765,19
21.8,4.795,20
22.9,4.832,21
24,4.862,22
25.1,4.884,23
26.2,4.899,24
27.3,4.921,25
28.4,4.936,26
29.4,4.951,27
30.5,4.966,28
31.6,4.974,29
32.7,4.988,30
33.8,4.996,31
34.9,5.011,32
36,5.018,32
37.1,5.026,33
38.2,5.041,34
39.2,5.048,35
40.3,5.07,36
41.4,5.078,37
42.5,5.078,38
43.6,5.085,39
44.7,5.1,40
45.8,5.115,41
46.9,5.122,42
48,5.137,43
49,5.145,44
50.1,5.152,45
51.2,5.16,46
52.3,5.175,47
53.4,5.189,48
54.5,5.197,49
55.6,5.212,50
56.7,5.219,51
57.8,5.234,52
58.8,5.249,53
59.9,5.256,54
61,5.271,55
62.1,5.286,56
63.2,5.301,57
64.3,5.316,58
65.4,5.324,59
66.5,5.331,60
67.6,5.346,61
68.7,5.361,62
69.7,5.368,63
70.8,5.383,64
71.9,5.391,65
73,5.405,66
74.1,5.42,67
75.2,5.435,68
76.3,5.443,69
77.4,5.458,70
78.5,5.465,71
79.5,5.487,72
80.6,5.502,73
81.7,5.517,74
82.8,5.532,75
83.9,5.547,76
85,5.562,77
86.1,5.577,78
87.2,5.592,79
88.3,5.599,80
89.3,5.614,81
90.4,5.621,82
91.5,5.636,83
92.6,5.651,84
93.7,5.673,85
94.8,5.681,86
95.9,5.696,87
97,5.711,88
98.1,5.718,89
99.1,5.733,90
100.2,5.74,91
101.3,5.755,92
102.4,5.763,93
103.5,5.785,94
104.6,5.793,95
105.7,5.807,95
106.8,5.815,96
107.9,5.837,97
108.9,5.86,98
110,5.874,99
111.1,5.889,100
112.2,5.904,101
113.3,5.912,102
114.4,5.927,103
115.5,5.941,104
116.6,5.964,105
117.6,5.979,106
118.7,5.994,107
119.8,6.016,108
120.9,6.023,109
122,6.038,110
123.1,6.046,111
124.2,6.061,112
125.3,6.068,113
126.4,6.09,114
127.5,6.098,115
128.5,6.12,116
129.6,6.135,117
130.7,6.157,118
131.8,6.172,119
132.9,6.187,120
134,6.21,121
135.1,6.224,122
136.2,6.239,123
137.3,6.254,124
138.3,6.269,125
139.4,6.284,126
140.5,6.299,127
141.6,6.314,128
142.7,6.321,129
143.8,6.336,130
144.9,6.344,131
146,6.351,132
147.1,6.366,133
148.1,6.381,134
149.2,6.396,135
150.3,6.411,136
151.4,6.433,137
152.5,6.448,138
153.6,6.463,139
154.7,6.485,140
155.8,6.5,141
156.9,6.515,142
157.9,6.53,143
159,6.552,144
160.1,6.567,145
161.2,6.574,146
162.3,6.597,147
163.4,6.612,148
164.5,6.619,149
165.6,6.634,150
166.6,6.649,151
167.7,6.664,152
168.8,6.686,153
169.9,6.693,154
171,6.716,155
172.1,6.738,156
173.2,6.753,157
174.3,6.775,158
175.4,6.79,158
176.4,6.805,159
177.5,6.82,160
178.6,6.842,161
179.7,6.865,162
180.8,6.887,163
181.9,6.902,164
183,6.924,165
184.1,6.939,166
185.2,6.962,167
186.2,6.984,168
187.3,6.999,169
188.4,7.021,170
189.5,7.036,171
190.6,7.058,172
191.7,7.081,173
192.8,7.096,174
193.9,7.11,175
195,7.125,176
196,7.14,177
197.1,7.155,178
198.2,7.17,179
199.3,7.185,180
200,7.207,181
201,7.222,182
203,7.244,183
204,7.259,184
205,7.282,185
206,7.297,186
207,7.319,187
208,7.341,188
209,7.356,189
210,7.378,190
211,7.386,191
212,7.401,192
213,7.416,193
215,7.423,194
216,7.438,195
217,7.453,196
218,7.468,197
219,7.475,198
220,7.483,199
221,7.498,200
222,7.505,201
223,7.52,202
225,7.527,203
226,7.542,204
227,7.557,205
228,7.572,206
229,7.579,207
230,7.594,208
231,7.609,209
232,7.624,210
233,7.639,211
234,7.661,212
235,7.676,213
236,7.706,214
238,7.721,215
239,7.743,216
240,7.773,217
241,7.795,218
242,7.81,219
243,7.833,220
244,7.848,221
245,7.87,222
246,7.892,223
247,7.915,224
248,7.929,225
250,7.952,226
251,7.967,227
252,7.982,228
253,7.996,229
254,8.019,229
255,8.034,230
256,8.056,231
257,8.071,232
258,8.086,233
259,8.101,234
260,8.123,235
262,8.145,236
263,8.168,237
264,8.183,238
265,8.197,239
266,8.22,240
267,8.235,241
268,8.25,242
269,8.264,243
270,8.279,244
271,8.294,245
272,8.309,246
274,8.331,247
275,8.346,248
276,8.361,249
277,8.384,250
278,8.406,251
279,8.421,252
280,8.443,253
281,8.465,254
282,8.488,255
283,8.503,256
284,8.518,257
285,8.532,258
287,8.547,259
288,8.555,260
289,8.577,261
290,8.592,262
291,8.607,263
292,8.622,264
293,8.652,265
294,8.667,266
295,8.681,267
296,8.704,268
297,8.719,269
299,8.726,270
300,8.741,271
301,8.756,272
302,8.771,273
303,8.786,274
304,8.808,275
305,8.823,276
306,8.838,277
307,8.853,278
308,8.875,279
309,8.897,280
311,8.912,281
312,8.927,282
313,8.942,283
314,8.964,284
315,8.987,285
316,9.002,286
317,9.016,287
318,9.031,288
319,9.054,289
320,9.069,290
321,9.091,291
322,9.113,292
324,9.143,292
325,9.158,293
326,9.173,294
327,9.195,295
328,9.217,296
329,9.24,297
330,9.255,298
331,9.277,299
332,9.292,300
333,9.307,301
334,9.322,302
336,9.337,303
337,9.344,304
338,9.359,305
339,9.374,306
340,9.381,307
341,9.396,308
342,9.411,309
343,9.419,310
344,9.433,311
345,9.441,312
346,9.448,313
348,9.448,314
349,9.456,315
350,9.456,316
351,9.463,317
352,9.463,318
353,9.471,319
354,9.478,320
355,9.486,321
356,9.508,322
357,9.523,323
358,9.538,324
360,9.553,325
361,9.575,326
362,9.59,327
363,9.612,328
364,9.627,329
365,9.642,330
366,9.664,331
367,9.687,332
368,9.709,333
369,9.739,334
370,9.761,335
371,9.783,336
373,9.813,337
374,9.835,338
375,9.865,339
376,9.888,340
377,9.917,341
378,9.94,342
379,9.962,343
380,9.984,344
381,10.007,345
383,10.036,346
384,10.059,347
385,10.081,348
386,10.096,349
387,10.118,350
388,10.133,351
389,10.156,352
390,10.171,353
391,10.185,354
392,10.208,355
393,10.223,356
395,10.238,357
396,10.245,358
397,10.26,359
398,10.275,360
399,10.29,361
400,10.305,362
401,10.312,363
402,10.327,364
403,10.334,365
404,10.342,366
405,10.357,366
407,10.379,367
408,10.394,368
409,10.409,369
410,10.424,370
411,10.446,371
412,10.461,372
413,10.491,373
414,10.506,374
415,10.528,375
416,10.55,376
417,10.58,377
419,10.602,378
420,10.617,379
421,10.632,380
422,10.654,381
423,10.669,382
424,10.692,383
425,10.714,384
426,10.744,385
427,10.766,386
428,10.788,387
429,10.811,388
430,10.841,389
432,10.863,390
433,10.893,391
434,10.908,392
435,10.922,393
436,10.945,394
437,10.96,395
438,10.982,396
439,10.997,397
440,11.019,398
441,11.034,399
442,11.049,400
444,11.064,401
445,11.079,402
446,11.094,403
447,11.109,404
448,11.124,405
449,11.138,406
450,11.153,407
451,11.168,408
452,11.191,409
453,11.198,410
454,11.205,411
456,11.205,412
457,11.213,413
458,11.213,414
459,11.213,415
460,11.22,416
461,11.228,417
462,11.228,418
463,11.228,419
464,11.235,420
465,11.228,421
466,11.228,422
468,11.228,423
469,11.235,424
470,11.25,425
471,11.272,426
472,11.287,427
473,11.317,428
474,11.347,429
475,11.377,429
476,11.406,430
477,11.436,431
478,11.473,432
479,11.503,433
481,11.533,434
482,11.57,435
483,11.593,436
484,11.622,437
485,11.652,438
486,11.682,439
487,11.704,440
488,11.727,441
489,11.749,442
490,11.771,443
491,11.786,444
493,11.801,445
494,11.831,446
495,11.846,447
496,11.868,448
497,11.883,449
498,11.898,450
499,11.913,451
500,11.92,452
501,11.92,453
502,11.928,454
503,11.935,455
505,11.943,456
506,11.95,457
507,11.965,458
508,11.972,459
509,11.98,460
510,11.987,461
511,11.995,462
512,12.01,463
513,12.017,464
514,12.032,465
515,12.062,466
517,12.084,467
518,12.106,468
519,12.129,469
520,12.151,470
521,12.181,471
522,12.211,472
523,12.24,473
524,12.263,474
525,12.292,475
526,12.322,476
527,12.345,477
528,12.359,478
530,12.382,479
531,12.404,480
532,12.419,481
533,12.441,482
534,12.456,483
535,12.479,484
536,12.493,485
538,12.516,486
539,12.523,487
540,12.531,488
541,12.538,489
542,12.546,490
543,12.56,491
544,12.583,492
545,12.605,493
546,12.635,494
547,12.665,495
548,12.695,496
550,12.724,497
551,12.747,498
552,12.784,499
553,12.814,500
554,12.829,501
555,12.851,502
556,12.873,503
557,12.903,504
558,12.918,505
559,12.94,506
560,12.955,507
561,12.97,508
563,12.985,509
564,12.992,510
565,13.007,511
566,13.007,511
567,13.007,512
568,13.015,513
569,13.022,514
570,13.03,515
571,13.052,516
572,13.067,517
573,13.082,518
575,13.089,519
576,13.097,520
577,13.104,521
578,13.119,522
579,13.134,523
580,13.141,524
581,13.149,525
582,13.156,526
583,13.156,527
584,13.164,528
585,13.171,529
587,13.186,530
588,13.193,531
589,13.208,532
590,13.223,533
591,13.238,534
592,13.253,535
593,13.268,536
594,13.29,537
595,13.305,538
596,13.335,539
597,13.357,540
599,13.379,541
600,13.424,542
601,13.447,543
602,13.476,544
603,13.499,545
604,13.528,546
605,13.558,547
606,13.595,548
607,13.633,549
608,13.67,550
609,13.692,551
610,13.722,552
612,13.752,553
613,13.782,554
614,13.811,555
615,13.841,556
616,13.863,557
617,13.886,558
618,13.916,559
619,13.938,560
620,13.953,561
621,13.96,562
622,13.968,563
624,13.96,564
625,13.953,565
626,13.953,566
627,13.945,567
628,13.938,568
629,13.93,569
630,13.938,570
631,13.938,571
632,13.945,572
633,13.945,573
634,13.96,574
636,13.975,574
637,13.997,575
638,14.027,576
639,14.057,577
640,14.094,578
641,14.131,579
642,14.169,580
643,14.213,581
644,14.251,582
645,14.28,583
646,14.31,584
648,14.355,585
649,14.385,586
650,14.414,587
651,14.437,588
652,14.467,589
653,14.496,590
654,14.526,591
655,14.541,592
656,14.563,593
657,14.578,594
658,14.608,595
659,14.645,596
661,14.668,597
662,14.705,598
663,14.742,599
664,14.787,600
665,14.816,601
666,14.846,602
667,14.891,603
668,14.928,604
669,14.95,605
670,14.973,606
671,14.988,607
673,14.995,608
674,15.003,609
675,15.01,610
676,15.025,611
677,15.047,612
678,15.055,613
679,15.07,614
680,15.085,615
682,15.092,616
683,15.092,617
684,15.099,618
685,15.107,619
686,15.107,620
687,15.107,621
688,15.107,622
689,15.107,623
690,15.107,624
691,15.107,625
692,15.107,626
694,15.114,627
695,15.129,628
696,15.159,629
697,15.181,630
698,15.204,631
699,15.233,632
700,15.256,633
701,15.278,634
702,15.3,635
703,15.33,636
704,15.353,637
706,15.382,638
707,15.397,639
708,15.427,640
709,15.449,641
710,15.457,642
711,15.479,643
712,15.494,644
713,15.516,645
714,15.531,646
715,15.561,647
716,15.583,648
717,15.613,649
719,15.65,650
720,15.695,651
721,15.732,652
722,15.769,653
723,15.814,653
724,15.859,654
725,15.896,655
726,15.933,656
727,15.971,657
728,16.008,658
729,16.038,659
731,16.075,660
732,16.097,661
733,16.127,662
734,16.142,663
735,16.172,664
736,16.194,665
737,16.224,666
738,16.261,667
739,16.283,668
740,16.32,669
741,16.343,670
743,16.373,671
744,16.395,672
745,16.417,673
746,16.44,674
747,16.454,675
748,16.462,676
749,16.469,677
750,16.469,678
751,16.469,679
752,16.469,680
753,16.469,681
755,16.477,682
756,16.477,683
757,16.492,684
758,16.514,685
759,16.544,686
760,16.574,687
761,16.596,688
762,16.626,689
763,16.648,690
764,16.685,691
765,16.7,692
766,16.715,693
768,16.715,694
769,16.708,695
770,16.7,696
771,16.7,697
772,16.708,698
773,16.73,699
774,16.752,700
775,16.775,701
776,16.797,702
777,16.819,703
778,16.842,704
780,16.871,705
781,16.879,706
782,16.909,707
783,16.931,708
784,16.961,709
785,16.998,710
786,17.028,711
787,17.058,712
788,17.087,713
789,17.117,714
790,17.139,715
792,17.169,716
793,17.199,716
794,17.229,717
795,17.251,718
796,17.281,719
797,17.296,720
798,17.311,721
799,17.333,722
800,17.355,723
801,17.378,724
802,17.393,725
804,17.407,726
805,17.43,727
806,17.46,728
807,17.474,729
808,17.497,730
809,17.527,732
810,17.556,733
811,17.579,734
813,17.609,735
814,17.638,736
815,17.676,737
816,17.705,737
817,17.728,738
818,17.757,739
819,17.787,740
820,17.817,741
821,17.839,742
822,17.869,743
823,17.891,744
825,17.914,745
826,17.944,746
827,17.966,747
828,17.988,748
829,18.003,749
830,18.011,750
831,18.018,751
832,18.011,752
833,18.003,753
834,17.996,754
835,17.973,755
837,17.951,756
838,17.929,757
839,17.906,758
840,17.884,759
841,17.877,760
842,17.854,761
843,17.847,762
844,17.847,763
845,17.869,764
846,17.891,765
847,17.914,766
849,17.936,767
850,17.958,768
851,17.981,769
852,18.003,770
853,18.033,771
854,18.07,772
855,18.115,773
856,18.152,774
857,18.197,775
858,18.226,776
859,18.256,777
860,18.286,778
862,18.301,779
863,18.316,780
864,18.338,781
865,18.353,782
866,18.368,783
867,18.383,784
868,18.398,785
869,18.42,786
870,18.442,787
871,18.48,788
872,18.509,789
874,18.547,790
875,18.584,791
876,18.614,792
877,18.636,793
878,18.658,794
879,18.688,795
880,18.718,796
881,18.748,797
882,18.785,798
883,18.83,799
884,18.859,800
886,18.882,800
887,18.904,801
888,18.919,802
889,18.941,803
890,18.956,804
891,18.964,805
892,18.964,806
893,18.971,807
894,18.978,808
895,19.001,809
896,19.016,810
898,19.016,811
899,19.001,812
900,18.986,813
901,18.971,814
902,18.956,815
903,18.941,816
904,18.941,817
905,18.956,818
906,18.993,819
907,19.045,820
908,19.105,821
909,19.194,822
911,19.261,823
912,19.336,824
913,19.418,825
914,19.492,826
915,19.567,827
916,19.634,828
917,19.701,829
918,19.76,830
919,19.812,831
920,19.857,832
921,19.894,833
923,19.931,834
924,19.969,835
925,19.991,836
926,20.01,837
927,20.03,838
928,20.04,839
930,20.05,840
931,20.07,841
932,20.07,842
933,20.06,843
934,20.04,844
935,20.03,845
936,20.03,846
937,20.02,847
938,20.02,848
939,20.02,849
940,20.03,850
942,20.03,851
943,20.04,852
944,20.05,853
945,20.07,854
946,20.1,855
947,20.13,856
948,20.16,857
949,20.2,858
950,20.22,859
951,20.24,860
952,20.27,861
953,20.3,862
955,20.33,863
956,20.35,864
957,20.37,865
958,20.39,866
959,20.43,867
960,20.47,868
961,20.5,869
962,20.53,870
963,20.56,871
964,20.59,872
965,20.6,873
967,20.62,874
968,20.65,875
969,20.66,876
970,20.68,877
971,20.68,878
972,20.7,879
973,20.72,880
974,20.74,881
975,20.76,882
976,20.78,883
977,20.79,884
979,20.8,885
980,20.81,886
981,20.82,887
982,20.82,888
983,20.84,889
984,20.85,889
985,20.85,890
986,20.86,891
987,20.87,892
988,20.88,893
989,20.89,894
991,20.91,895
992,20.91,896
993,20.94,897
994,20.95,898
995,20.96,899
996,20.97,900
997,20.97,901
998,20.96,902
1000,20.94,904
1001,20.91,905
1002,20.85,906
1003,0.15635,907
1004,0.15635,908
1005,0.15635,909
1006,0.15635,910
1007,0.15635,911
1008,0.15635,912
1010,0.15635,913
1011,0.15635,914
1012,0.15635,915
1013,0.15635,916
1014,0.15635,917
1015,0.15635,917
1016,0.15635,918
1017,0.14891,919
1018,0.14891,920
1019,0.14891,921
1020,0.15635,922
1021,0.15635,923
1023,0.15635,924
1024,0.15635,925
1025,0.15635,926
1026,0.15635,927
1027,0.15635,928
1028,0.15635,929
1029,0.15635,930
1030,0.15635,931
1031,0.15635,932
1032,0.15635,933
1033,0.15635,934
1035,0.15635,935
1036,0.15635,936
1037,0.15635,937
1038,0.15635,938
1039,0.15635,939
1040,0.15635,940
1041,0.15635,941
1042,0.15635,942
1043,0.1638,943
1044,0.15635,944
1045,0.1638,945
1047,0.1638,946
1048,0.1638,947
1049,0.15635,948
1050,0.15635,949
1051,0.1638,950
1052,0.1638,951
1053,0.1638,952
1054,0.1638,953
1055,0.1638,954
1056,0.15635,955
1057,0.15635,956
1059,0.15635,957
1060,0.15635,958
1061,0.15635,959
1062,0.15635,960
1063,0.15635,961
1064,0.1638,962
1065,0.15635,963
1066,0.15635,964
1067,0.1638,965
1068,0.1638,966
1069,0.1638,967
1070,0.1638,968
1072,0.1638,969
1073,0.1638,970
1074,0.15635,971
1075,0.15635,972
1076,0.15635,973
1077,0.1638,974
1078,0.1638,975
1079,0.15635,976
1080,0.15635,977
1081,0.1638,978
1082,0.1638,979
1084,0.1638,980
1085,0.15635,980
1086,0.15635,981
1087,0.15635,982
1088,0.1638,983
1089,0.15635,984
1090,0.15635,985
1091,0.1638,986
1092,0.1638,987
1093,0.15635,988
1094,0.1638,989
1096,0.1638,990
1097,0.17125,991
1098,0.1638,992
1099,0.1638,993
1100,0.1638,994
1101,0.15635,995
1102,0.15635,996
1103,0.1638,997
1104,0.17125,998
1105,0.15635,999
1106,0.15635,1000
1108,0.15635,1001
1109,0.15635,1002
1110,0.15635,1003
1111,0.15635,1004
1112,0.1638,1005
1113,0.1638,1006
1114,0.1638,1007
1115,0.15635,1008
1116,0.15635,1009
1117,0.1638,1010
1118,0.1638,1011
1119,0.15635,1012
1121,0.1638,1013
1122,0.1638,1014
1123,0.15635,1015
1124,0.15635,1016
1125,0.15635,1017
1126,0.15635,1018
1127,0.15635,1019
1128,0.1638,1020
1129,0.1638,1021
1130,0.1638,1022
1131,0.1638,1023
1133,0.15635,1024
1134,0.1638,1025
1135,0.1638,1026
1136,0.1638,1027
1137,0.1638,1028
1138,0.1638,1029
1139,0.15635,1030
1140,0.1638,1031
1141,0.1638,1032
1142,0.15635,1033
1143,0.1638,1034
1145,0.1638,1035
1146,0.15635,1036
1147,0.15635,1037
1148,0.1638,1038
1149,0.15635,1039
1150,0.14891,1040
1151,0.15635,1041
1152,0.15635,1042
1153,0.1638,1043
1154,0.1638,1043
1155,0.1638,1044
1157,0.15635,1045
1158,0.15635,1046
1159,0.15635,1047
1160,0.15635,1048
1161,0.1638,1049
1162,0.15635,1050
1163,0.15635,1051
1164,0.15635,1052
1165,0.15635,1053
1166,0.15635,1054
1167,0.15635,1055
1168,0.15635,1056
1170,0.15635,1057
1171,0.1638,1058
1172,0.1638,1059
1173,0.1638,1060
1174,0.15635,1061
1175,0.1638,1062
1176,0.15635,1063
1177,0.15635,1064
1178,0.15635,1065
1179,0.15635,1066
1180,0.15635,1067
1182,0.15635,1068
1183,0.15635,1069
1184,0.15635,1070
1185,0.15635,1071
1186,0.15635,1072
1187,0.15635,1073
1188,0.15635,1074
1189,0.15635,1075
1190,0.15635,1076
1191,0.15635,1077
1192,0.15635,1078
1194,0.1638,1079
1195,0.15635,1080
1196,0.15635,1081
1197,0.1638,1082
1198,0.15635,1083
1199,0.1638,1084
1200,0.15635,1085
1201,0.1638,1086
1202,0.1638,1087
1203,0.1638,1088
1204,0.15635,1089
1206,0.1638,1090
1207,0.1638,1091
1208,0.1638,1092
1209,0.1638,1093
1210,0.1638,1094
1211,0.15635,1095
1212,0.15635,1096
1213,0.15635,1097
1214,0.1638,1098
1215,0.1638,1099
1216,0.1638,1100
1217,0.1638,1101
1219,0.1638,1102
1220,0.1638,1103
1221,0.1638,1104
1222,0.1638,1105
1223,0.1638,1106
1224,0.15635,1106
1225,0.15635,1107
1226,0.1638,1108
1227,0.1638,1109
1228,0.1638,1110
1229,0.17125,1111
1231,0.1638,1112
1232,0.1638,1113
1233,0.1638,1114
1234,0.17125,1115
1235,0.1638,1116
1236,0.17125,1117
1237,0.17125,1118
1238,0.1638,1119
1239,0.1638,1120
1240,0.1638,1121
1241,0.1638,1122
1243,0.1638,1123
1244,0.17125,1124
1245,0.17125,1125
1246,0.1638,1126
1247,0.17125,1127
1248,0.17125,1128
1249,0.17125,1129
1250,0.17125,1130
1251,0.1638,1131
1252,0.1638,1132
1253,0.1638,1133
1255,0.1638,1134
1256,0.1638,1135
1257,0.1638,1136
1258,0.1638,1137
1259,0.1638,1138
1260,0.17125,1139
1261,0.1638,1140
1262,0.1638,1141
1263,0.17125,1142
1264,0.17125,1143
1265,0.17125,1144
1266,0.1638,1145
1268,0.1638,1146
1269,0.17125,1147
1270,0.17125,1148
1271,0.1638,1149
1272,0.17125,1150
1273,0.17125,1151
1274,0.17125,1152
1275,0.1638,1153
1276,0.1638,1154
1277,0.1638,1155
1278,0.12657,1156
1280,0.13402,1157
1281,0.13402,1158
1282,0.13402,1159
1283,0.12657,1160
1284,0.12657,1161
1285,0.13402,1162
1286,0.13402,1163
1287,0.13402,1164
1288,0.13402,1165
1289,0.13402,1166
1290,0.13402,1167
1292,0.14146,1168
1293,0.14146,1169
1294,0.14146,1169
1295,0.14146,1170
1296,0.14146,1171
1297,0.13402,1172
1298,0.13402,1173
1299,0.13402,1174
1300,0.13402,1175
1301,0.13402,1176
1302,0.13402,1177
1304,0.13402,1178
1305,0.13402,1179
1306,0.13402,1180
1307,0.13402,1181
1308,0.13402,1182
1309,0.13402,1183
1310,0.13402,1184
1311,0.13402,1185
1312,0.13402,1186
1313,0.13402,1187
1314,0.13402,1188
1315,0.13402,1189
1317,0.13402,1190
1318,0.13402,1191
1319,0.13402,1192
1320,0.13402,1193
1321,0.13402,1194
1322,0.13402,1195
1323,0.13402,1196
1324,0.13402,1197
1325,0.13402,1198
1326,0.13402,1199
1327,0.13402,1200
1329,0.13402,1201
1330,0.13402,1202
1331,0.13402,1203
1332,0.13402,1204
1333,0.13402,1205
1334,0.13402,1206
1335,0.14146,1207
1336,0.13402,1208
1337,0.13402,1209
1338,0.13402,1210
1339,0.13402,1211
1341,0.13402,1212
1342,0.13402,1213
1343,0.13402,1214
1344,0.13402,1215
1345,0.13402,1216
1346,0.13402,1217
1347,0.13402,1218
1348,0.14146,1219
1349,0.13402,1220
1350,0.14146,1221
1351,0.13402,1222
1353,0.13402,1223
1354,0.13402,1224
1355,0.13402,1225
1356,0.13402,1226
1357,0.13402,1227
1358,0.13402,1228
1359,0.13402,1229
1360,0.13402,1230
1361,0.13402,1231
1362,0.13402,1232
1363,0.13402,1232
1364,0.13402,1233
1366,0.13402,1234
1367,0.13402,1235
1368,0.13402,1236
1369,0.13402,1237
1370,0.13402,1238
1371,0.13402,1239
1372,0.13402,1240
1373,0.13402,1241
1374,0.13402,1242
1375,0.13402,1243
1376,0.13402,1244
1378,0.13402,1245
1379,0.13402,1246
1380,0.13402,1247
1381,0.13402,1248
1382,0.13402,1249
1383,0.13402,1250
1384,0.13402,1251
1385,0.13402,1252
1386,0.13402,1253
1387,0.14146,1254
1388,0.14146,1255
1390,0.13402,1256
1391,0.13402,1257
1392,0.13402,1258
1393,0.13402,1259
1394,0.13402,1260
1395,0.14146,1261
1396,0.14146,1262
1397,0.14146,1263
1398,0.13402,1264
1399,0.13402,1265
1400,0.13402,1266
1402,0.14146,1267
1403,0.13402,1268
1404,0.13402,1269
1405,0.13402,1270
1406,0.13402,1271
1407,0.12657,1272
1408,0.13402,1273
1409,0.13402,1274
1410,0.13402,1275
1411,0.13402,1276
1412,0.13402,1277
1413,0.14146,1278
1415,0.14146,1279
1416,0.14146,1280
1417,0.13402,1281
1418,0.13402,1282
1419,0.14146,1283
1420,0.13402,1284
1421,0.13402,1285
1422,0.13402,1286
1423,0.14146,1287
1424,0.13402,1288
1425,0.13402,1289
1427,0.13402,1290
1428,0.13402,1291
1429,0.13402,1292
1430,0.13402,1293
1431,0.13402,1294
1432,0.13402,1295
1433,0.14146,1295
1434,0.13402,1296
1435,0.14146,1297
1436,0.14146,1298
1437,0.14146,1299
1439,0.14146,1300
1440,0.14146,1301
1441,0.14146,1302
1442,0.14146,1303
1443,0.14146,1304
1444,0.14146,1305
1445,0.14146,1306
1446,0.14146,1307
1447,0.14146,1308
1448,0.14146,1309
1449,0.14146,1310
1451,0.14146,1311
1452,0.14146,1312
1453,0.14891,1313
1454,0.14146,1314
1455,0.14891,1315
1456,0.14146,1316
1457,0.14891,1317
1458,0.14146,1318
1459,0.14146,1319
1460,0.14891,1320
1461,0.14891,1321
1462,0.14891,1322
1464,0.14891,1323
1465,0.14891,1324
1466,0.14891,1325
1467,0.14146,1326
1468,0.14891,1327
1469,0.14891,1328
1470,0.14891,1329
1471,0.15635,1330
1472,0.14891,1331
1473,0.14891,1332
1474,0.14891,1333
1476,0.14891,1334
1477,0.14891,1335
1478,0.14891,1336
1479,0.14891,1337
1480,0.15635,1338
1481,0.15635,1339
1482,0.15635,1340
1483,0.15635,1341
1484,0.14891,1342
1485,0.14891,1343
1486,0.14891,1344
1488,0.15635,1345
1489,0.15635,1346
1490,0.14891,1347
1491,0.14891,1348
1492,0.15635,1349
1493,0.15635,1350
1494,0.15635,1351
1495,0.14891,1352
1496,0.14891,1353
1497,0.15635,1354
1499,0.14891,1355
1500,0.15635,1356
1501,0.15635,1357
1502,0.15635,1358
1503,0.15635,1359
1504,0.15635,1360
1506,0.15635,1361
1507,0.15635,1362
1508,0.15635,1363
1509,0.14891,1364
1510,0.15635,1365
1511,0.15635,1366
1512,0.15635,1367
1513,0.15635,1368
1514,0.14891,1369
1515,0.15635,1370
1516,0.15635,1371
1518,0.15635,1372
1519,0.15635,1373
1520,0.15635,1374
1521,0.15635,1375
1522,0.1638,1376
1523,0.1638,1377
1524,0.15635,1378
1525,0.15635,1379
1526,0.15635,1380
1527,0.15635,1381
1528,0.15635,1382
1529,0.15635,1383
1531,0.1638,1384
1532,0.15635,1385
1533,0.1638,1386
1534,0.15635,1387
1535,0.15635,1388
1536,0.15635,1389
1537,0.15635,1390
1538,0.15635,1391
1539,0.15635,1392
1540,0.1638,1392
1541,0.1638,1393
1543,0.1638,1394
1544,0.1638,1395
1545,0.15635,1396
1546,0.15635,1397
1547,0.1638,1398
1548,0.1638,1399
1549,0.1638,1400
1550,0.1638,1401
1551,0.1638,1402
1552,0.1638,1403
1553,0.17125,1404
1555,0.1638,1405
1556,0.1638,1406
1557,0.1638,1407
1558,0.1638,1408
1559,0.1638,1409
1560,0.1638,1410
1561,0.1638,1411
1562,0.1638,1412
1563,0.1638,1413
1564,0.17125,1414
1565,0.1638,1415
1567,0.1638,1416
1568,0.1638,1417
1569,0.1638,1418
1570,0.1638,1419
1571,0.17125,1420
1572,0.17125,1421
1573,0.17125,1422
1574,0.17125,1423
1575,0.17125,1424
1576,0.1638,1425
1577,0.17125,1426
1579,0.17125,1427
1580,0.17869,1428
1581,0.17869,1429
1582,0.1638,1430
1583,0.17125,1431
1584,0.1638,1432
1585,0.1638,1433
1586,0.1638,1434
1587,0.17125,1435
1588,0.17125,1436
1589,0.1638,1437
1590,0.17125,1438
1592,0.17125,1439
1593,0.17125,1440
1594,0.17125,1441
1595,0.1638,1442
1596,0.17125,1443
1597,0.17125,1444
1598,0.17125,1445
1599,0.17125,1446
1600,0.17125,1447
1601,0.17125,1448
1602,0.17125,1449
1604,0.17125,1450
1605,0.17125,1451
1606,0.17125,1452
1607,0.17125,1453
1608,0.17125,1454
1609,0.17125,1455
1610,0.17125,1455
1611,0.17869,1456
1612,0.17869,1457
1613,0.17125,1458
1614,0.17125,1459
1616,0.17125,1460
1617,0.17125,1461
1618,0.17869,1462
1619,0.17869,1463
1620,0.17125,1464
1621,0.17869,1465
1622,0.17869,1466
1623,0.17125,1467
1624,0.17125,1468