File: in-progress/Koerner_2005_Polymer/RawDataFromAuthors/cnttobreak/cnt5bpu.csv
Strain (%),Stress (MPa),Time (sec)
0.0476,0.522,
1.058,0.9581,1
2.05,1.3299,2
3.06,1.6588,3
4.05,1.9591,3
5.07,2.224,4
6.06,2.445,5
7.07,2.653,6
8.07,2.831,7
9.08,2.974,8
10.08,3.11,8
11.08,3.239,9
12.08,3.346,10
13.09,3.446,11
14.09,3.532,12
15.1,3.611,13
16.11,3.697,14
17.1,3.761,14
18.1,3.825,15
19.11,3.882,16
20.1,3.94,17
21.1,3.983,18
22.1,4.025,19
23.1,4.068,19
24.1,4.104,20
25.1,4.14,21
26.1,4.176,22
27.1,4.204,23
28.1,4.233,24
29.1,4.261,24
30.1,4.29,25
31.1,4.319,26
32.2,4.347,27
33.2,4.369,28
34.2,4.39,29
35.2,4.404,30
36.2,4.426,30
37.2,4.447,31
38.2,4.469,32
39.2,4.483,33
40.2,4.505,34
41.2,4.519,35
42.2,4.54,35
43.2,4.562,36
44.2,4.576,37
45.2,4.59,38
46.2,4.605,39
47.2,4.619,40
48.2,4.633,41
49.2,4.648,41
50.2,4.662,42
51.2,4.669,43
52.2,4.683,44
53.2,4.698,45
54.2,4.712,46
55.2,4.719,46
56.2,4.733,47
57.2,4.74,48
58.2,4.755,49
59.2,4.762,50
60.2,4.769,51
61.2,4.783,51
62.2,4.798,52
63.3,4.805,53
64.3,4.812,54
65.3,4.826,55
66.3,4.833,56
67.3,4.848,57
68.3,4.855,57
69.3,4.869,58
70.3,4.876,59
71.3,4.883,60
72.3,4.891,61
73.3,4.905,62
74.3,4.912,62
75.3,4.919,63
76.3,4.926,64
77.3,4.934,65
78.3,4.941,66
79.3,4.948,67
80.3,4.962,68
81.3,4.969,68
82.3,4.976,69
83.3,4.991,70
84.3,4.991,71
85.3,5.005,72
86.3,5.012,73
87.3,5.026,73
88.3,5.034,74
89.3,5.048,75
90.3,5.055,76
91.3,5.062,77
92.3,5.069,78
93.4,5.077,78
94.3,5.091,79
95.4,5.098,80
96.4,5.105,81
97.4,5.119,82
98.4,5.127,83
99.4,5.141,84
100.4,5.148,84
101.4,5.155,85
102.4,5.162,86
103.4,5.177,87
104.4,5.184,88
105.4,5.198,89
106.4,5.205,89
107.4,5.212,90
108.4,5.227,91
109.4,5.234,92
110.4,5.248,93
111.4,5.262,94
112.4,5.277,95
113.4,5.284,95
114.4,5.298,96
115.4,5.312,97
116.4,5.32,98
117.4,5.334,99
118.4,5.348,100
119.4,5.355,100
120.4,5.37,101
121.4,5.377,102
122.4,5.391,103
123.5,5.405,104
124.4,5.42,105
125.5,5.434,105
126.5,5.441,106
127.5,5.455,107
128.5,5.47,108
129.5,5.484,109
130.5,5.498,110
131.5,5.513,111
132.5,5.527,111
133.5,5.541,112
134.5,5.548,113
135.5,5.563,114
136.5,5.57,115
137.5,5.584,116
138.5,5.591,116
139.5,5.598,117
140.5,5.613,118
141.5,5.62,119
142.5,5.627,120
143.5,5.634,121
144.5,5.649,122
145.5,5.656,122
146.5,5.663,123
147.5,5.677,124
148.5,5.684,125
149.5,5.691,126
150.5,5.706,127
151.5,5.72,127
152.5,5.727,128
153.5,5.741,129
154.5,5.756,130
155.6,5.763,131
156.6,5.777,132
157.6,5.792,132
158.6,5.799,133
159.6,5.813,134
160.6,5.827,135
161.6,5.842,136
162.6,5.856,137
163.6,5.87,138
164.6,5.877,138
165.6,5.892,139
166.6,5.906,140
167.6,5.913,141
168.6,5.927,142
169.6,5.935,143
170.6,5.949,143
171.6,5.963,144
172.6,5.977,145
173.6,5.992,146
174.6,6.013,147
175.6,6.02,148
176.6,6.042,149
177.6,6.056,149
178.6,6.078,150
179.6,6.092,151
180.6,6.106,152
181.6,6.12,153
182.6,6.142,154
183.6,6.163,154
184.6,6.178,155
185.6,6.192,156
186.7,6.199,157
187.7,6.213,158
188.7,6.221,159
189.7,6.235,159
190.7,6.249,160
191.7,6.256,161
192.7,6.271,162
193.7,6.285,163
194.7,6.292,164
195.7,6.299,165
196.7,6.313,165
197.7,6.328,166
198.7,6.342,167
199.7,6.356,168
201,6.371,169
202,6.385,170
203,6.399,170
204,6.414,171
205,6.428,172
206,6.449,173
207,6.471,174
208,6.485,175
209,6.499,176
210,6.514,176
211,6.528,177
212,6.549,178
213,6.564,179
214,6.585,180
215,6.599,181
216,6.621,181
217,6.635,182
218,6.65,183
219,6.664,184
220,6.678,185
221,6.692,186
222,6.707,186
223,6.728,187
224,6.735,188
225,6.757,189
226,6.764,190
227,6.778,191
228,6.793,192
229,6.807,192
230,6.821,193
231,6.835,194
232,6.85,195
233,6.864,196
234,6.885,197
235,6.893,197
236,6.907,198
237,6.921,199
238,6.936,200
239,6.95,201
240,6.964,202
241,6.978,203
242,6.993,203
243,7.007,204
244,7.028,205
245,7.043,206
246,7.05,207
247,7.064,208
248,7.079,208
249,7.093,209
250,7.1,210
251,7.121,211
252,7.129,212
253,7.143,213
254,7.157,213
255,7.171,214
256,7.186,215
257,7.2,216
258,7.214,217
259,7.229,218
260,7.243,219
261,7.257,219
262,7.264,220
263,7.272,221
264,7.286,222
265,7.307,223
266,7.329,224
267,7.343,224
268,7.365,225
269,7.372,226
270,7.393,227
271,7.407,228
272,7.429,229
273,7.443,230
274,7.457,230
275,7.472,231
276,7.486,232
277,7.5,233
278,7.515,234
279,7.522,235
280,7.543,235
281,7.558,236
282,7.572,237
283,7.579,238
284,7.593,239
285,7.615,240
286,7.629,240
287,7.651,241
288,7.665,242
289,7.686,243
290,7.701,244
291,7.715,245
292,7.729,246
293,7.743,246
294,7.765,247
295,7.779,248
296,7.794,249
297,7.808,250
298,7.822,251
299,7.829,251
300,7.844,252
301,7.858,253
302,7.872,254
303,7.879,255
304,7.894,256
305,7.901,257
306,7.915,257
307,7.922,258
308,7.937,259
309,7.951,260
310,7.965,261
311,7.987,262
312,8.001,262
313,8.015,263
314,8.029,264
315,8.044,265
316,8.058,266
317,8.072,267
318,8.087,267
319,8.094,268
320,8.108,269
321,8.122,270
322,8.144,271
323,8.158,272
324,8.172,273
325,8.194,273
326,8.208,274
327,8.223,275
328,8.237,276
329,8.251,277
330,8.265,278
331,8.28,278
332,8.301,279
333,8.315,280
334,8.337,281
335,8.358,282
336,8.38,283
337,8.394,284
338,8.416,284
339,8.437,285
340,8.451,286
341,8.466,287
342,8.48,288
343,8.487,289
344,8.494,289
345,8.501,290
346,8.509,291
347,8.516,292
348,8.53,293
349,8.53,294
350,8.544,294
351,8.551,295
352,8.559,296
353,8.573,297
354,8.587,298
355,8.594,299
356,8.609,300
357,8.623,300
358,8.637,301
359,8.659,302
360,8.68,303
361,8.694,304
362,8.709,305
363,8.723,305
364,8.737,306
365,8.752,307
366,8.766,308
367,8.78,309
368,8.795,310
369,8.809,311
370,8.83,311
371,8.845,312
372,8.859,313
373,8.873,314
374,8.887,315
375,8.902,316
376,8.916,316
377,8.93,317
378,8.952,318
379,8.959,319
380,8.98,320
381,8.995,321
382,9.016,321
383,9.03,322
384,9.052,323
385,9.073,324
386,9.095,325
387,9.123,326
388,9.159,327
389,9.188,327
390,9.216,328
391,9.245,329
392,9.274,330
393,9.302,331
394,9.331,332
395,9.359,332
396,9.381,333
397,9.402,334
398,9.424,335
399,9.445,336
400,9.459,337
401,9.481,338
402,9.502,338
403,9.524,339
404,9.538,340
405,9.56,341
406,9.581,342
407,9.602,343
408,9.617,343
409,9.631,344
410,9.653,345
411,9.667,346
412,9.681,347
413,9.703,348
414,9.717,348
415,9.731,349
416,9.745,350
417,9.767,351
418,9.774,352
419,9.788,353
420,9.803,354
421,9.817,354
422,9.824,355
423,9.838,356
424,9.846,357
425,9.86,358
426,9.874,359
427,9.896,359
428,9.91,360
429,9.924,361
430,9.946,362
431,9.967,363
432,9.989,364
434,10.01,365
435,10.031,366
436,10.053,366
437,10.074,367
438,10.096,368
439,10.117,369
440,10.139,370
441,10.16,371
442,10.174,371
443,10.196,372
444,10.21,373
445,10.225,374
446,10.246,375
447,10.26,376
448,10.282,377
449,10.296,377
450,10.317,378
451,10.332,379
452,10.346,380
453,10.368,381
454,10.382,382
455,10.396,382
456,10.41,383
457,10.425,384
458,10.439,385
459,10.453,386
460,10.46,387
461,10.475,388
462,10.496,388
463,10.511,389
464,10.525,390
465,10.539,391
466,10.561,392
467,10.575,393
468,10.589,393
469,10.603,394
470,10.625,395
471,10.639,396
472,10.654,397
473,10.668,398
474,10.689,398
475,10.696,399
476,10.711,400
477,10.725,401
478,10.739,402
479,10.754,403
480,10.775,404
481,10.789,404
482,10.804,405
483,10.825,406
484,10.839,407
485,10.854,408
486,10.875,409
487,10.897,409
488,10.911,410
489,10.94,411
490,10.961,412
491,10.99,413
492,11.018,414
493,11.032,415
494,11.054,415
495,11.075,416
496,11.09,417
497,11.104,418
498,11.118,419
499,11.133,420
500,11.147,420
501,11.161,421
502,11.175,422
503,11.183,423
504,11.197,424
505,11.211,425
506,11.233,425
507,11.24,426
508,11.254,427
509,11.268,428
510,11.276,429
511,11.29,430
512,11.304,431
513,11.311,431
514,11.326,432
515,11.333,433
516,11.347,434
517,11.354,435
518,11.369,436
519,11.383,436
520,11.39,437
521,11.404,438
522,11.411,439
523,11.426,440
524,11.433,441
525,11.447,442
526,11.461,442
527,11.483,443
528,11.49,444
529,11.504,445
530,11.519,446
531,11.533,447
532,11.547,447
533,11.554,448
534,11.569,449
535,11.576,450
536,11.583,451
537,11.583,452
538,11.597,452
539,11.612,453
540,11.626,454
541,11.647,455
542,11.676,456
543,11.705,457
544,11.733,458
545,11.762,458
546,11.798,459
547,11.826,460
548,11.862,461
549,11.898,462
550,11.933,463
551,11.962,463
552,11.991,464
553,12.019,465
554,12.041,466
555,12.069,467
556,12.091,468
557,12.119,469
558,12.141,469
559,12.169,470
560,12.191,471
561,12.212,472
562,12.234,473
563,12.255,474
564,12.277,474
565,12.291,475
566,12.312,476
567,12.334,477
568,12.348,478
569,12.377,479
570,12.398,479
571,12.42,480
572,12.441,481
573,12.462,482
574,12.491,483
575,12.505,484
576,12.527,485
577,12.541,486
578,12.555,486
579,12.577,487
580,12.591,488
581,12.605,489
582,12.62,490
583,12.62,491
584,12.627,491
585,12.634,492
586,12.634,493
587,12.627,494
588,12.634,495
589,12.627,496
590,12.627,497
591,12.62,497
592,12.62,498
593,12.613,499
594,12.613,500
595,12.613,501
596,12.613,502
597,12.62,502
598,12.627,503
599,12.634,504
600,12.641,505
601,12.641,506
602,12.648,507
603,12.641,508
604,12.648,508
605,12.648,509
606,12.67,510
608,12.684,511
609,12.706,512
610,12.727,513
611,12.748,513
612,12.777,514
613,12.806,515
614,12.834,516
615,12.87,517
616,12.899,518
617,12.942,518
618,12.97,519
619,13.013,520
620,13.056,521
621,13.099,522
622,13.142,523
623,13.17,524
624,13.213,524
625,13.249,525
626,13.285,526
627,13.32,527
628,13.349,528
629,13.378,529
630,13.406,529
631,13.428,530
632,13.456,531
633,13.492,532
634,13.514,533
635,13.542,534
636,13.571,535
637,13.592,535
638,13.621,536
639,13.649,537
640,13.664,538
641,13.678,539
642,13.678,540
643,13.678,540
644,13.685,541
645,13.692,542
646,13.707,543
647,13.721,544
648,13.742,545
649,13.757,545
650,13.778,546
651,13.785,547
652,13.8,548
653,13.814,549
654,13.828,550
655,13.835,551
656,13.85,551
657,13.871,552
658,13.885,553
659,13.907,554
660,13.921,555
661,13.943,556
662,13.971,556
663,13.993,557
664,14.021,558
665,14.05,559
666,14.071,560
667,14.1,561
668,14.128,562
669,14.15,562
670,14.171,563
671,14.2,564
672,14.229,565
673,14.25,566
674,14.264,567
675,14.279,567
676,14.286,568
677,14.293,569
678,14.307,570
679,14.321,571
680,14.336,572
681,14.357,572
682,14.386,573
683,14.414,574
684,14.45,575
685,14.472,576
686,14.507,577
687,14.529,578
688,14.55,578
689,14.565,579
690,14.593,580
691,14.622,581
692,14.643,582
693,14.658,583
694,14.679,583
695,14.7,584
696,14.722,585
697,14.75,586
698,14.772,587
699,14.801,588
700,14.822,589
701,14.843,589
702,14.865,590
703,14.886,591
704,14.908,592
705,14.922,593
706,14.944,594
707,14.965,594
708,14.986,595
709,15.029,597
710,15.051,597
711,15.079,598
712,15.115,599
713,15.144,600
714,15.172,601
715,15.201,602
716,15.222,602
717,15.251,603
718,15.28,604
719,15.301,605
720,15.322,606
721,15.337,607
722,15.358,608
723,15.38,608
724,15.394,609
725,15.415,610
726,15.437,611
727,15.458,612
728,15.473,613
729,15.494,613
730,15.508,614
731,15.508,615
732,15.516,616
733,15.516,617
734,15.516,618
735,15.516,618
736,15.508,619
737,15.508,620
738,15.516,621
739,15.53,622
740,15.551,623
741,15.558,624
742,15.58,624
743,15.608,625
744,15.623,626
745,15.644,627
746,15.666,628
747,15.687,629
748,15.709,629
749,15.709,630
750,15.701,631
751,15.709,632
752,15.687,633
754,15.68,634
754,15.68,635
756,15.673,635
757,15.659,636
758,15.63,637
759,15.608,638
760,15.566,639
761,15.494,640
762,15.415,640
763,15.322,641
764,15.194,642
765,15.015,643
766,14.786,644
767,14.493,645
768,14.15,645
769,13.721,646
770,13.242,647
771,12.627,648
772,11.712,649
773,0.0572,650
774,0.0572,651
775,0.06435,651
776,0.0572,652
777,0.06435,653
778,0.0572,654
779,0.0572,655
780,0.06435,656
781,0.06435,656
782,0.06435,657
783,0.06435,658
784,0.06435,659
785,0.06435,660
786,0.0572,661
787,0.06435,662
788,0.0572,662
789,0.06435,663
790,0.0572,664
791,0.0572,665
792,0.0572,666
793,0.0572,667
794,0.06435,667
795,0.06435,668
796,0.06435,669
797,0.0572,670
798,0.0572,671
799,0.06435,672
800,0.06435,672
801,0.0572,673
802,0.06435,674
803,0.06435,675
804,0.0572,676
805,0.06435,677
806,0.0572,678
807,0.0572,678
808,0.0572,679
809,0.0572,680
810,0.0572,681
811,0.0572,682
812,0.0572,683
813,0.0572,683
814,0.0572,684
815,0.0572,685
816,0.0572,686
817,0.0572,687
818,0.0572,688
819,0.0572,689
820,0.0572,689
821,0.0572,690
822,0.0572,691
823,0.0572,692
824,0.0572,693
825,0.0572,694
826,0.0572,694
827,0.0572,695
828,0.0572,696
829,0.0572,697
830,0.0572,698
831,0.0572,699
832,0.0572,699
833,0.0572,700
834,0.0572,701
835,0.0572,702
836,0.0572,703
837,0.0572,704
838,0.0572,705
839,0.0572,705
840,0.0572,706
841,0.0572,707
842,0.0572,708
843,0.0572,709
844,0.0572,710
845,0.0572,710
846,0.0572,711
847,0.0572,712
848,0.0572,713
849,0.0572,714
850,0.0572,715
851,0.0572,716
852,0.0572,716
853,0.0572,717
854,0.0572,718
855,0.0572,719
856,0.0572,720
857,0.0572,721
858,0.0572,721
859,0.0572,722
860,0.0572,723
861,0.0572,724
862,0.0572,725
863,0.0572,726
864,0.0572,726
865,0.0572,727
866,0.0572,728
867,0.0572,729
868,0.0572,730
869,0.0572,731
870,0.0572,732
871,0.0572,732
872,0.0572,733
873,0.0572,734
874,0.0572,735
875,0.0572,736
876,0.0572,737
877,0.0572,737
878,0.0572,738
879,0.06435,739
880,0.06435,740
881,0.06435,741
882,0.06435,742
883,0.06435,743
884,0.06435,743
885,0.06435,744
886,0.06435,745
887,0.06435,746
888,0.06435,747
889,0.06435,748
890,0.06435,748
891,0.06435,749
892,0.06435,750
893,0.06435,751
894,0.06435,752
895,0.06435,753
896,0.06435,753
897,0.06435,754
898,0.0715,755
899,0.06435,756
900,0.06435,757
901,0.06435,758
902,0.06435,759
903,0.06435,759
904,0.0715,760
905,0.06435,761
906,0.0715,762
907,0.0715,763
908,0.06435,764
909,0.06435,764
910,0.06435,765
911,0.0715,766
912,0.06435,767
913,0.0715,768
914,0.0715,769
915,0.0715,770
916,0.0715,770
917,0.0715,771
918,0.0715,772
919,0.06435,773
920,0.0715,774
921,0.0715,775
922,0.0715,775
923,0.06435,776
924,0.06435,777
925,0.06435,778
926,0.06435,779
927,0.0715,780
928,0.06435,780
929,0.0715,781
930,0.06435,782
931,0.0715,783
932,0.06435,784
933,0.06435,785
934,0.06435,786
935,0.06435,786
936,0.0715,787
937,0.0715,788
938,0.0715,789
939,0.0715,790
940,0.06435,791
941,0.0715,791
942,0.06435,792
943,0.06435,793
944,0.06435,794
945,0.06435,795
946,0.0715,796
947,0.0715,797
948,0.0715,797
949,0.0715,798
950,0.0715,799
951,0.06435,800
952,0.0715,801
953,0.0715,802
954,0.0715,802
955,0.0715,803
956,0.0715,804
957,0.0715,805
958,0.0715,806
959,0.07865,807
960,0.07865,807
961,0.0715,808
962,0.07865,809
963,0.0715,810
964,0.0715,811
965,0.0715,812
966,0.0715,813
967,0.0715,813
968,0.06435,814
969,0.0715,815
970,0.0715,816
971,0.0715,817
972,0.0715,818
973,0.0715,818
974,0.0715,819
975,0.0715,820
976,0.0715,821
977,0.0715,822
978,0.0715,823
979,0.0715,824
980,0.0715,824
981,0.0715,825
982,0.0715,826
983,0.0715,827
984,0.0715,828
985,0.0715,829
986,0.0715,829
987,0.0715,830
988,0.0715,831
989,0.0715,832
990,0.07865,833
991,0.0715,834
992,0.0715,834
993,0.0715,835
994,0.0715,836
995,0.0715,837
996,0.0715,838
997,0.0715,839
998,0.0715,840
999,0.0715,840
1001,0.0715,842
1002,0.0715,843
1003,0.0715,843
1004,0.0715,844
1005,0.0715,845
1006,0.0715,846
1007,0.0715,847
1008,0.0715,848
1009,0.0715,849
1010,0.0715,849
1011,0.0715,850
1012,0.07865,851
1013,0.0715,852
1014,0.0715,853
1015,0.0715,854
1016,0.0715,854
1017,0.0715,855
1018,0.0715,856
1019,0.07865,857
1020,0.07865,858
1021,0.07865,859
1022,0.0715,859
1023,0.0715,860
1024,0.0715,861
1025,0.07865,862
1026,0.07865,863
1027,0.0715,864
1028,0.0715,865
1029,0.0715,865
1030,0.07865,866
1031,0.07865,867
1032,0.07865,868
1033,0.07865,869
1034,0.0715,870
1035,0.0715,870
1036,0.0715,871
1037,0.0715,872
1038,0.0715,873
1039,0.0715,874
1040,0.0715,875
1041,0.0715,876
1042,0.0715,876
1043,0.0715,877
1044,0.0715,878
1045,0.0715,879
1046,0.0715,880
1047,0.0715,881
1048,0.0715,881
1049,0.0715,882
1050,0.0715,883
1051,0.07865,884
1052,0.0715,885
1053,0.0715,886
1054,0.0715,886
1055,0.0715,887
1056,0.0715,888
1057,0.0715,889
1058,0.0715,890
1059,0.0715,891
1060,0.0715,892
1061,0.0715,892
1062,0.0715,893
1063,0.0715,894
1064,0.0715,895
1065,0.0715,896
1066,0.0715,897
1067,0.0715,897
1068,0.0715,898
1069,0.07865,899
1070,0.0715,900
1071,0.07865,901
1072,0.07865,902
1073,0.0715,903
1074,0.0715,903
1075,0.0715,904
1076,0.0715,905
1077,0.0715,906
1078,0.0715,907
1079,0.0715,908
1080,0.0715,908
1081,0.0715,909
1082,0.0715,910
1083,0.0715,911
1084,0.0715,912
1085,0.0715,913
1086,0.07865,913
1087,0.07865,914
1088,0.0715,915
1089,0.0715,916
1090,0.0715,917
1091,0.0715,918
1092,0.0715,919
1093,0.0715,919
1094,0.0715,920
1095,0.0715,921
1096,0.0715,922
1097,0.0715,923
1098,0.0715,924
1099,0.0715,924
1100,0.0715,925
1101,0.0715,926
1102,0.0715,927
1103,0.0715,928
1104,0.0715,929
1105,0.0715,930
1106,0.0715,930
1107,0.0715,931
1108,0.0715,932
1109,0.0715,933
1110,0.0715,934
1111,0.0715,935
1112,0.0715,935
1113,0.0715,936
1114,0.0715,937
1115,0.0715,938
1116,0.0715,939
1117,0.0715,940
1118,0.0715,940
1119,0.0715,941
1120,0.0715,942
1121,0.0715,943
1122,0.0715,944
1123,0.07865,945
1124,0.07865,946
1125,0.07865,946
1126,0.0715,947
1127,0.07865,948
1128,0.07865,949
1129,0.07865,950
1130,0.07865,951
1131,0.07865,951
1132,0.07865,952
1133,0.07865,953
1134,0.07865,954
1135,0.07865,955
1136,0.07865,956
1137,0.07865,957
1138,0.07865,957
1139,0.07865,958
1140,0.07865,959
1141,0.07865,960
1142,0.07865,961
1143,0.07865,962
1144,0.0715,962
1145,0.07865,963
1146,0.07865,964
1147,0.07865,965
1148,0.07865,966
1149,0.07865,967
1150,0.07865,967
1151,0.0858,968
1152,0.0858,969
1153,0.0858,970
1154,0.0858,971
1155,0.0858,972
1156,0.0858,973
1157,0.0858,973
1158,0.0858,974
1159,0.0858,975
1160,0.0858,976
1161,0.0858,977
1162,0.07865,978
1163,0.0715,978
1164,0.0715,979
1165,0.0715,980
1166,0.0715,981
1167,0.0715,982
1168,0.0715,983
1169,0.0715,984
1170,0.0715,984
1171,0.0715,985
1172,0.0715,986
1173,0.0715,987
1174,0.06435,988
1176,0.0715,989
1176,0.0715,989
1178,0.0715,990
1179,0.0715,991
1180,0.0715,992
1181,0.0715,993
1182,0.0715,994
1183,0.06435,994
1184,0.0715,995
1185,0.0715,996
1186,0.0715,997
1187,0.0715,998
1188,0.0715,999
1189,0.07865,1000
1190,0.0715,1000
1191,0.07865,1001
1192,0.0715,1002
1193,0.07865,1003
1194,0.0715,1004
1195,0.0715,1005
1196,0.0715,1005
1197,0.0715,1006
1198,0.0715,1007
1199,0.0715,1008
1200,0.0715,1009
1201,0.07865,1010
1202,0.0715,1011
1203,0.0715,1011
1204,0.0715,1012
1205,0.0715,1013
1206,0.07865,1014
1207,0.07865,1015
1208,0.07865,1016
1209,0.07865,1016
1210,0.07865,1017
1211,0.07865,1018
1212,0.0715,1019
1213,0.07865,1020
1214,0.07865,1021
1215,0.07865,1021
1216,0.07865,1022
1217,0.07865,1023
1218,0.07865,1024
1219,0.0715,1025
1220,0.0715,1026
1221,0.0715,1027
1222,0.07865,1027
1223,0.0715,1028
1224,0.0715,1029
1225,0.0715,1030
1226,0.0715,1031
1227,0.07865,1032
1228,0.07865,1032
1229,0.07865,1033
1230,0.0715,1034
1231,0.0715,1035
1232,0.0715,1036
1233,0.0715,1037
1234,0.0715,1038
1235,0.0715,1038
1236,0.0715,1039
1237,0.0715,1040
1238,0.0715,1041
1239,0.0715,1042
1240,0.0715,1043
1241,0.0715,1043
1242,0.0715,1044
1243,0.0715,1045
1244,0.0715,1046
1245,0.0715,1047
1246,0.0715,1048
1247,0.07865,1048
1248,0.07865,1049
1249,0.07865,1050
1250,0.0715,1051
1251,0.0715,1052
1252,0.0715,1053
1253,0.0715,1054
1254,0.0715,1054
1255,0.0715,1055
1256,0.0715,1056
1257,0.0715,1057
1258,0.0715,1058
1259,0.0715,1059
1260,0.07865,1059
1261,0.07865,1060
1262,0.07865,1061
1263,0.0715,1062
1264,0.07865,1063
1265,0.0715,1064
1266,0.07865,1065
1267,0.07865,1065
1268,0.07865,1066
1269,0.07865,1067
1270,0.0858,1068
1271,0.07865,1069
1272,0.07865,1070
1273,0.07865,1070
1274,0.07865,1071
1275,0.07865,1072
1276,0.07865,1073
1277,0.07865,1074
1278,0.07865,1075
1279,0.07865,1075
1280,0.07865,1076
1281,0.07865,1077
1282,0.0858,1078
1283,0.07865,1079
1284,0.07865,1080
1285,0.07865,1081
1286,0.0858,1081
1287,0.07865,1082
1288,0.07865,1083
1289,0.07865,1084
1290,0.07865,1085
1291,0.07865,1086
1292,0.07865,1086
1293,0.07865,1087
1294,0.07865,1088
1295,0.07865,1089
1296,0.07865,1090
1297,0.07865,1091
1298,0.07865,1092
1299,0.07865,1092
1300,0.07865,1093
1301,0.0858,1094
1302,0.0858,1095
1303,0.0858,1096
1304,0.0858,1097
1305,0.0858,1097
1306,0.07865,1098
1307,0.07865,1099
1308,0.07865,1100
1309,0.07865,1101
1310,0.07865,1102
1311,0.0858,1102
1312,0.0858,1103
1313,0.0858,1104
1314,0.0858,1105
1315,0.0858,1106
1316,0.0858,1107
1317,0.0858,1108
1318,0.0858,1108
1319,0.0858,1109
1320,0.0858,1110
1321,0.0858,1111
1322,0.0858,1112
1323,0.0858,1113
1324,0.09295,1113
1325,0.0858,1114
1326,0.0858,1115
1327,0.0858,1116
1328,0.0858,1117
1329,0.0858,1118
1330,0.0858,1119
1331,0.09295,1119
1332,0.09295,1120
1333,0.09295,1121
1334,0.09295,1122
1335,0.09295,1123
1336,0.1001,1124
1337,0.09295,1124
1338,0.0858,1125
1339,0.09295,1126
1340,0.0858,1127
1341,0.09295,1128
1342,0.09295,1129
1343,0.09295,1129
1344,0.09295,1130
1345,0.09295,1131
1346,0.1001,1132
1347,0.1001,1133
1348,0.1001,1134
1349,0.1001,1135
1350,0.1001,1135
1351,0.09295,1136
1352,0.09295,1137
1353,0.09295,1138
1354,0.0858,1139
1355,0.0858,1140
1356,0.09295,1140
1357,0.09295,1141
1358,0.09295,1142
1359,0.09295,1143
1360,0.09295,1144
1361,0.1001,1145
1362,0.09295,1146
1363,0.1001,1146
1364,0.09295,1147
1365,0.1001,1148
1366,0.1001,1149
1367,0.1001,1150
1368,0.1001,1151
1369,0.1001,1151
1370,0.1001,1152
1371,0.1001,1153
1372,0.10725,1154
1373,0.1001,1155
1374,0.10725,1156
1375,0.10725,1156
1376,0.10725,1157
1377,0.10725,1158
1378,0.10725,1159
1379,0.10725,1160
1380,0.1144,1161
1381,0.09295,1162
1382,0.07865,1162
1383,0.0715,1163
1384,0.0715,1164
1385,0.06435,1165
1386,0.0715,1166
1387,0.0715,1167
1388,0.0715,1167
1389,0.0715,1168
1390,0.0715,1169
1391,0.06435,1170
1392,0.0715,1171
1393,0.0715,1172
1394,0.0715,1173
1395,0.0715,1173
1396,0.0715,1174
1397,0.0715,1175
1398,0.0715,1176
1399,0.0715,1177
1400,0.06435,1178
1401,0.0715,1178
1402,0.0715,1179
1403,0.0715,1180
1404,0.06435,1181
1405,0.0715,1182
1406,0.0715,1183
1407,0.0715,1183
1408,0.0715,1184
1409,0.0715,1185
1410,0.0715,1186
1411,0.0715,1187
1412,0.0715,1188
1413,0.0715,1189
1414,0.0715,1189
1415,0.0715,1190
1416,0.06435,1191
1417,0.0715,1192
1418,0.0715,1193
1419,0.0715,1194
1420,0.0715,1194
1421,0.0715,1195
1422,0.0715,1196
1423,0.0715,1197
1424,0.0715,1198
1425,0.06435,1199
1426,0.06435,1200
1427,0.0715,1200
1428,0.0715,1201
1429,0.0715,1202
1430,0.0715,1203
1431,0.0715,1204
1432,0.0715,1205
1433,0.0715,1205
1434,0.06435,1206
1435,0.0715,1207
1436,0.0715,1208
1437,0.0715,1209
1438,0.0715,1210
1439,0.0715,1210
1440,0.0715,1211
1441,0.0715,1212
1442,0.0715,1213
1443,0.0715,1214
1444,0.07865,1215
1445,0.07865,1216
1446,0.07865,1216
1447,0.0715,1217
1448,0.0715,1218
1449,0.0715,1219
1450,0.0715,1220
1451,0.0715,1221
1452,0.0715,1221
1453,0.07865,1222
1454,0.07865,1223
1455,0.07865,1224
1456,0.0715,1225
1457,0.07865,1226
1458,0.0715,1227
1459,0.0715,1227
1460,0.07865,1228
1461,0.07865,1229
1462,0.07865,1230
1463,0.07865,1231
1464,0.07865,1232
1465,0.07865,1232
1466,0.0715,1233
1467,0.07865,1234
1468,0.0715,1235
1469,0.07865,1236
1470,0.07865,1237
1471,0.07865,1237
1472,0.07865,1238
1473,0.0715,1239
1474,0.0715,1240
1475,0.0715,1241
1476,0.0715,1241