File: in-progress/Koerner_2005_Polymer/RawDataFromAuthors/cnttobreak/cnt5pu.csv
Strain (%),Stress (MPa),Time (sec)
0.0415,0.5461,
0.608,0.8547,1
1.166,1.1396,2
1.736,1.4008,2
2.31,1.6382,3
2.87,1.84,4
3.44,2.03,5
4,2.208,5
4.57,2.374,6
5.13,2.517,7
5.7,2.647,8
6.27,2.754,8
6.84,2.873,9
7.4,2.968,10
7.96,3.063,11
8.53,3.158,11
9.09,3.229,12
9.66,3.288,13
10.23,3.359,14
10.8,3.419,14
11.36,3.478,15
11.93,3.526,16
12.49,3.573,17
13.06,3.621,17
13.62,3.656,18
14.19,3.692,19
14.76,3.716,20
15.32,3.751,20
15.89,3.775,21
16.45,3.811,22
17.02,3.834,23
17.58,3.858,23
18.15,3.882,24
18.72,3.894,25
19.29,3.917,26
19.85,3.941,26
20.4,3.953,27
21,3.965,28
21.5,3.977,29
22.1,3.989,29
22.7,4,30
23.2,4.012,31
23.8,4.024,32
24.4,4.036,32
24.9,4.036,33
25.5,4.048,34
26.1,4.06,35
26.6,4.072,35
27.2,4.072,36
27.8,4.084,37
28.3,4.095,38
28.9,4.095,38
29.5,4.107,39
30,4.119,40
30.6,4.131,41
31.2,4.131,41
31.7,4.143,42
32.3,4.143,43
32.9,4.155,44
33.4,4.155,44
34,4.167,45
34.6,4.167,46
35.1,4.167,47
35.7,4.167,47
36.3,4.179,48
36.8,4.179,49
37.4,4.179,50
38,4.19,50
38.5,4.19,51
39.1,4.19,52
39.7,4.202,53
40.2,4.202,53
40.8,4.214,54
41.4,4.226,55
41.9,4.226,56
42.5,4.238,56
43.1,4.238,57
43.6,4.238,58
44.2,4.25,59
44.8,4.25,59
45.3,4.262,60
45.9,4.274,61
46.5,4.274,62
47,4.274,62
47.6,4.285,63
48.2,4.285,64
48.7,4.297,65
49.3,4.297,65
49.9,4.309,66
50.4,4.309,67
51,4.309,68
51.6,4.321,68
52.1,4.321,69
52.7,4.321,70
53.2,4.321,71
53.8,4.321,71
54.4,4.321,72
54.9,4.333,73
55.5,4.333,74
56.1,4.345,74
56.6,4.345,75
57.2,4.345,76
57.8,4.357,77
58.3,4.357,77
58.9,4.368,78
59.5,4.368,79
60,4.368,80
60.6,4.38,80
61.2,4.38,81
61.7,4.38,82
62.3,4.392,83
62.9,4.392,83
63.4,4.404,84
64,4.416,85
64.6,4.428,86
65.1,4.428,86
65.7,4.428,87
66.3,4.44,88
66.8,4.44,89
67.4,4.452,89
68,4.463,90
68.5,4.452,91
69.1,4.463,92
69.7,4.463,92
70.2,4.475,93
70.8,4.487,94
71.4,4.487,95
71.9,4.487,95
72.5,4.499,96
73.1,4.499,97
73.6,4.523,98
74.2,4.523,98
74.8,4.523,99
75.3,4.535,100
75.9,4.547,101
76.5,4.547,101
77,4.547,102
77.6,4.547,103
78.2,4.558,104
78.7,4.558,104
79.3,4.558,105
79.8,4.558,106
80.4,4.57,107
81,4.57,107
81.6,4.57,108
82.1,4.57,109
82.7,4.57,110
83.2,4.582,110
83.8,4.582,111
84.4,4.594,112
84.9,4.606,113
85.5,4.606,113
86.1,4.618,114
86.6,4.618,115
87.2,4.618,116
87.8,4.63,116
88.3,4.63,117
88.9,4.642,118
89.5,4.642,119
90,4.653,119
90.6,4.665,120
91.2,4.653,121
91.7,4.665,122
92.3,4.677,122
92.9,4.677,123
93.4,4.689,124
94,4.701,125
94.6,4.713,125
95.1,4.713,126
95.7,4.713,127
96.3,4.725,128
96.8,4.725,128
97.4,4.725,129
98,4.725,130
98.5,4.736,131
99.1,4.748,131
99.7,4.748,132
100.2,4.76,133
100.8,4.76,134
101.4,4.772,134
101.9,4.772,135
102.5,4.784,136
103.1,4.796,137
103.6,4.808,137
104.2,4.808,138
104.8,4.808,139
105.3,4.82,140
105.9,4.82,140
106.5,4.831,141
107,4.831,142
107.6,4.831,143
108.2,4.843,143
108.7,4.843,144
109.3,4.855,145
109.8,4.855,146
110.4,4.855,146
111,4.867,147
111.6,4.867,148
112.1,4.879,149
112.7,4.891,149
113.2,4.891,150
113.8,4.903,151
114.4,4.903,152
114.9,4.915,152
115.5,4.926,153
116.1,4.938,154
116.6,4.938,155
117.2,4.95,155
117.8,4.962,156
118.3,4.974,157
118.9,4.986,158
119.5,4.986,158
120,4.998,159
120.6,5.009,160
121.2,5.021,161
121.7,5.021,161
122.3,5.033,162
122.9,5.045,163
123.4,5.057,164
124,5.057,164
124.6,5.069,165
125.1,5.081,166
125.7,5.093,167
126.3,5.104,167
126.8,5.116,168
127.4,5.116,169
128,5.128,170
128.5,5.128,170
129.1,5.128,171
129.7,5.14,172
130.2,5.152,173
130.8,5.152,173
131.4,5.164,174
131.9,5.176,175
132.5,5.176,176
133.1,5.188,176
133.6,5.188,177
134.2,5.188,178
134.8,5.199,179
135.3,5.199,179
135.9,5.211,180
136.4,5.223,181
137,5.223,182
137.6,5.235,182
138.1,5.247,183
138.7,5.259,184
139.3,5.271,185
139.9,5.283,185
140.4,5.294,186
141,5.306,187
141.6,5.318,188
142.1,5.33,188
142.7,5.342,189
143.2,5.354,190
143.8,5.366,191
144.4,5.366,191
144.9,5.377,192
145.5,5.389,193
146.1,5.401,194
146.6,5.413,194
147.2,5.413,195
147.8,5.425,196
148.3,5.425,197
148.9,5.437,197
149.5,5.449,198
150,5.449,199
150.6,5.461,200
151.2,5.472,200
151.7,5.484,201
152.3,5.484,202
152.9,5.496,203
153.4,5.508,203
154,5.532,204
154.6,5.532,205
155.1,5.556,206
155.7,5.567,206
156.3,5.579,207
156.8,5.591,208
157.4,5.603,209
158,5.615,209
158.5,5.627,210
159.1,5.627,211
159.7,5.651,212
160.2,5.662,212
160.8,5.674,213
161.4,5.686,214
161.9,5.698,215
162.5,5.71,215
163.1,5.71,216
163.6,5.722,217
164.2,5.734,218
164.8,5.745,218
165.3,5.745,219
165.9,5.769,220
166.5,5.769,221
167,5.781,221
167.6,5.793,222
168.2,5.805,223
168.7,5.805,224
169.3,5.817,224
169.8,5.817,225
170.4,5.829,226
171,5.84,227
171.5,5.852,227
172.1,5.864,228
172.7,5.876,229
173.2,5.888,230
173.8,5.9,230
174.4,5.912,231
174.9,5.924,232
175.5,5.935,233
176.1,5.947,233
176.6,5.959,234
177.2,5.959,235
177.8,5.971,236
178.3,5.983,236
178.9,5.995,237
179.5,6.007,238
180,6.019,239
180.6,6.042,239
181.2,6.042,240
181.7,6.054,241
182.3,6.066,242
182.9,6.078,242
183.4,6.09,243
184,6.102,244
184.6,6.113,245
185.1,6.137,245
185.7,6.149,246
186.3,6.161,247
186.8,6.173,248
187.4,6.185,248
188,6.197,249
188.5,6.197,250
189.1,6.208,251
189.7,6.22,251
190.2,6.22,252
190.8,6.232,253
191.4,6.244,254
191.9,6.256,254
192.5,6.268,255
193.1,6.268,256
193.6,6.28,257
194.2,6.292,257
194.8,6.315,258
195.3,6.315,259
195.9,6.327,260
196.5,6.339,260
197,6.351,261
197.6,6.363,262
198.2,6.375,263
198.7,6.387,263
199.3,6.398,264
199.8,6.41,265
200,6.422,266
201,6.434,266
202,6.446,267
202,6.446,268
203,6.47,269
203,6.481,269
204,6.493,270
204,6.505,271
205,6.517,272
206,6.529,272
206,6.529,273
207,6.541,274
207,6.553,275
208,6.565,275
208,6.576,276
209,6.588,277
209,6.588,278
210,6.612,278
211,6.624,279
211,6.624,280
212,6.636,281
212,6.648,281
213,6.66,282
213,6.671,283
214,6.683,284
215,6.695,284
215,6.707,285
216,6.719,286
216,6.731,287
217,6.731,287
217,6.743,288
218,6.755,289
219,6.766,290
219,6.79,290
220,6.802,291
220,6.814,292
221,6.814,293
221,6.826,293
222,6.838,294
222,6.849,295
223,6.861,296
224,6.873,296
224,6.885,297
225,6.885,298
225,6.897,299
226,6.909,299
226,6.921,300
227,6.933,301
228,6.944,302
228,6.956,302
229,6.956,303
229,6.968,304
230,6.98,305
230,6.992,305
231,7.004,306
232,7.016,307
232,7.028,308
233,7.039,308
233,7.039,309
234,7.063,310
234,7.075,311
235,7.087,311
236,7.099,312
236,7.111,313
237,7.123,314
237,7.134,314
238,7.146,315
238,7.158,316
239,7.17,317
239,7.182,317
240,7.194,318
241,7.206,319
241,7.206,320
242,7.217,320
242,7.217,321
243,7.229,322
243,7.229,323
244,7.241,323
245,7.253,324
245,7.265,325
246,7.277,326
246,7.277,326
247,7.289,327
247,7.301,328
248,7.312,329
249,7.324,329
249,7.336,330
250,7.348,331
250,7.36,332
251,7.372,332
251,7.384,333
252,7.407,334
252,7.407,335
253,7.419,335
254,7.431,336
254,7.443,337
255,7.455,338
255,7.479,338
256,7.479,339
256,7.502,340
257,7.502,341
258,7.514,341
258,7.514,342
259,7.526,343
259,7.538,344
260,7.538,344
261,7.55,345
261,7.562,346
262,7.574,347
262,7.585,347
263,7.597,348
263,7.609,349
264,7.621,350
264,7.645,350
265,7.657,351
266,7.669,352
266,7.669,353
267,7.68,353
267,7.68,354
268,7.692,355
268,7.704,356
269,7.716,356
270,7.728,357
270,7.728,358
271,7.74,359
271,7.752,359
272,7.764,360
272,7.764,361
273,7.775,362
274,7.787,362
274,7.799,363
275,7.811,364
275,7.823,365
276,7.835,365
276,7.847,366
277,7.858,367
278,7.87,368
278,7.882,368
279,7.894,369
279,7.894,370
280,7.906,371
280,7.906,371
281,7.918,372
281,7.93,373
282,7.942,374
283,7.953,374
283,7.953,375
284,7.965,376
284,7.977,377
285,7.989,377
285,8.001,378
286,8.013,379
287,8.037,380
287,8.048,380
288,8.06,381
288,8.084,382
289,8.096,383
289,8.108,383
290,8.12,384
291,8.132,385
291,8.143,386
292,8.155,386
292,8.167,387
293,8.179,388
293,8.191,389
294,8.203,389
294,8.203,390
295,8.215,391
296,8.226,392
296,8.238,392
297,8.25,393
297,8.25,394
298,8.274,395
298,8.274,395
299,8.298,396
300,8.31,397
300,8.321,398
301,8.333,398
301,8.345,399
302,8.357,400
302,8.369,401
303,8.381,401
304,8.393,402
304,8.405,403
305,8.416,404
305,8.428,404
306,8.44,405
306,8.452,406
307,8.464,407
308,8.476,407
308,8.476,408
309,8.488,409
309,8.511,410
310,8.511,410
310,8.523,411
311,8.535,412
311,8.547,413
312,8.559,413
313,8.571,414
313,8.571,415
314,8.583,416
314,8.594,416
315,8.594,417
315,8.606,418
316,8.618,419
317,8.63,419
317,8.63,420
318,8.642,421
318,8.654,422
319,8.654,422
319,8.666,423
320,8.666,424
321,8.689,425
321,8.689,425
322,8.701,426
322,8.713,427
323,8.725,428
323,8.737,428
324,8.749,429
324,8.761,430
325,8.773,431
326,8.784,431
326,8.808,432
327,8.82,433
327,8.832,434
328,8.844,434
328,8.844,435
329,8.856,436
330,8.879,437
330,8.879,437
331,8.891,438
331,8.903,439
332,8.915,440
332,8.927,440
333,8.939,441
334,8.939,442
334,8.939,443
335,8.951,443
335,8.951,444
336,8.951,445
336,8.951,446
337,8.962,446
337,8.974,447
338,8.986,448
339,8.998,449
339,9.01,449
340,9.022,450
340,9.046,451
341,9.057,452
341,9.081,452
342,9.105,453
343,9.117,454
343,9.141,455
344,9.152,455
344,9.164,456
345,9.176,457
345,9.188,458
346,9.188,458
347,9.188,459
347,9.2,460
348,9.212,461
348,9.2,461
349,9.2,462
349,9.2,463
350,9.2,464
351,9.212,464
351,9.224,465
352,9.236,466
352,9.247,467
353,9.259,467
353,9.259,468
354,9.259,469
354,9.247,470
355,9.247,470
356,9.236,471
356,9.224,472
357,9.224,473
357,9.224,473
358,9.236,474
358,9.247,475
359,9.259,476
360,9.283,476
360,9.295,477
361,9.307,478
361,9.319,479
362,9.342,479
362,9.354,480
363,9.378,481
364,9.39,482
364,9.414,482
365,9.437,483
365,9.461,484
366,9.485,485
366,9.497,485
367,9.52,486
368,9.532,487
368,9.556,488
369,9.568,488
369,9.58,489
370,9.592,490
370,9.615,491
371,9.627,491
371,9.651,492
372,9.675,493
373,9.687,494
373,9.722,494
374,9.734,495
374,9.758,496
375,9.77,497
375,9.782,497
376,9.805,498
377,9.817,499
377,9.829,500
378,9.841,500
378,9.865,501
379,9.865,502
379,9.877,503
380,9.888,503
381,9.912,504
381,9.924,505
382,9.936,506
382,9.948,506
383,9.948,507
383,9.948,508
384,9.96,509
384,9.96,509
385,9.96,510
386,9.948,511
386,9.936,512
387,9.924,512
387,9.924,513
388,9.912,514
388,9.924,515
389,9.936,515
390,9.936,516
390,9.96,517
391,9.972,518
391,9.983,518
392,10.007,519
392,10.043,520
393,10.055,521
394,10.066,522
394,10.078,522
395,10.09,523
395,10.114,524
396,10.126,525
396,10.138,525
397,10.15,526
398,10.161,527
398,10.173,528
399,10.197,528
399,10.209,529
400,10.233,530
400,10.245,531
401,10.256,531
402,10.268,532
402,10.268,533
403,10.28,534
403,10.292,534
404,10.304,535
404,10.316,536
405,10.328,537
406,10.34,537
406,10.351,538
407,10.363,539
407,10.387,540
408,10.399,540
408,10.411,541
409,10.423,542
409,10.446,543
410,10.446,543
411,10.47,544
411,10.482,545
412,10.482,546
412,10.506,546
413,10.518,547
413,10.518,548
414,10.529,549
415,10.553,549
415,10.553,550
416,10.577,551
416,10.601,552
417,10.613,552
417,10.624,553
418,10.636,554
419,10.648,555
419,10.66,555
420,10.684,556
420,10.696,557
421,10.708,558
421,10.719,558
422,10.719,559
422,10.719,560
423,10.719,561
424,10.708,561
424,10.708,562
425,10.708,563
425,10.708,564
426,10.719,564
426,10.719,565
427,10.743,566
428,10.743,567
428,10.767,567
429,10.791,568
429,10.802,569
430,10.814,570
430,10.838,570
431,10.85,571
432,10.874,572
432,10.886,573
433,10.897,573
433,10.909,574
434,10.933,575
434,10.933,576
435,10.957,576
436,10.969,577
436,10.969,578
437,10.992,579
437,10.992,579
438,11.004,580
438,11.016,581
439,11.028,582
439,11.04,582
440,11.04,583
441,11.052,584
441,11.064,585
442,11.076,585
442,11.076,586
443,11.087,587
443,11.099,588
444,11.111,588
445,11.111,589
445,11.135,590
446,11.147,591
446,11.17,591
447,11.182,592
447,11.194,593
448,11.206,594
449,11.23,594
449,11.23,595
450,11.254,596
450,11.265,597
451,11.265,597
451,11.289,598
452,11.289,599
452,11.301,600
453,11.313,600
454,11.313,601
454,11.325,602
455,11.349,603
455,11.36,603
456,11.372,604
456,11.384,605
457,11.396,606
458,11.408,606
458,11.408,607
459,11.432,608
459,11.432,609
460,11.443,609
460,11.455,610
461,11.467,611
462,11.479,612
462,11.479,612
463,11.491,613
463,11.503,614
464,11.515,615
464,11.515,615
465,11.538,616
466,11.55,617
466,11.562,618
467,11.574,618
467,11.598,619
468,11.622,620
468,11.633,621
469,11.645,621
469,11.669,622
470,11.681,623
471,11.693,624
471,11.705,624
472,11.717,625
472,11.728,626
473,11.74,627
473,11.752,627
474,11.764,628
475,11.776,629
475,11.8,630
476,11.811,630
476,11.823,631
477,11.835,632
477,11.847,633
478,11.859,633
479,11.859,634
479,11.871,635
480,11.883,636
480,11.871,636
481,11.883,637
481,11.895,638
482,11.906,639
482,11.93,639
483,11.942,640
484,11.954,641
484,11.966,642
485,11.978,642
485,11.99,643
486,12.013,644
486,12.025,645
487,12.037,645
488,12.049,646
488,12.049,647
489,12.061,648
489,12.073,648
490,12.096,649
490,12.108,650
491,12.12,651
492,12.132,651
492,12.156,652
493,12.168,653
493,12.179,654
494,12.191,654
494,12.203,655
495,12.215,656
496,12.227,657
496,12.239,657
497,12.251,658
497,12.263,659
498,12.274,660
498,12.286,660
499,12.298,661
499,12.322,662
500,12.334,663
501,12.346,663
501,12.369,664
502,12.381,665
502,12.393,666
503,12.405,666
503,12.417,667
504,12.429,668
505,12.441,669
505,12.453,669
506,12.453,670
506,12.464,671
507,12.488,672
507,12.488,672
508,12.512,673
509,12.536,674
509,12.536,675
510,12.559,675
510,12.571,676
511,12.571,677
511,12.583,678
512,12.595,678
513,12.595,679
513,12.607,680
514,12.619,681
514,12.631,681
515,12.642,682
515,12.654,683
516,12.678,684
517,12.69,684
517,12.69,685
518,12.702,686
518,12.714,687
519,12.726,687
519,12.737,688
520,12.749,689
521,12.749,690
521,12.761,690
522,12.773,691
522,12.773,692
523,12.785,693
523,12.809,693
524,12.821,694
525,12.832,695
525,12.844,696
526,12.856,696
526,12.88,697
527,12.892,698
527,12.904,699
528,12.915,699
528,12.927,700
529,12.927,701
530,12.939,702
530,12.951,702
531,12.951,703
531,12.975,704
532,12.987,705
532,12.999,705
533,12.999,706
534,13.01,707
534,13.022,708
535,13.034,708
535,13.046,709
536,13.058,710
536,13.07,711
537,13.082,711
538,13.094,712
538,13.105,713
539,13.117,714
539,13.117,714
540,13.129,715
540,13.141,716
541,13.153,717
541,13.153,717
542,13.153,718
543,13.165,719
543,13.177,720
544,13.189,720
544,13.189,721
545,13.212,722
545,13.224,723
546,13.236,723
547,13.248,724
547,13.26,725
548,13.272,726
548,13.272,726
549,13.283,727
549,13.295,728
550,13.319,729
551,13.331,729
551,13.331,730
552,13.343,731
552,13.355,732
553,13.367,732
553,13.378,733
554,13.39,734
555,13.402,735
555,13.414,735
556,13.426,736
556,13.426,737
557,13.438,738
557,13.45,738
558,13.462,739
558,13.473,740
559,13.485,741
560,13.485,741
560,13.509,742
561,13.509,743
561,13.521,744
562,13.533,744
562,13.545,745
563,13.557,746
564,13.568,747
564,13.58,747
565,13.592,748
565,13.604,749
566,13.616,750
566,13.628,750
567,13.628,751
568,13.64,752
568,13.651,753
569,13.663,753
569,13.663,754
570,13.675,755
570,13.687,756
571,13.675,756
571,13.687,757
572,13.699,758
573,13.699,759
573,13.723,759
574,13.735,760
574,13.746,761
575,13.77,762
575,13.782,762
576,13.806,763
577,13.818,764
577,13.841,765
578,13.865,765
578,13.877,766
579,13.901,767
579,13.913,768
580,13.913,768
581,13.936,769
581,13.936,770
582,13.96,771
582,13.96,771
583,13.972,772
583,13.984,773
584,14.008,774
585,14.019,774
585,14.031,775
586,14.043,776
586,14.055,777
587,14.079,777
587,14.091,778
588,14.103,779
588,14.103,780
589,14.114,780
590,14.114,781
590,14.114,782
591,14.114,783
591,14.103,783
592,14.103,784
592,14.079,785
593,14.079,786
594,14.091,786
594,14.103,787
595,14.103,788
595,14.114,789
596,14.126,789
596,14.126,790
597,14.138,791
598,14.162,792
598,14.174,792
599,14.186,793
599,14.198,794
600,14.209,795
600,14.221,795
601,14.233,796
601,14.233,797
602,14.245,798
603,14.233,798
603,14.233,799
604,14.233,800
604,14.221,801
605,14.221,801
605,14.221,802
606,14.233,803
607,14.269,804
607,14.281,804
608,14.316,805
608,14.34,806
609,14.364,807
609,14.387,807
610,14.423,808
611,14.435,809
611,14.459,810
612,14.482,810
612,14.494,811
613,14.506,812
613,14.53,813
614,14.542,813
615,14.554,814
615,14.566,815
616,14.577,816
616,14.589,816
617,14.601,817
617,14.601,818
618,14.613,819
618,14.613,819
619,14.613,820
620,14.613,821
620,14.601,822
621,14.613,822
621,14.613,823
622,14.625,824
622,14.637,825
623,14.649,825
624,14.672,826
624,14.684,827
625,14.696,828
625,14.72,828
626,14.732,829
626,14.744,830
627,14.755,831
628,14.767,831
628,14.755,832
629,14.755,833
629,14.744,834
630,14.732,834
630,14.72,835
631,14.72,836
631,14.72,837
632,14.72,837
633,14.72,838
633,14.732,839
634,14.744,840
634,14.755,840
635,14.779,841
635,14.803,842
636,14.827,843
637,14.862,843
637,14.886,844
638,14.91,845
638,14.922,846
639,14.945,846
639,14.969,847
640,14.981,848
641,15.005,849
641,15.028,850
642,15.04,851
643,15.052,851
643,15.064,852
644,15.076,853
644,15.076,854
645,15.088,854
645,15.112,855
646,15.112,856
647,15.123,857
647,15.123,857
648,15.135,858
648,15.147,859
649,15.147,860
649,15.147,860
650,15.147,861
650,15.159,862
651,15.171,863
652,15.183,863
652,15.195,864
653,15.195,865
653,15.195,866
654,15.195,866
654,15.195,867
655,15.207,868
656,15.207,869
656,15.207,869
657,15.207,870
657,15.195,871
658,15.195,872
658,15.195,872
659,15.183,873
660,15.171,874
660,15.159,875
661,15.147,875
661,15.135,876
662,15.112,877
662,15.1,878
663,15.076,878
664,15.064,879
664,15.04,880
665,15.028,881
665,14.993,881
666,14.934,882
666,14.886,883
667,14.839,884
667,14.779,884
668,14.72,885
669,14.637,886
669,14.542,887
670,14.435,887
670,14.304,888
671,14.15,889
671,13.972,890
672,13.746,890
673,13.462,891
673,13.034,892
674,12.263,893
674,10.411,893
675,0.05935,894
675,0.05935,895
676,0.07123,896
677,0.05935,896
677,0.05935,897
678,0.07123,898
678,0.05935,899
679,0.07123,899
679,0.07123,900
680,0.05935,901
680,0.07123,902
681,0.05935,902
682,0.05935,903
682,0.05935,904
683,0.07123,905
683,0.05935,905
684,0.05935,906
684,0.05935,907
685,0.05935,908
686,0.05935,908
686,0.07123,909
687,0.07123,910
687,0.07123,911
688,0.07123,911
688,0.07123,912
689,0.07123,913
690,0.07123,914
690,0.07123,914
691,0.07123,915
691,0.07123,916
692,0.07123,917
692,0.07123,917
693,0.05935,918
694,0.07123,919
694,0.05935,920
695,0.05935,920
695,0.05935,921
696,0.05935,922
696,0.07123,923
697,0.05935,923
697,0.07123,924
698,0.07123,925
699,0.05935,926
699,0.07123,926
700,0.07123,927
700,0.07123,928
701,0.07123,929
701,0.07123,929
702,0.07123,930
703,0.07123,931
703,0.05935,932
704,0.05935,932
704,0.05935,933
705,0.05935,934
705,0.07123,935
706,0.07123,935
707,0.05935,936
707,0.05935,937
708,0.07123,938
708,0.05935,938
709,0.05935,939
709,0.07123,940
710,0.07123,941
710,0.07123,941
711,0.07123,942
712,0.07123,943
712,0.05935,944
713,0.05935,944
713,0.07123,945
714,0.07123,946
714,0.07123,947
715,0.07123,947
716,0.07123,948
716,0.07123,949
717,0.07123,950
717,0.07123,950
718,0.07123,951
718,0.07123,952
719,0.07123,953
720,0.07123,953
720,0.07123,954
721,0.07123,955
721,0.07123,956
722,0.07123,956
722,0.07123,957
723,0.07123,958
724,0.07123,959
724,0.07123,959
725,0.07123,960
725,0.07123,961
726,0.07123,962
726,0.07123,962
727,0.05935,963
727,0.07123,964
728,0.07123,965
729,0.07123,965
729,0.07123,966
730,0.07123,967
730,0.07123,968
731,0.07123,968
731,0.07123,969
732,0.07123,970
733,0.07123,971
733,0.07123,971
734,0.07123,972
734,0.07123,973
735,0.07123,974
735,0.07123,974
736,0.07123,975
737,0.07123,976
737,0.07123,977
738,0.07123,977
738,0.07123,978
739,0.07123,979
739,0.07123,980
740,0.07123,980
740,0.07123,981
741,0.07123,982
742,0.07123,983
742,0.07123,983
743,0.07123,984
743,0.07123,985
744,0.05935,986
744,0.07123,986
745,0.07123,987
746,0.07123,988
746,0.07123,989
747,0.07123,989
747,0.07123,990
748,0.07123,991
748,0.07123,992
749,0.07123,992
750,0.07123,993
750,0.07123,994
751,0.07123,995
751,0.07123,995
752,0.0831,996
752,0.07123,997
753,0.07123,998
753,0.07123,998
754,0.07123,999
755,0.07123,1000
755,0.07123,1001
756,0.07123,1001
756,0.07123,1002
757,0.07123,1003
757,0.07123,1004
758,0.07123,1004
759,0.07123,1005
759,0.07123,1006
760,0.07123,1007
760,0.07123,1007
761,0.07123,1008
761,0.05935,1009
762,0.07123,1010
763,0.07123,1010
763,0.07123,1011
764,0.07123,1012
764,0.07123,1013
765,0.07123,1013
765,0.0831,1014
766,0.07123,1015
767,0.07123,1016
767,0.07123,1016
768,0.07123,1017
768,0.07123,1018
769,0.07123,1019
769,0.07123,1019
770,0.07123,1020
770,0.07123,1021
771,0.07123,1022
772,0.07123,1022
772,0.07123,1023
773,0.07123,1024
773,0.07123,1025
774,0.07123,1025
774,0.07123,1026
775,0.07123,1027
776,0.07123,1028
776,0.07123,1028
777,0.07123,1029
777,0.07123,1030
778,0.07123,1031
778,0.07123,1031
779,0.07123,1032
780,0.07123,1033
780,0.07123,1034
781,0.07123,1034
781,0.07123,1035
782,0.07123,1036
782,0.07123,1037
783,0.07123,1037
784,0.07123,1038
784,0.07123,1039
785,0.07123,1040
785,0.0831,1040
786,0.07123,1041
786,0.07123,1042
787,0.07123,1043
787,0.07123,1043
788,0.07123,1044
789,0.07123,1045
789,0.07123,1046
790,0.0831,1046
790,0.0831,1047
791,0.0831,1048
791,0.0831,1049
792,0.0831,1049
793,0.0831,1050
793,0.0831,1051
794,0.0831,1052
794,0.07123,1052
795,0.0831,1053
795,0.07123,1054
796,0.07123,1055
797,0.0831,1055
797,0.07123,1056
798,0.07123,1057
798,0.07123,1058
799,0.07123,1058
799,0.07123,1059
800,0.07123,1060
800,0.0831,1061
801,0.0831,1061
802,0.0831,1062
802,0.07123,1063
803,0.07123,1064
803,0.0831,1064
804,0.07123,1065
804,0.0831,1066
805,0.07123,1067
806,0.07123,1067
806,0.0831,1068
807,0.07123,1069
807,0.07123,1070
808,0.07123,1070
808,0.07123,1071
809,0.07123,1072
810,0.07123,1073
810,0.07123,1073
811,0.07123,1074
811,0.07123,1075
812,0.07123,1076
812,0.07123,1076
813,0.07123,1077
813,0.07123,1078
814,0.07123,1079
815,0.07123,1079
815,0.07123,1080